[2025-05-31T16:30:48.268+0000] {local_task_job_runner.py:123} INFO - ::group::Pre task execution logs
[2025-05-31T16:30:57.136+0000] {taskinstance.py:2612} INFO - Dependencies all met for dep_context=non-requeueable deps ti=<TaskInstance: log_monitoring_dag.start_log_producer manual__2025-05-31T15:51:59.426777+00:00 [queued]>
[2025-05-31T16:30:57.612+0000] {taskinstance.py:2612} INFO - Dependencies all met for dep_context=requeueable deps ti=<TaskInstance: log_monitoring_dag.start_log_producer manual__2025-05-31T15:51:59.426777+00:00 [queued]>
[2025-05-31T16:30:58.241+0000] {taskinstance.py:2865} INFO - Starting attempt 2 of 2
[2025-05-31T16:31:03.503+0000] {taskinstance.py:2888} INFO - Executing <Task(BashOperator): start_log_producer> on 2025-05-31 15:51:59.426777+00:00
[2025-05-31T16:31:10.748+0000] {logging_mixin.py:190} WARNING - /home/***/.local/lib/python3.12/site-packages/***/task/task_runner/standard_task_runner.py:70 DeprecationWarning: This process (pid=742) is multi-threaded, use of fork() may lead to deadlocks in the child.
[2025-05-31T16:31:13.443+0000] {standard_task_runner.py:72} INFO - Started process 774 to run task
[2025-05-31T16:31:10.137+0000] {standard_task_runner.py:104} INFO - Running: ['***', 'tasks', 'run', 'log_monitoring_dag', 'start_log_producer', 'manual__2025-05-31T15:51:59.426777+00:00', '--job-id', '208', '--raw', '--subdir', 'DAGS_FOLDER/log_monitoring_dag.py', '--cfg-path', '/tmp/tmp4zctw6i5']
[2025-05-31T16:31:14.545+0000] {standard_task_runner.py:105} INFO - Job 208: Subtask start_log_producer
[2025-05-31T16:31:31.680+0000] {logging_mixin.py:190} WARNING - /home/***/.local/lib/python3.12/site-packages/***/settings.py:209 DeprecationWarning: The sql_alchemy_conn option in [core] has been moved to the sql_alchemy_conn option in [database] - the old setting has been used, but please update your config.
[2025-05-31T16:31:34.941+0000] {job.py:229} INFO - Heartbeat recovered after 76.37 seconds
[2025-05-31T16:31:53.126+0000] {task_command.py:467} INFO - Running <TaskInstance: log_monitoring_dag.start_log_producer manual__2025-05-31T15:51:59.426777+00:00 [running]> on host 1d31c4e9dbe9
[2025-05-31T16:31:56.292+0000] {job.py:229} INFO - Heartbeat recovered after 23.48 seconds
[2025-05-31T16:32:11.444+0000] {taskinstance.py:3131} INFO - Exporting env vars: AIRFLOW_CTX_DAG_OWNER='***' AIRFLOW_CTX_DAG_ID='log_monitoring_dag' AIRFLOW_CTX_TASK_ID='start_log_producer' AIRFLOW_CTX_EXECUTION_DATE='2025-05-31T15:51:59.426777+00:00' AIRFLOW_CTX_TRY_NUMBER='2' AIRFLOW_CTX_DAG_RUN_ID='manual__2025-05-31T15:51:59.426777+00:00'
[2025-05-31T16:32:11.648+0000] {taskinstance.py:731} INFO - ::endgroup::
[2025-05-31T16:32:14.108+0000] {job.py:229} INFO - Heartbeat recovered after 18.58 seconds
[2025-05-31T16:32:25.084+0000] {subprocess.py:63} INFO - Tmp dir root location: /tmp
[2025-05-31T16:32:26.345+0000] {job.py:229} INFO - Heartbeat recovered after 14.83 seconds
[2025-05-31T16:32:28.687+0000] {subprocess.py:75} INFO - Running command: ['/usr/bin/bash', '-c', 'cd /opt/***/app && python -u log_producer.py']
[2025-05-31T16:32:33.004+0000] {subprocess.py:86} INFO - Output:
[2025-05-31T16:32:36.334+0000] {job.py:229} INFO - Heartbeat recovered after 10.76 seconds
[2025-05-31T16:32:48.779+0000] {job.py:229} INFO - Heartbeat recovered after 13.09 seconds
[2025-05-31T16:33:01.223+0000] {job.py:229} INFO - Heartbeat recovered after 13.25 seconds
[2025-05-31T16:33:11.215+0000] {job.py:229} INFO - Heartbeat recovered after 10.62 seconds
[2025-05-31T16:33:51.220+0000] {job.py:229} INFO - Heartbeat recovered after 11.20 seconds
[2025-05-31T16:34:06.535+0000] {job.py:229} INFO - Heartbeat recovered after 16.25 seconds
[2025-05-31T16:35:35.343+0000] {job.py:229} INFO - Heartbeat recovered after 90.34 seconds
[2025-05-31T16:35:40.158+0000] {subprocess.py:93} INFO - Traceback (most recent call last):
[2025-05-31T16:35:40.572+0000] {subprocess.py:93} INFO -   File "/opt/***/app/log_producer.py", line 7, in <module>
[2025-05-31T16:35:41.213+0000] {subprocess.py:93} INFO -     producer = KafkaProducer(
[2025-05-31T16:35:41.214+0000] {subprocess.py:93} INFO -                ^^^^^^^^^^^^^^
[2025-05-31T16:35:41.215+0000] {subprocess.py:93} INFO -   File "/home/***/.local/lib/python3.12/site-packages/kafka/producer/kafka.py", line 481, in __init__
[2025-05-31T16:35:41.216+0000] {subprocess.py:93} INFO -     client = self.config['kafka_client'](
[2025-05-31T16:35:41.216+0000] {subprocess.py:93} INFO -              ^^^^^^^^^^^^^^^^^^^^^^^^^^^^
[2025-05-31T16:35:41.217+0000] {subprocess.py:93} INFO -   File "/home/***/.local/lib/python3.12/site-packages/kafka/client_async.py", line 262, in __init__
[2025-05-31T16:35:45.881+0000] {subprocess.py:93} INFO -     self.config['api_version'] = self.check_version()
[2025-05-31T16:35:46.464+0000] {subprocess.py:93} INFO -                                  ^^^^^^^^^^^^^^^^^^^^
[2025-05-31T16:35:46.465+0000] {subprocess.py:93} INFO -   File "/home/***/.local/lib/python3.12/site-packages/kafka/client_async.py", line 1074, in check_version
[2025-05-31T16:35:46.857+0000] {subprocess.py:93} INFO -     raise Errors.NoBrokersAvailable()
[2025-05-31T16:35:46.859+0000] {subprocess.py:93} INFO - kafka.errors.NoBrokersAvailable: NoBrokersAvailable
[2025-05-31T16:35:48.928+0000] {subprocess.py:97} INFO - Command exited with return code 1
[2025-05-31T16:35:49.383+0000] {taskinstance.py:3310} ERROR - Task failed with exception
Traceback (most recent call last):
  File "/home/airflow/.local/lib/python3.12/site-packages/airflow/models/taskinstance.py", line 767, in _execute_task
    result = _execute_callable(context=context, **execute_callable_kwargs)
             ^^^^^^^^^^^^^^^^^^^^^^^^^^^^^^^^^^^^^^^^^^^^^^^^^^^^^^^^^^^^^
  File "/home/airflow/.local/lib/python3.12/site-packages/airflow/models/taskinstance.py", line 733, in _execute_callable
    return ExecutionCallableRunner(
           ^^^^^^^^^^^^^^^^^^^^^^^^
  File "/home/airflow/.local/lib/python3.12/site-packages/airflow/utils/operator_helpers.py", line 252, in run
    return self.func(*args, **kwargs)
           ^^^^^^^^^^^^^^^^^^^^^^^^^^
  File "/home/airflow/.local/lib/python3.12/site-packages/airflow/models/baseoperator.py", line 406, in wrapper
    return func(self, *args, **kwargs)
           ^^^^^^^^^^^^^^^^^^^^^^^^^^^
  File "/home/airflow/.local/lib/python3.12/site-packages/airflow/operators/bash.py", line 249, in execute
    raise AirflowException(
airflow.exceptions.AirflowException: Bash command failed. The command returned a non-zero exit code 1.
[2025-05-31T16:35:49.956+0000] {job.py:229} INFO - Heartbeat recovered after 44.72 seconds
[2025-05-31T16:35:50.216+0000] {taskinstance.py:1225} INFO - Marking task as FAILED. dag_id=log_monitoring_dag, task_id=start_log_producer, run_id=manual__2025-05-31T15:51:59.426777+00:00, execution_date=20250531T155159, start_date=20250531T163057, end_date=20250531T163550
[2025-05-31T16:35:51.112+0000] {taskinstance.py:340} INFO - ::group::Post task execution logs
[2025-05-31T16:35:51.267+0000] {standard_task_runner.py:124} ERROR - Failed to execute job 208 for task start_log_producer (Bash command failed. The command returned a non-zero exit code 1.; 774)
Traceback (most recent call last):
  File "/home/airflow/.local/lib/python3.12/site-packages/airflow/task/task_runner/standard_task_runner.py", line 117, in _start_by_fork
    ret = args.func(args, dag=self.dag)
          ^^^^^^^^^^^^^^^^^^^^^^^^^^^^^
  File "/home/airflow/.local/lib/python3.12/site-packages/airflow/cli/cli_config.py", line 49, in command
    return func(*args, **kwargs)
           ^^^^^^^^^^^^^^^^^^^^^
  File "/home/airflow/.local/lib/python3.12/site-packages/airflow/utils/cli.py", line 115, in wrapper
    return f(*args, **kwargs)
           ^^^^^^^^^^^^^^^^^^
  File "/home/airflow/.local/lib/python3.12/site-packages/airflow/cli/commands/task_command.py", line 483, in task_run
    task_return_code = _run_task_by_selected_method(args, _dag, ti)
                       ^^^^^^^^^^^^^^^^^^^^^^^^^^^^^^^^^^^^^^^^^^^^
  File "/home/airflow/.local/lib/python3.12/site-packages/airflow/cli/commands/task_command.py", line 256, in _run_task_by_selected_method
    return _run_raw_task(args, ti)
           ^^^^^^^^^^^^^^^^^^^^^^^
  File "/home/airflow/.local/lib/python3.12/site-packages/airflow/cli/commands/task_command.py", line 341, in _run_raw_task
    return ti._run_raw_task(
           ^^^^^^^^^^^^^^^^^
  File "/home/airflow/.local/lib/python3.12/site-packages/airflow/utils/session.py", line 97, in wrapper
    return func(*args, session=session, **kwargs)
           ^^^^^^^^^^^^^^^^^^^^^^^^^^^^^^^^^^^^^^
  File "/home/airflow/.local/lib/python3.12/site-packages/airflow/models/taskinstance.py", line 3004, in _run_raw_task
    return _run_raw_task(
           ^^^^^^^^^^^^^^
  File "/home/airflow/.local/lib/python3.12/site-packages/airflow/models/taskinstance.py", line 273, in _run_raw_task
    TaskInstance._execute_task_with_callbacks(
  File "/home/airflow/.local/lib/python3.12/site-packages/airflow/models/taskinstance.py", line 3158, in _execute_task_with_callbacks
    result = self._execute_task(context, task_orig)
             ^^^^^^^^^^^^^^^^^^^^^^^^^^^^^^^^^^^^^^
  File "/home/airflow/.local/lib/python3.12/site-packages/airflow/models/taskinstance.py", line 3182, in _execute_task
    return _execute_task(self, context, task_orig)
           ^^^^^^^^^^^^^^^^^^^^^^^^^^^^^^^^^^^^^^^
  File "/home/airflow/.local/lib/python3.12/site-packages/airflow/models/taskinstance.py", line 767, in _execute_task
    result = _execute_callable(context=context, **execute_callable_kwargs)
             ^^^^^^^^^^^^^^^^^^^^^^^^^^^^^^^^^^^^^^^^^^^^^^^^^^^^^^^^^^^^^
  File "/home/airflow/.local/lib/python3.12/site-packages/airflow/models/taskinstance.py", line 733, in _execute_callable
    return ExecutionCallableRunner(
           ^^^^^^^^^^^^^^^^^^^^^^^^
  File "/home/airflow/.local/lib/python3.12/site-packages/airflow/utils/operator_helpers.py", line 252, in run
    return self.func(*args, **kwargs)
           ^^^^^^^^^^^^^^^^^^^^^^^^^^
  File "/home/airflow/.local/lib/python3.12/site-packages/airflow/models/baseoperator.py", line 406, in wrapper
    return func(self, *args, **kwargs)
           ^^^^^^^^^^^^^^^^^^^^^^^^^^^
  File "/home/airflow/.local/lib/python3.12/site-packages/airflow/operators/bash.py", line 249, in execute
    raise AirflowException(
airflow.exceptions.AirflowException: Bash command failed. The command returned a non-zero exit code 1.
[2025-05-31T16:35:51.842+0000] {local_task_job_runner.py:266} INFO - Task exited with return code 1
[2025-05-31T16:35:51.953+0000] {local_task_job_runner.py:245} INFO - ::endgroup::
