[2025-06-02T00:51:56.924+0000] {local_task_job_runner.py:123} INFO - ::group::Pre task execution logs
[2025-06-02T00:51:57.837+0000] {taskinstance.py:2612} INFO - Dependencies all met for dep_context=non-requeueable deps ti=<TaskInstance: log_monitoring_dag.start_spark_consumer scheduled__2025-06-02T00:40:00+00:00 [queued]>
[2025-06-02T00:51:57.846+0000] {taskinstance.py:2612} INFO - Dependencies all met for dep_context=requeueable deps ti=<TaskInstance: log_monitoring_dag.start_spark_consumer scheduled__2025-06-02T00:40:00+00:00 [queued]>
[2025-06-02T00:51:57.847+0000] {taskinstance.py:2865} INFO - Starting attempt 1 of 2
[2025-06-02T00:51:57.861+0000] {taskinstance.py:2888} INFO - Executing <Task(BashOperator): start_spark_consumer> on 2025-06-02 00:40:00+00:00
[2025-06-02T00:51:58.064+0000] {standard_task_runner.py:104} INFO - Running: ['***', 'tasks', 'run', 'log_monitoring_dag', 'start_spark_consumer', 'scheduled__2025-06-02T00:40:00+00:00', '--job-id', '59', '--raw', '--subdir', 'DAGS_FOLDER/log_monitoring_dag.py', '--cfg-path', '/tmp/tmpw4o_knzn']
[2025-06-02T00:51:58.174+0000] {standard_task_runner.py:105} INFO - Job 59: Subtask start_spark_consumer
[2025-06-02T00:51:58.184+0000] {logging_mixin.py:190} WARNING - /home/***/.local/lib/python3.12/site-packages/***/task/task_runner/standard_task_runner.py:70 DeprecationWarning: This process (pid=333) is multi-threaded, use of fork() may lead to deadlocks in the child.
[2025-06-02T00:51:58.507+0000] {standard_task_runner.py:72} INFO - Started process 337 to run task
[2025-06-02T00:51:58.780+0000] {logging_mixin.py:190} WARNING - /home/***/.local/lib/python3.12/site-packages/***/settings.py:209 DeprecationWarning: The sql_alchemy_conn option in [core] has been moved to the sql_alchemy_conn option in [database] - the old setting has been used, but please update your config.
[2025-06-02T00:51:59.022+0000] {task_command.py:467} INFO - Running <TaskInstance: log_monitoring_dag.start_spark_consumer scheduled__2025-06-02T00:40:00+00:00 [running]> on host 95af1ae74a08
[2025-06-02T00:51:59.024+0000] {logging_mixin.py:190} WARNING - /home/***/.local/lib/python3.12/site-packages/***/settings.py:470 DeprecationWarning: The sql_alchemy_conn option in [core] has been moved to the sql_alchemy_conn option in [database] - the old setting has been used, but please update your config.
[2025-06-02T00:52:01.631+0000] {taskinstance.py:3131} INFO - Exporting env vars: AIRFLOW_CTX_DAG_OWNER='***' AIRFLOW_CTX_DAG_ID='log_monitoring_dag' AIRFLOW_CTX_TASK_ID='start_spark_consumer' AIRFLOW_CTX_EXECUTION_DATE='2025-06-02T00:40:00+00:00' AIRFLOW_CTX_TRY_NUMBER='1' AIRFLOW_CTX_DAG_RUN_ID='scheduled__2025-06-02T00:40:00+00:00'
[2025-06-02T00:52:01.632+0000] {taskinstance.py:731} INFO - ::endgroup::
[2025-06-02T00:52:02.142+0000] {subprocess.py:63} INFO - Tmp dir root location: /tmp
[2025-06-02T00:52:02.143+0000] {subprocess.py:75} INFO - Running command: ['/usr/bin/bash', '-c', '\n            docker run --rm             --network realtime_log_monitoring_default             -v /opt/***/app:/app             bitnami/spark:3.3.0             spark-submit --packages org.apache.spark:spark-sql-kafka-0-10_2.12:3.2.0 /app/log_consumer.py\n        ']
[2025-06-02T00:52:02.315+0000] {subprocess.py:86} INFO - Output:
[2025-06-02T00:52:32.043+0000] {job.py:229} INFO - Heartbeat recovered after 27.98 seconds
[2025-06-02T00:52:37.660+0000] {job.py:229} INFO - Heartbeat recovered after 23.88 seconds
[2025-06-02T00:54:22.046+0000] {job.py:229} INFO - Heartbeat recovered after 37.84 seconds
[2025-06-02T00:54:28.264+0000] {job.py:229} INFO - Heartbeat recovered after 38.92 seconds
[2025-06-02T00:55:25.102+0000] {job.py:229} INFO - Heartbeat recovered after 57.43 seconds
[2025-06-02T00:55:30.992+0000] {job.py:229} INFO - Heartbeat recovered after 51.35 seconds
[2025-06-02T00:58:02.176+0000] {job.py:229} INFO - Heartbeat recovered after 145.64 seconds
[2025-06-02T00:58:08.326+0000] {job.py:229} INFO - Heartbeat recovered after 145.80 seconds
[2025-06-02T01:00:24.655+0000] {job.py:229} INFO - Heartbeat recovered after 123.55 seconds
[2025-06-02T01:00:30.654+0000] {job.py:229} INFO - Heartbeat recovered after 108.49 seconds
[2025-06-02T01:01:55.646+0000] {job.py:229} INFO - Heartbeat recovered after 39.40 seconds
[2025-06-02T01:03:10.771+0000] {job.py:229} INFO - Heartbeat recovered after 49.97 seconds
[2025-06-02T01:03:54.388+0000] {job.py:239} ERROR - Job heartbeat failed with error
Traceback (most recent call last):
  File "/home/airflow/.local/lib/python3.12/site-packages/sqlalchemy/engine/base.py", line 3371, in _wrap_pool_connect
    return fn()
           ^^^^
  File "/home/airflow/.local/lib/python3.12/site-packages/sqlalchemy/pool/base.py", line 327, in connect
    return _ConnectionFairy._checkout(self)
           ^^^^^^^^^^^^^^^^^^^^^^^^^^^^^^^^
  File "/home/airflow/.local/lib/python3.12/site-packages/sqlalchemy/pool/base.py", line 894, in _checkout
    fairy = _ConnectionRecord.checkout(pool)
            ^^^^^^^^^^^^^^^^^^^^^^^^^^^^^^^^
  File "/home/airflow/.local/lib/python3.12/site-packages/sqlalchemy/pool/base.py", line 493, in checkout
    rec = pool._do_get()
          ^^^^^^^^^^^^^^
  File "/home/airflow/.local/lib/python3.12/site-packages/sqlalchemy/pool/impl.py", line 256, in _do_get
    return self._create_connection()
           ^^^^^^^^^^^^^^^^^^^^^^^^^
  File "/home/airflow/.local/lib/python3.12/site-packages/sqlalchemy/pool/base.py", line 273, in _create_connection
    return _ConnectionRecord(self)
           ^^^^^^^^^^^^^^^^^^^^^^^
  File "/home/airflow/.local/lib/python3.12/site-packages/sqlalchemy/pool/base.py", line 388, in __init__
    self.__connect()
  File "/home/airflow/.local/lib/python3.12/site-packages/sqlalchemy/pool/base.py", line 690, in __connect
    with util.safe_reraise():
  File "/home/airflow/.local/lib/python3.12/site-packages/sqlalchemy/util/langhelpers.py", line 70, in __exit__
    compat.raise_(
  File "/home/airflow/.local/lib/python3.12/site-packages/sqlalchemy/util/compat.py", line 211, in raise_
    raise exception
  File "/home/airflow/.local/lib/python3.12/site-packages/sqlalchemy/pool/base.py", line 686, in __connect
    self.dbapi_connection = connection = pool._invoke_creator(self)
                                         ^^^^^^^^^^^^^^^^^^^^^^^^^^
  File "/home/airflow/.local/lib/python3.12/site-packages/sqlalchemy/engine/create.py", line 574, in connect
    return dialect.connect(*cargs, **cparams)
           ^^^^^^^^^^^^^^^^^^^^^^^^^^^^^^^^^^
  File "/home/airflow/.local/lib/python3.12/site-packages/sqlalchemy/engine/default.py", line 598, in connect
    return self.dbapi.connect(*cargs, **cparams)
           ^^^^^^^^^^^^^^^^^^^^^^^^^^^^^^^^^^^^^
  File "/home/airflow/.local/lib/python3.12/site-packages/psycopg2/__init__.py", line 122, in connect
    conn = _connect(dsn, connection_factory=connection_factory, **kwasync)
           ^^^^^^^^^^^^^^^^^^^^^^^^^^^^^^^^^^^^^^^^^^^^^^^^^^^^^^^^^^^^^^^
psycopg2.OperationalError: could not translate host name "postgres" to address: Temporary failure in name resolution


The above exception was the direct cause of the following exception:

Traceback (most recent call last):
  File "/home/airflow/.local/lib/python3.12/site-packages/airflow/jobs/job.py", line 207, in heartbeat
    self._merge_from(Job._fetch_from_db(self, session))
                     ^^^^^^^^^^^^^^^^^^^^^^^^^^^^^^^^^
  File "/home/airflow/.local/lib/python3.12/site-packages/airflow/api_internal/internal_api_call.py", line 139, in wrapper
    return func(*args, **kwargs)
           ^^^^^^^^^^^^^^^^^^^^^
  File "/home/airflow/.local/lib/python3.12/site-packages/airflow/utils/session.py", line 94, in wrapper
    return func(*args, **kwargs)
           ^^^^^^^^^^^^^^^^^^^^^
  File "/home/airflow/.local/lib/python3.12/site-packages/airflow/utils/retries.py", line 93, in wrapped_function
    for attempt in run_with_db_retries(max_retries=retries, logger=logger, **retry_kwargs):
                   ^^^^^^^^^^^^^^^^^^^^^^^^^^^^^^^^^^^^^^^^^^^^^^^^^^^^^^^^^^^^^^^^^^^^^^^
  File "/home/airflow/.local/lib/python3.12/site-packages/tenacity/__init__.py", line 443, in __iter__
    do = self.iter(retry_state=retry_state)
         ^^^^^^^^^^^^^^^^^^^^^^^^^^^^^^^^^^
  File "/home/airflow/.local/lib/python3.12/site-packages/tenacity/__init__.py", line 376, in iter
    result = action(retry_state)
             ^^^^^^^^^^^^^^^^^^^
  File "/home/airflow/.local/lib/python3.12/site-packages/tenacity/__init__.py", line 418, in exc_check
    raise retry_exc.reraise()
          ^^^^^^^^^^^^^^^^^^^
  File "/home/airflow/.local/lib/python3.12/site-packages/tenacity/__init__.py", line 185, in reraise
    raise self.last_attempt.result()
          ^^^^^^^^^^^^^^^^^^^^^^^^^^
  File "/usr/local/lib/python3.12/concurrent/futures/_base.py", line 449, in result
    return self.__get_result()
           ^^^^^^^^^^^^^^^^^^^
  File "/usr/local/lib/python3.12/concurrent/futures/_base.py", line 401, in __get_result
    raise self._exception
  File "/home/airflow/.local/lib/python3.12/site-packages/airflow/utils/retries.py", line 102, in wrapped_function
    return func(*args, **kwargs)
           ^^^^^^^^^^^^^^^^^^^^^
  File "/home/airflow/.local/lib/python3.12/site-packages/airflow/jobs/job.py", line 335, in _fetch_from_db
    session.merge(job)
  File "/home/airflow/.local/lib/python3.12/site-packages/sqlalchemy/orm/session.py", line 3056, in merge
    return self._merge(
           ^^^^^^^^^^^^
  File "/home/airflow/.local/lib/python3.12/site-packages/sqlalchemy/orm/session.py", line 3136, in _merge
    merged = self.get(
             ^^^^^^^^^
  File "/home/airflow/.local/lib/python3.12/site-packages/sqlalchemy/orm/session.py", line 2853, in get
    return self._get_impl(
           ^^^^^^^^^^^^^^^
  File "/home/airflow/.local/lib/python3.12/site-packages/sqlalchemy/orm/session.py", line 2975, in _get_impl
    return db_load_fn(
           ^^^^^^^^^^^
  File "/home/airflow/.local/lib/python3.12/site-packages/sqlalchemy/orm/loading.py", line 530, in load_on_pk_identity
    session.execute(
  File "/home/airflow/.local/lib/python3.12/site-packages/sqlalchemy/orm/session.py", line 1716, in execute
    conn = self._connection_for_bind(bind)
           ^^^^^^^^^^^^^^^^^^^^^^^^^^^^^^^
  File "/home/airflow/.local/lib/python3.12/site-packages/sqlalchemy/orm/session.py", line 1555, in _connection_for_bind
    return self._transaction._connection_for_bind(
           ^^^^^^^^^^^^^^^^^^^^^^^^^^^^^^^^^^^^^^^
  File "/home/airflow/.local/lib/python3.12/site-packages/sqlalchemy/orm/session.py", line 750, in _connection_for_bind
    conn = bind.connect()
           ^^^^^^^^^^^^^^
  File "/home/airflow/.local/lib/python3.12/site-packages/sqlalchemy/future/engine.py", line 412, in connect
    return super(Engine, self).connect()
           ^^^^^^^^^^^^^^^^^^^^^^^^^^^^^
  File "/home/airflow/.local/lib/python3.12/site-packages/sqlalchemy/engine/base.py", line 3325, in connect
    return self._connection_cls(self, close_with_result=close_with_result)
           ^^^^^^^^^^^^^^^^^^^^^^^^^^^^^^^^^^^^^^^^^^^^^^^^^^^^^^^^^^^^^^^
  File "/home/airflow/.local/lib/python3.12/site-packages/sqlalchemy/engine/base.py", line 96, in __init__
    else engine.raw_connection()
         ^^^^^^^^^^^^^^^^^^^^^^^
  File "/home/airflow/.local/lib/python3.12/site-packages/sqlalchemy/engine/base.py", line 3404, in raw_connection
    return self._wrap_pool_connect(self.pool.connect, _connection)
           ^^^^^^^^^^^^^^^^^^^^^^^^^^^^^^^^^^^^^^^^^^^^^^^^^^^^^^^
  File "/home/airflow/.local/lib/python3.12/site-packages/sqlalchemy/engine/base.py", line 3374, in _wrap_pool_connect
    Connection._handle_dbapi_exception_noconnection(
  File "/home/airflow/.local/lib/python3.12/site-packages/sqlalchemy/engine/base.py", line 2208, in _handle_dbapi_exception_noconnection
    util.raise_(
  File "/home/airflow/.local/lib/python3.12/site-packages/sqlalchemy/util/compat.py", line 211, in raise_
    raise exception
  File "/home/airflow/.local/lib/python3.12/site-packages/sqlalchemy/engine/base.py", line 3371, in _wrap_pool_connect
    return fn()
           ^^^^
  File "/home/airflow/.local/lib/python3.12/site-packages/sqlalchemy/pool/base.py", line 327, in connect
    return _ConnectionFairy._checkout(self)
           ^^^^^^^^^^^^^^^^^^^^^^^^^^^^^^^^
  File "/home/airflow/.local/lib/python3.12/site-packages/sqlalchemy/pool/base.py", line 894, in _checkout
    fairy = _ConnectionRecord.checkout(pool)
            ^^^^^^^^^^^^^^^^^^^^^^^^^^^^^^^^
  File "/home/airflow/.local/lib/python3.12/site-packages/sqlalchemy/pool/base.py", line 493, in checkout
    rec = pool._do_get()
          ^^^^^^^^^^^^^^
  File "/home/airflow/.local/lib/python3.12/site-packages/sqlalchemy/pool/impl.py", line 256, in _do_get
    return self._create_connection()
           ^^^^^^^^^^^^^^^^^^^^^^^^^
  File "/home/airflow/.local/lib/python3.12/site-packages/sqlalchemy/pool/base.py", line 273, in _create_connection
    return _ConnectionRecord(self)
           ^^^^^^^^^^^^^^^^^^^^^^^
  File "/home/airflow/.local/lib/python3.12/site-packages/sqlalchemy/pool/base.py", line 388, in __init__
    self.__connect()
  File "/home/airflow/.local/lib/python3.12/site-packages/sqlalchemy/pool/base.py", line 690, in __connect
    with util.safe_reraise():
  File "/home/airflow/.local/lib/python3.12/site-packages/sqlalchemy/util/langhelpers.py", line 70, in __exit__
    compat.raise_(
  File "/home/airflow/.local/lib/python3.12/site-packages/sqlalchemy/util/compat.py", line 211, in raise_
    raise exception
  File "/home/airflow/.local/lib/python3.12/site-packages/sqlalchemy/pool/base.py", line 686, in __connect
    self.dbapi_connection = connection = pool._invoke_creator(self)
                                         ^^^^^^^^^^^^^^^^^^^^^^^^^^
  File "/home/airflow/.local/lib/python3.12/site-packages/sqlalchemy/engine/create.py", line 574, in connect
    return dialect.connect(*cargs, **cparams)
           ^^^^^^^^^^^^^^^^^^^^^^^^^^^^^^^^^^
  File "/home/airflow/.local/lib/python3.12/site-packages/sqlalchemy/engine/default.py", line 598, in connect
    return self.dbapi.connect(*cargs, **cparams)
           ^^^^^^^^^^^^^^^^^^^^^^^^^^^^^^^^^^^^^
  File "/home/airflow/.local/lib/python3.12/site-packages/psycopg2/__init__.py", line 122, in connect
    conn = _connect(dsn, connection_factory=connection_factory, **kwasync)
           ^^^^^^^^^^^^^^^^^^^^^^^^^^^^^^^^^^^^^^^^^^^^^^^^^^^^^^^^^^^^^^^
sqlalchemy.exc.OperationalError: (psycopg2.OperationalError) could not translate host name "postgres" to address: Temporary failure in name resolution

(Background on this error at: https://sqlalche.me/e/14/e3q8)
[2025-06-02T01:04:40.912+0000] {job.py:254} ERROR - Job heartbeat failed with error. Scheduler is in unhealthy state
[2025-06-02T01:05:01.605+0000] {job.py:229} INFO - Heartbeat recovered after 154.84 seconds
[2025-06-02T01:05:12.524+0000] {job.py:229} INFO - Heartbeat recovered after 24.95 seconds
[2025-06-02T01:06:06.695+0000] {subprocess.py:93} INFO - [38;5;6m [38;5;5m01:06:02.84 [0m
[2025-06-02T01:06:13.119+0000] {subprocess.py:93} INFO - [38;5;6m [38;5;5m01:06:03.25 [0m[1mWelcome to the Bitnami spark container[0m
[2025-06-02T01:06:13.805+0000] {subprocess.py:93} INFO - [38;5;6m [38;5;5m01:06:03.25 [0mSubscribe to project updates by watching [1mhttps://github.com/bitnami/containers[0m
[2025-06-02T01:06:13.821+0000] {subprocess.py:93} INFO - [38;5;6m [38;5;5m01:06:03.25 [0mSubmit issues and feature requests at [1mhttps://github.com/bitnami/containers/issues[0m
[2025-06-02T01:06:14.972+0000] {subprocess.py:93} INFO - [38;5;6m [38;5;5m01:06:03.25 [0m
[2025-06-02T01:06:15.193+0000] {subprocess.py:93} INFO - 
[2025-06-02T01:07:35.688+0000] {job.py:229} INFO - Heartbeat recovered after 61.57 seconds
[2025-06-02T01:07:42.775+0000] {job.py:229} INFO - Heartbeat recovered after 59.06 seconds
[2025-06-02T01:08:08.461+0000] {job.py:229} INFO - Heartbeat recovered after 12.16 seconds
[2025-06-02T01:08:19.391+0000] {job.py:229} INFO - Heartbeat recovered after 11.95 seconds
[2025-06-02T01:09:04.171+0000] {job.py:229} INFO - Heartbeat recovered after 44.81 seconds
[2025-06-02T01:09:18.438+0000] {job.py:229} INFO - Heartbeat recovered after 20.75 seconds
[2025-06-02T01:09:36.738+0000] {job.py:229} INFO - Heartbeat recovered after 19.54 seconds
[2025-06-02T01:10:05.011+0000] {job.py:229} INFO - Heartbeat recovered after 30.15 seconds
[2025-06-02T01:10:20.037+0000] {job.py:229} INFO - Heartbeat recovered after 17.12 seconds
[2025-06-02T01:10:35.117+0000] {job.py:229} INFO - Heartbeat recovered after 16.47 seconds
[2025-06-02T01:10:46.561+0000] {job.py:229} INFO - Heartbeat recovered after 11.80 seconds
[2025-06-02T01:10:57.730+0000] {job.py:229} INFO - Heartbeat recovered after 11.50 seconds
[2025-06-02T01:11:34.743+0000] {job.py:229} INFO - Heartbeat recovered after 31.22 seconds
[2025-06-02T01:12:09.004+0000] {job.py:229} INFO - Heartbeat recovered after 34.36 seconds
[2025-06-02T01:12:35.140+0000] {job.py:229} INFO - Heartbeat recovered after 18.61 seconds
[2025-06-02T01:13:04.878+0000] {job.py:229} INFO - Heartbeat recovered after 22.41 seconds
[2025-06-02T01:13:28.966+0000] {job.py:229} INFO - Heartbeat recovered after 24.72 seconds
[2025-06-02T01:14:09.681+0000] {job.py:229} INFO - Heartbeat recovered after 21.27 seconds
[2025-06-02T01:14:50.925+0000] {job.py:229} INFO - Heartbeat recovered after 34.81 seconds
[2025-06-02T01:14:57.756+0000] {job.py:229} INFO - Heartbeat recovered after 11.66 seconds
[2025-06-02T01:15:30.274+0000] {job.py:229} INFO - Heartbeat recovered after 20.21 seconds
[2025-06-02T01:15:53.728+0000] {job.py:229} INFO - Heartbeat recovered after 24.10 seconds
[2025-06-02T01:16:04.000+0000] {job.py:229} INFO - Heartbeat recovered after 10.73 seconds
[2025-06-02T01:16:25.527+0000] {job.py:229} INFO - Heartbeat recovered after 16.45 seconds
[2025-06-02T01:17:21.187+0000] {job.py:229} INFO - Heartbeat recovered after 21.81 seconds
[2025-06-02T01:17:50.684+0000] {job.py:229} INFO - Heartbeat recovered after 33.11 seconds
[2025-06-02T01:17:54.949+0000] {subprocess.py:93} INFO - :: loading settings :: url = jar:file:/opt/bitnami/spark/jars/ivy-2.5.0.jar!/org/apache/ivy/core/settings/ivysettings.xml
[2025-06-02T01:17:55.472+0000] {subprocess.py:93} INFO - Ivy Default Cache set to: /opt/bitnami/spark/.ivy2/cache
[2025-06-02T01:17:56.817+0000] {subprocess.py:93} INFO - The jars for the packages stored in: /opt/bitnami/spark/.ivy2/jars
[2025-06-02T01:17:57.764+0000] {subprocess.py:93} INFO - org.apache.spark#spark-sql-kafka-0-10_2.12 added as a dependency
[2025-06-02T01:17:57.764+0000] {subprocess.py:93} INFO - :: resolving dependencies :: org.apache.spark#spark-submit-parent-125f2df1-e33a-46c4-80a1-5c540fa66c3e;1.0
[2025-06-02T01:17:57.765+0000] {subprocess.py:93} INFO - 	confs: [default]
[2025-06-02T01:18:06.654+0000] {job.py:229} INFO - Heartbeat recovered after 16.18 seconds
[2025-06-02T01:18:15.686+0000] {subprocess.py:93} INFO - You probably access the destination server through a proxy server that is not well configured.
[2025-06-02T01:18:15.688+0000] {subprocess.py:93} INFO - You probably access the destination server through a proxy server that is not well configured.
[2025-06-02T01:18:25.878+0000] {subprocess.py:93} INFO - You probably access the destination server through a proxy server that is not well configured.
[2025-06-02T01:18:26.215+0000] {subprocess.py:93} INFO - You probably access the destination server through a proxy server that is not well configured.
[2025-06-02T01:18:28.886+0000] {subprocess.py:93} INFO - :: resolution report :: resolve 33227ms :: artifacts dl 91ms
[2025-06-02T01:18:29.715+0000] {subprocess.py:93} INFO - 	:: modules in use:
[2025-06-02T01:18:30.594+0000] {subprocess.py:93} INFO - 	---------------------------------------------------------------------
[2025-06-02T01:18:30.884+0000] {subprocess.py:93} INFO - 	|                  |            modules            ||   artifacts   |
[2025-06-02T01:18:32.067+0000] {subprocess.py:93} INFO - 	|       conf       | number| search|dwnlded|evicted|| number|dwnlded|
[2025-06-02T01:18:33.113+0000] {subprocess.py:93} INFO - 	---------------------------------------------------------------------
[2025-06-02T01:18:33.314+0000] {subprocess.py:93} INFO - 	|      default     |   1   |   0   |   0   |   0   ||   0   |   0   |
[2025-06-02T01:18:33.569+0000] {subprocess.py:93} INFO - 	---------------------------------------------------------------------
[2025-06-02T01:18:34.252+0000] {subprocess.py:93} INFO - 
[2025-06-02T01:18:34.355+0000] {subprocess.py:93} INFO - :: problems summary ::
[2025-06-02T01:18:34.386+0000] {subprocess.py:93} INFO - :::: WARNINGS
[2025-06-02T01:18:34.515+0000] {subprocess.py:93} INFO - 	Host repo1.maven.org not found. url=https://repo1.maven.org/maven2/org/apache/spark/spark-sql-kafka-0-10_2.12/3.2.0/spark-sql-kafka-0-10_2.12-3.2.0.pom
[2025-06-02T01:18:34.540+0000] {subprocess.py:93} INFO - 
[2025-06-02T01:18:34.631+0000] {subprocess.py:93} INFO - 	Host repo1.maven.org not found. url=https://repo1.maven.org/maven2/org/apache/spark/spark-sql-kafka-0-10_2.12/3.2.0/spark-sql-kafka-0-10_2.12-3.2.0.jar
[2025-06-02T01:18:34.637+0000] {subprocess.py:93} INFO - 
[2025-06-02T01:18:34.667+0000] {subprocess.py:93} INFO - 	Host repos.spark-packages.org not found. url=https://repos.spark-packages.org/org/apache/spark/spark-sql-kafka-0-10_2.12/3.2.0/spark-sql-kafka-0-10_2.12-3.2.0.pom
[2025-06-02T01:18:34.679+0000] {subprocess.py:93} INFO - 
[2025-06-02T01:18:34.679+0000] {subprocess.py:93} INFO - 	Host repos.spark-packages.org not found. url=https://repos.spark-packages.org/org/apache/spark/spark-sql-kafka-0-10_2.12/3.2.0/spark-sql-kafka-0-10_2.12-3.2.0.jar
[2025-06-02T01:18:34.680+0000] {subprocess.py:93} INFO - 
[2025-06-02T01:18:34.681+0000] {subprocess.py:93} INFO - 		module not found: org.apache.spark#spark-sql-kafka-0-10_2.12;3.2.0
[2025-06-02T01:18:34.852+0000] {subprocess.py:93} INFO - 
[2025-06-02T01:18:34.853+0000] {subprocess.py:93} INFO - 	==== local-m2-cache: tried
[2025-06-02T01:18:34.943+0000] {subprocess.py:93} INFO - 
[2025-06-02T01:18:35.005+0000] {subprocess.py:93} INFO - 	  file:/opt/bitnami/spark/.m2/repository/org/apache/spark/spark-sql-kafka-0-10_2.12/3.2.0/spark-sql-kafka-0-10_2.12-3.2.0.pom
[2025-06-02T01:18:35.007+0000] {subprocess.py:93} INFO - 
[2025-06-02T01:18:35.007+0000] {subprocess.py:93} INFO - 	  -- artifact org.apache.spark#spark-sql-kafka-0-10_2.12;3.2.0!spark-sql-kafka-0-10_2.12.jar:
[2025-06-02T01:18:35.039+0000] {subprocess.py:93} INFO - 
[2025-06-02T01:18:35.095+0000] {subprocess.py:93} INFO - 	  file:/opt/bitnami/spark/.m2/repository/org/apache/spark/spark-sql-kafka-0-10_2.12/3.2.0/spark-sql-kafka-0-10_2.12-3.2.0.jar
[2025-06-02T01:18:35.112+0000] {subprocess.py:93} INFO - 
[2025-06-02T01:18:35.113+0000] {subprocess.py:93} INFO - 	==== local-ivy-cache: tried
[2025-06-02T01:18:35.114+0000] {subprocess.py:93} INFO - 
[2025-06-02T01:18:35.132+0000] {subprocess.py:93} INFO - 	  /opt/bitnami/spark/.ivy2/local/org.apache.spark/spark-sql-kafka-0-10_2.12/3.2.0/ivys/ivy.xml
[2025-06-02T01:18:35.133+0000] {subprocess.py:93} INFO - 
[2025-06-02T01:18:35.134+0000] {subprocess.py:93} INFO - 	  -- artifact org.apache.spark#spark-sql-kafka-0-10_2.12;3.2.0!spark-sql-kafka-0-10_2.12.jar:
[2025-06-02T01:18:35.167+0000] {subprocess.py:93} INFO - 
[2025-06-02T01:18:35.440+0000] {subprocess.py:93} INFO - 	  /opt/bitnami/spark/.ivy2/local/org.apache.spark/spark-sql-kafka-0-10_2.12/3.2.0/jars/spark-sql-kafka-0-10_2.12.jar
[2025-06-02T01:18:35.440+0000] {subprocess.py:93} INFO - 
[2025-06-02T01:18:35.477+0000] {subprocess.py:93} INFO - 	==== central: tried
[2025-06-02T01:18:35.511+0000] {subprocess.py:93} INFO - 
[2025-06-02T01:18:35.512+0000] {subprocess.py:93} INFO - 	  https://repo1.maven.org/maven2/org/apache/spark/spark-sql-kafka-0-10_2.12/3.2.0/spark-sql-kafka-0-10_2.12-3.2.0.pom
[2025-06-02T01:18:35.573+0000] {subprocess.py:93} INFO - 
[2025-06-02T01:18:35.618+0000] {subprocess.py:93} INFO - 	  -- artifact org.apache.spark#spark-sql-kafka-0-10_2.12;3.2.0!spark-sql-kafka-0-10_2.12.jar:
[2025-06-02T01:18:35.646+0000] {subprocess.py:93} INFO - 
[2025-06-02T01:18:35.675+0000] {subprocess.py:93} INFO - 	  https://repo1.maven.org/maven2/org/apache/spark/spark-sql-kafka-0-10_2.12/3.2.0/spark-sql-kafka-0-10_2.12-3.2.0.jar
[2025-06-02T01:18:35.768+0000] {subprocess.py:93} INFO - 
[2025-06-02T01:18:35.780+0000] {subprocess.py:93} INFO - 	==== spark-packages: tried
[2025-06-02T01:18:35.781+0000] {subprocess.py:93} INFO - 
[2025-06-02T01:18:35.781+0000] {subprocess.py:93} INFO - 	  https://repos.spark-packages.org/org/apache/spark/spark-sql-kafka-0-10_2.12/3.2.0/spark-sql-kafka-0-10_2.12-3.2.0.pom
[2025-06-02T01:18:35.849+0000] {subprocess.py:93} INFO - 
[2025-06-02T01:18:35.850+0000] {subprocess.py:93} INFO - 	  -- artifact org.apache.spark#spark-sql-kafka-0-10_2.12;3.2.0!spark-sql-kafka-0-10_2.12.jar:
[2025-06-02T01:18:35.864+0000] {subprocess.py:93} INFO - 
[2025-06-02T01:18:35.875+0000] {subprocess.py:93} INFO - 	  https://repos.spark-packages.org/org/apache/spark/spark-sql-kafka-0-10_2.12/3.2.0/spark-sql-kafka-0-10_2.12-3.2.0.jar
[2025-06-02T01:18:35.876+0000] {subprocess.py:93} INFO - 
[2025-06-02T01:18:35.899+0000] {subprocess.py:93} INFO - 		::::::::::::::::::::::::::::::::::::::::::::::
[2025-06-02T01:18:35.901+0000] {subprocess.py:93} INFO - 
[2025-06-02T01:18:35.910+0000] {subprocess.py:93} INFO - 		::          UNRESOLVED DEPENDENCIES         ::
[2025-06-02T01:18:35.911+0000] {subprocess.py:93} INFO - 
[2025-06-02T01:18:35.912+0000] {subprocess.py:93} INFO - 		::::::::::::::::::::::::::::::::::::::::::::::
[2025-06-02T01:18:35.912+0000] {subprocess.py:93} INFO - 
[2025-06-02T01:18:35.949+0000] {subprocess.py:93} INFO - 		:: org.apache.spark#spark-sql-kafka-0-10_2.12;3.2.0: not found
[2025-06-02T01:18:35.950+0000] {subprocess.py:93} INFO - 
[2025-06-02T01:18:35.951+0000] {subprocess.py:93} INFO - 		::::::::::::::::::::::::::::::::::::::::::::::
[2025-06-02T01:18:35.986+0000] {subprocess.py:93} INFO - 
[2025-06-02T01:18:35.986+0000] {subprocess.py:93} INFO - 
[2025-06-02T01:18:36.021+0000] {subprocess.py:93} INFO - 
[2025-06-02T01:18:36.022+0000] {subprocess.py:93} INFO - :: USE VERBOSE OR DEBUG MESSAGE LEVEL FOR MORE DETAILS
[2025-06-02T01:18:36.023+0000] {subprocess.py:93} INFO - Exception in thread "main" java.lang.RuntimeException: [unresolved dependency: org.apache.spark#spark-sql-kafka-0-10_2.12;3.2.0: not found]
[2025-06-02T01:18:36.023+0000] {subprocess.py:93} INFO - 	at org.apache.spark.deploy.SparkSubmitUtils$.resolveMavenCoordinates(SparkSubmit.scala:1456)
[2025-06-02T01:18:36.187+0000] {subprocess.py:93} INFO - 	at org.apache.spark.util.DependencyUtils$.resolveMavenDependencies(DependencyUtils.scala:185)
[2025-06-02T01:18:36.233+0000] {subprocess.py:93} INFO - 	at org.apache.spark.deploy.SparkSubmit.prepareSubmitEnvironment(SparkSubmit.scala:308)
[2025-06-02T01:18:36.294+0000] {subprocess.py:93} INFO - 	at org.apache.spark.deploy.SparkSubmit.org$apache$spark$deploy$SparkSubmit$$runMain(SparkSubmit.scala:901)
[2025-06-02T01:18:36.295+0000] {subprocess.py:93} INFO - 	at org.apache.spark.deploy.SparkSubmit.doRunMain$1(SparkSubmit.scala:180)
[2025-06-02T01:18:36.295+0000] {subprocess.py:93} INFO - 	at org.apache.spark.deploy.SparkSubmit.submit(SparkSubmit.scala:203)
[2025-06-02T01:18:36.428+0000] {subprocess.py:93} INFO - 	at org.apache.spark.deploy.SparkSubmit.doSubmit(SparkSubmit.scala:90)
[2025-06-02T01:18:36.429+0000] {subprocess.py:93} INFO - 	at org.apache.spark.deploy.SparkSubmit$$anon$2.doSubmit(SparkSubmit.scala:1046)
[2025-06-02T01:18:36.430+0000] {subprocess.py:93} INFO - 	at org.apache.spark.deploy.SparkSubmit$.main(SparkSubmit.scala:1055)
[2025-06-02T01:18:36.430+0000] {subprocess.py:93} INFO - 	at org.apache.spark.deploy.SparkSubmit.main(SparkSubmit.scala)
[2025-06-02T01:19:01.609+0000] {job.py:229} INFO - Heartbeat recovered after 14.43 seconds
[2025-06-02T01:19:36.127+0000] {subprocess.py:97} INFO - Command exited with return code 1
[2025-06-02T01:20:19.861+0000] {taskinstance.py:3310} ERROR - Task failed with exception
Traceback (most recent call last):
  File "/home/airflow/.local/lib/python3.12/site-packages/airflow/models/taskinstance.py", line 767, in _execute_task
    result = _execute_callable(context=context, **execute_callable_kwargs)
             ^^^^^^^^^^^^^^^^^^^^^^^^^^^^^^^^^^^^^^^^^^^^^^^^^^^^^^^^^^^^^
  File "/home/airflow/.local/lib/python3.12/site-packages/airflow/models/taskinstance.py", line 733, in _execute_callable
    return ExecutionCallableRunner(
           ^^^^^^^^^^^^^^^^^^^^^^^^
  File "/home/airflow/.local/lib/python3.12/site-packages/airflow/utils/operator_helpers.py", line 252, in run
    return self.func(*args, **kwargs)
           ^^^^^^^^^^^^^^^^^^^^^^^^^^
  File "/home/airflow/.local/lib/python3.12/site-packages/airflow/models/baseoperator.py", line 406, in wrapper
    return func(self, *args, **kwargs)
           ^^^^^^^^^^^^^^^^^^^^^^^^^^^
  File "/home/airflow/.local/lib/python3.12/site-packages/airflow/operators/bash.py", line 249, in execute
    raise AirflowException(
airflow.exceptions.AirflowException: Bash command failed. The command returned a non-zero exit code 1.
[2025-06-02T01:20:28.045+0000] {taskinstance.py:1225} INFO - Marking task as UP_FOR_RETRY. dag_id=log_monitoring_dag, task_id=start_spark_consumer, run_id=scheduled__2025-06-02T00:40:00+00:00, execution_date=20250602T004000, start_date=20250602T005157, end_date=20250602T012027
[2025-06-02T01:20:33.784+0000] {taskinstance.py:340} INFO - ::group::Post task execution logs
[2025-06-02T01:20:34.425+0000] {standard_task_runner.py:124} ERROR - Failed to execute job 59 for task start_spark_consumer (Bash command failed. The command returned a non-zero exit code 1.; 337)
Traceback (most recent call last):
  File "/home/airflow/.local/lib/python3.12/site-packages/airflow/task/task_runner/standard_task_runner.py", line 117, in _start_by_fork
    ret = args.func(args, dag=self.dag)
          ^^^^^^^^^^^^^^^^^^^^^^^^^^^^^
  File "/home/airflow/.local/lib/python3.12/site-packages/airflow/cli/cli_config.py", line 49, in command
    return func(*args, **kwargs)
           ^^^^^^^^^^^^^^^^^^^^^
  File "/home/airflow/.local/lib/python3.12/site-packages/airflow/utils/cli.py", line 115, in wrapper
    return f(*args, **kwargs)
           ^^^^^^^^^^^^^^^^^^
  File "/home/airflow/.local/lib/python3.12/site-packages/airflow/cli/commands/task_command.py", line 483, in task_run
    task_return_code = _run_task_by_selected_method(args, _dag, ti)
                       ^^^^^^^^^^^^^^^^^^^^^^^^^^^^^^^^^^^^^^^^^^^^
  File "/home/airflow/.local/lib/python3.12/site-packages/airflow/cli/commands/task_command.py", line 256, in _run_task_by_selected_method
    return _run_raw_task(args, ti)
           ^^^^^^^^^^^^^^^^^^^^^^^
  File "/home/airflow/.local/lib/python3.12/site-packages/airflow/cli/commands/task_command.py", line 341, in _run_raw_task
    return ti._run_raw_task(
           ^^^^^^^^^^^^^^^^^
  File "/home/airflow/.local/lib/python3.12/site-packages/airflow/utils/session.py", line 97, in wrapper
    return func(*args, session=session, **kwargs)
           ^^^^^^^^^^^^^^^^^^^^^^^^^^^^^^^^^^^^^^
  File "/home/airflow/.local/lib/python3.12/site-packages/airflow/models/taskinstance.py", line 3004, in _run_raw_task
    return _run_raw_task(
           ^^^^^^^^^^^^^^
  File "/home/airflow/.local/lib/python3.12/site-packages/airflow/models/taskinstance.py", line 273, in _run_raw_task
    TaskInstance._execute_task_with_callbacks(
  File "/home/airflow/.local/lib/python3.12/site-packages/airflow/models/taskinstance.py", line 3158, in _execute_task_with_callbacks
    result = self._execute_task(context, task_orig)
             ^^^^^^^^^^^^^^^^^^^^^^^^^^^^^^^^^^^^^^
  File "/home/airflow/.local/lib/python3.12/site-packages/airflow/models/taskinstance.py", line 3182, in _execute_task
    return _execute_task(self, context, task_orig)
           ^^^^^^^^^^^^^^^^^^^^^^^^^^^^^^^^^^^^^^^
  File "/home/airflow/.local/lib/python3.12/site-packages/airflow/models/taskinstance.py", line 767, in _execute_task
    result = _execute_callable(context=context, **execute_callable_kwargs)
             ^^^^^^^^^^^^^^^^^^^^^^^^^^^^^^^^^^^^^^^^^^^^^^^^^^^^^^^^^^^^^
  File "/home/airflow/.local/lib/python3.12/site-packages/airflow/models/taskinstance.py", line 733, in _execute_callable
    return ExecutionCallableRunner(
           ^^^^^^^^^^^^^^^^^^^^^^^^
  File "/home/airflow/.local/lib/python3.12/site-packages/airflow/utils/operator_helpers.py", line 252, in run
    return self.func(*args, **kwargs)
           ^^^^^^^^^^^^^^^^^^^^^^^^^^
  File "/home/airflow/.local/lib/python3.12/site-packages/airflow/models/baseoperator.py", line 406, in wrapper
    return func(self, *args, **kwargs)
           ^^^^^^^^^^^^^^^^^^^^^^^^^^^
  File "/home/airflow/.local/lib/python3.12/site-packages/airflow/operators/bash.py", line 249, in execute
    raise AirflowException(
airflow.exceptions.AirflowException: Bash command failed. The command returned a non-zero exit code 1.
[2025-06-02T01:20:36.938+0000] {local_task_job_runner.py:266} INFO - Task exited with return code 1
[2025-06-02T01:20:39.191+0000] {standard_task_runner.py:217} INFO - Process not found (most likely exited), stop collecting metrics
[2025-06-02T01:21:02.138+0000] {taskinstance.py:3900} INFO - 0 downstream tasks scheduled from follow-on schedule check
[2025-06-02T01:21:03.336+0000] {local_task_job_runner.py:245} INFO - ::endgroup::
