[2025-06-01T14:15:57.832+0000] {local_task_job_runner.py:123} INFO - ::group::Pre task execution logs
[2025-06-01T14:15:57.933+0000] {taskinstance.py:2612} INFO - Dependencies all met for dep_context=non-requeueable deps ti=<TaskInstance: log_monitoring_dag.start_log_producer manual__2025-06-01T13:21:18.917724+00:00 [queued]>
[2025-06-01T14:15:57.939+0000] {taskinstance.py:2612} INFO - Dependencies all met for dep_context=requeueable deps ti=<TaskInstance: log_monitoring_dag.start_log_producer manual__2025-06-01T13:21:18.917724+00:00 [queued]>
[2025-06-01T14:15:57.940+0000] {taskinstance.py:2865} INFO - Starting attempt 3 of 2
[2025-06-01T14:15:58.208+0000] {taskinstance.py:2888} INFO - Executing <Task(BashOperator): start_log_producer> on 2025-06-01 13:21:18.917724+00:00
[2025-06-01T14:15:59.828+0000] {logging_mixin.py:190} WARNING - /home/***/.local/lib/python3.12/site-packages/***/task/task_runner/standard_task_runner.py:70 DeprecationWarning: This process (pid=171) is multi-threaded, use of fork() may lead to deadlocks in the child.
[2025-06-01T14:15:59.915+0000] {standard_task_runner.py:72} INFO - Started process 180 to run task
[2025-06-01T14:15:58.518+0000] {standard_task_runner.py:104} INFO - Running: ['***', 'tasks', 'run', 'log_monitoring_dag', 'start_log_producer', 'manual__2025-06-01T13:21:18.917724+00:00', '--job-id', '152', '--raw', '--subdir', 'DAGS_FOLDER/log_monitoring_dag.py', '--cfg-path', '/tmp/tmpmemz26ta']
[2025-06-01T14:16:00.159+0000] {standard_task_runner.py:105} INFO - Job 152: Subtask start_log_producer
[2025-06-01T14:16:05.307+0000] {logging_mixin.py:190} WARNING - /home/***/.local/lib/python3.12/site-packages/***/settings.py:209 DeprecationWarning: The sql_alchemy_conn option in [core] has been moved to the sql_alchemy_conn option in [database] - the old setting has been used, but please update your config.
[2025-06-01T14:16:06.982+0000] {job.py:229} INFO - Heartbeat recovered after 12.02 seconds
[2025-06-01T14:16:12.172+0000] {task_command.py:467} INFO - Running <TaskInstance: log_monitoring_dag.start_log_producer manual__2025-06-01T13:21:18.917724+00:00 [running]> on host 57a314bdae63
[2025-06-01T14:16:29.226+0000] {job.py:229} INFO - Heartbeat recovered after 14.25 seconds
[2025-06-01T14:16:35.188+0000] {taskinstance.py:3131} INFO - Exporting env vars: AIRFLOW_CTX_DAG_OWNER='***' AIRFLOW_CTX_DAG_ID='log_monitoring_dag' AIRFLOW_CTX_TASK_ID='start_log_producer' AIRFLOW_CTX_EXECUTION_DATE='2025-06-01T13:21:18.917724+00:00' AIRFLOW_CTX_TRY_NUMBER='3' AIRFLOW_CTX_DAG_RUN_ID='manual__2025-06-01T13:21:18.917724+00:00'
[2025-06-01T14:16:35.191+0000] {taskinstance.py:731} INFO - ::endgroup::
[2025-06-01T14:16:36.158+0000] {subprocess.py:63} INFO - Tmp dir root location: /tmp
[2025-06-01T14:16:36.414+0000] {subprocess.py:75} INFO - Running command: ['/usr/bin/bash', '-c', 'cd /opt/***/app && python -u log_producer.py']
[2025-06-01T14:16:36.434+0000] {subprocess.py:86} INFO - Output:
[2025-06-01T14:16:53.050+0000] {subprocess.py:93} INFO - Traceback (most recent call last):
[2025-06-01T14:16:53.051+0000] {subprocess.py:93} INFO -   File "/opt/***/app/log_producer.py", line 7, in <module>
[2025-06-01T14:16:53.053+0000] {subprocess.py:93} INFO -     producer = KafkaProducer(
[2025-06-01T14:16:53.054+0000] {subprocess.py:93} INFO -                ^^^^^^^^^^^^^^
[2025-06-01T14:16:53.054+0000] {subprocess.py:93} INFO -   File "/home/***/.local/lib/python3.12/site-packages/kafka/producer/kafka.py", line 481, in __init__
[2025-06-01T14:16:53.069+0000] {subprocess.py:93} INFO -     client = self.config['kafka_client'](
[2025-06-01T14:16:53.069+0000] {subprocess.py:93} INFO -              ^^^^^^^^^^^^^^^^^^^^^^^^^^^^
[2025-06-01T14:16:53.070+0000] {subprocess.py:93} INFO -   File "/home/***/.local/lib/python3.12/site-packages/kafka/client_async.py", line 262, in __init__
[2025-06-01T14:16:53.718+0000] {subprocess.py:93} INFO -     self.config['api_version'] = self.check_version()
[2025-06-01T14:16:53.719+0000] {subprocess.py:93} INFO -                                  ^^^^^^^^^^^^^^^^^^^^
[2025-06-01T14:16:53.720+0000] {subprocess.py:93} INFO -   File "/home/***/.local/lib/python3.12/site-packages/kafka/client_async.py", line 1074, in check_version
[2025-06-01T14:16:54.409+0000] {subprocess.py:93} INFO -     raise Errors.NoBrokersAvailable()
[2025-06-01T14:16:54.410+0000] {subprocess.py:93} INFO - kafka.errors.NoBrokersAvailable: NoBrokersAvailable
[2025-06-01T14:16:54.526+0000] {subprocess.py:97} INFO - Command exited with return code 1
[2025-06-01T14:16:54.856+0000] {taskinstance.py:3310} ERROR - Task failed with exception
Traceback (most recent call last):
  File "/home/airflow/.local/lib/python3.12/site-packages/airflow/models/taskinstance.py", line 767, in _execute_task
    result = _execute_callable(context=context, **execute_callable_kwargs)
             ^^^^^^^^^^^^^^^^^^^^^^^^^^^^^^^^^^^^^^^^^^^^^^^^^^^^^^^^^^^^^
  File "/home/airflow/.local/lib/python3.12/site-packages/airflow/models/taskinstance.py", line 733, in _execute_callable
    return ExecutionCallableRunner(
           ^^^^^^^^^^^^^^^^^^^^^^^^
  File "/home/airflow/.local/lib/python3.12/site-packages/airflow/utils/operator_helpers.py", line 252, in run
    return self.func(*args, **kwargs)
           ^^^^^^^^^^^^^^^^^^^^^^^^^^
  File "/home/airflow/.local/lib/python3.12/site-packages/airflow/models/baseoperator.py", line 406, in wrapper
    return func(self, *args, **kwargs)
           ^^^^^^^^^^^^^^^^^^^^^^^^^^^
  File "/home/airflow/.local/lib/python3.12/site-packages/airflow/operators/bash.py", line 249, in execute
    raise AirflowException(
airflow.exceptions.AirflowException: Bash command failed. The command returned a non-zero exit code 1.
[2025-06-01T14:16:54.861+0000] {taskinstance.py:1225} INFO - Marking task as FAILED. dag_id=log_monitoring_dag, task_id=start_log_producer, run_id=manual__2025-06-01T13:21:18.917724+00:00, execution_date=20250601T132118, start_date=20250601T141557, end_date=20250601T141654
[2025-06-01T14:16:55.999+0000] {taskinstance.py:340} INFO - ::group::Post task execution logs
[2025-06-01T14:16:56.000+0000] {standard_task_runner.py:124} ERROR - Failed to execute job 152 for task start_log_producer (Bash command failed. The command returned a non-zero exit code 1.; 180)
Traceback (most recent call last):
  File "/home/airflow/.local/lib/python3.12/site-packages/airflow/task/task_runner/standard_task_runner.py", line 117, in _start_by_fork
    ret = args.func(args, dag=self.dag)
          ^^^^^^^^^^^^^^^^^^^^^^^^^^^^^
  File "/home/airflow/.local/lib/python3.12/site-packages/airflow/cli/cli_config.py", line 49, in command
    return func(*args, **kwargs)
           ^^^^^^^^^^^^^^^^^^^^^
  File "/home/airflow/.local/lib/python3.12/site-packages/airflow/utils/cli.py", line 115, in wrapper
    return f(*args, **kwargs)
           ^^^^^^^^^^^^^^^^^^
  File "/home/airflow/.local/lib/python3.12/site-packages/airflow/cli/commands/task_command.py", line 483, in task_run
    task_return_code = _run_task_by_selected_method(args, _dag, ti)
                       ^^^^^^^^^^^^^^^^^^^^^^^^^^^^^^^^^^^^^^^^^^^^
  File "/home/airflow/.local/lib/python3.12/site-packages/airflow/cli/commands/task_command.py", line 256, in _run_task_by_selected_method
    return _run_raw_task(args, ti)
           ^^^^^^^^^^^^^^^^^^^^^^^
  File "/home/airflow/.local/lib/python3.12/site-packages/airflow/cli/commands/task_command.py", line 341, in _run_raw_task
    return ti._run_raw_task(
           ^^^^^^^^^^^^^^^^^
  File "/home/airflow/.local/lib/python3.12/site-packages/airflow/utils/session.py", line 97, in wrapper
    return func(*args, session=session, **kwargs)
           ^^^^^^^^^^^^^^^^^^^^^^^^^^^^^^^^^^^^^^
  File "/home/airflow/.local/lib/python3.12/site-packages/airflow/models/taskinstance.py", line 3004, in _run_raw_task
    return _run_raw_task(
           ^^^^^^^^^^^^^^
  File "/home/airflow/.local/lib/python3.12/site-packages/airflow/models/taskinstance.py", line 273, in _run_raw_task
    TaskInstance._execute_task_with_callbacks(
  File "/home/airflow/.local/lib/python3.12/site-packages/airflow/models/taskinstance.py", line 3158, in _execute_task_with_callbacks
    result = self._execute_task(context, task_orig)
             ^^^^^^^^^^^^^^^^^^^^^^^^^^^^^^^^^^^^^^
  File "/home/airflow/.local/lib/python3.12/site-packages/airflow/models/taskinstance.py", line 3182, in _execute_task
    return _execute_task(self, context, task_orig)
           ^^^^^^^^^^^^^^^^^^^^^^^^^^^^^^^^^^^^^^^
  File "/home/airflow/.local/lib/python3.12/site-packages/airflow/models/taskinstance.py", line 767, in _execute_task
    result = _execute_callable(context=context, **execute_callable_kwargs)
             ^^^^^^^^^^^^^^^^^^^^^^^^^^^^^^^^^^^^^^^^^^^^^^^^^^^^^^^^^^^^^
  File "/home/airflow/.local/lib/python3.12/site-packages/airflow/models/taskinstance.py", line 733, in _execute_callable
    return ExecutionCallableRunner(
           ^^^^^^^^^^^^^^^^^^^^^^^^
  File "/home/airflow/.local/lib/python3.12/site-packages/airflow/utils/operator_helpers.py", line 252, in run
    return self.func(*args, **kwargs)
           ^^^^^^^^^^^^^^^^^^^^^^^^^^
  File "/home/airflow/.local/lib/python3.12/site-packages/airflow/models/baseoperator.py", line 406, in wrapper
    return func(self, *args, **kwargs)
           ^^^^^^^^^^^^^^^^^^^^^^^^^^^
  File "/home/airflow/.local/lib/python3.12/site-packages/airflow/operators/bash.py", line 249, in execute
    raise AirflowException(
airflow.exceptions.AirflowException: Bash command failed. The command returned a non-zero exit code 1.
[2025-06-01T14:16:56.038+0000] {local_task_job_runner.py:266} INFO - Task exited with return code 1
[2025-06-01T14:16:56.187+0000] {standard_task_runner.py:217} INFO - Process not found (most likely exited), stop collecting metrics
[2025-06-01T14:16:56.199+0000] {taskinstance.py:3900} INFO - 0 downstream tasks scheduled from follow-on schedule check
[2025-06-01T14:16:56.208+0000] {local_task_job_runner.py:245} INFO - ::endgroup::
