[2025-06-02T14:02:00.212+0000] {local_task_job_runner.py:123} INFO - ::group::Pre task execution logs
[2025-06-02T14:02:00.245+0000] {taskinstance.py:2612} INFO - Dependencies all met for dep_context=non-requeueable deps ti=<TaskInstance: log_monitoring_dag.run_alert_script manual__2025-06-02T12:54:53.448668+00:00 [queued]>
[2025-06-02T14:02:00.261+0000] {taskinstance.py:2612} INFO - Dependencies all met for dep_context=requeueable deps ti=<TaskInstance: log_monitoring_dag.run_alert_script manual__2025-06-02T12:54:53.448668+00:00 [queued]>
[2025-06-02T14:02:00.262+0000] {taskinstance.py:2865} INFO - Starting attempt 6 of 7
[2025-06-02T14:02:00.290+0000] {taskinstance.py:2888} INFO - Executing <Task(BashOperator): run_alert_script> on 2025-06-02 12:54:53.448668+00:00
[2025-06-02T14:02:00.305+0000] {logging_mixin.py:190} WARNING - /home/***/.local/lib/python3.12/site-packages/***/task/task_runner/standard_task_runner.py:70 DeprecationWarning: This process (pid=968) is multi-threaded, use of fork() may lead to deadlocks in the child.
[2025-06-02T14:02:00.303+0000] {standard_task_runner.py:104} INFO - Running: ['***', 'tasks', 'run', 'log_monitoring_dag', 'run_alert_script', 'manual__2025-06-02T12:54:53.448668+00:00', '--job-id', '105', '--raw', '--subdir', 'DAGS_FOLDER/log_monitoring_dag.py', '--cfg-path', '/tmp/tmp2h6ok_us']
[2025-06-02T14:02:00.309+0000] {standard_task_runner.py:72} INFO - Started process 969 to run task
[2025-06-02T14:02:00.309+0000] {standard_task_runner.py:105} INFO - Job 105: Subtask run_alert_script
[2025-06-02T14:02:00.345+0000] {logging_mixin.py:190} WARNING - /home/***/.local/lib/python3.12/site-packages/***/settings.py:209 DeprecationWarning: The sql_alchemy_conn option in [core] has been moved to the sql_alchemy_conn option in [database] - the old setting has been used, but please update your config.
[2025-06-02T14:02:00.393+0000] {task_command.py:467} INFO - Running <TaskInstance: log_monitoring_dag.run_alert_script manual__2025-06-02T12:54:53.448668+00:00 [running]> on host c47ce43ea693
[2025-06-02T14:02:00.496+0000] {taskinstance.py:3131} INFO - Exporting env vars: AIRFLOW_CTX_DAG_OWNER='***' AIRFLOW_CTX_DAG_ID='log_monitoring_dag' AIRFLOW_CTX_TASK_ID='run_alert_script' AIRFLOW_CTX_EXECUTION_DATE='2025-06-02T12:54:53.448668+00:00' AIRFLOW_CTX_TRY_NUMBER='6' AIRFLOW_CTX_DAG_RUN_ID='manual__2025-06-02T12:54:53.448668+00:00'
[2025-06-02T14:02:00.497+0000] {taskinstance.py:731} INFO - ::endgroup::
[2025-06-02T14:02:00.517+0000] {subprocess.py:63} INFO - Tmp dir root location: /tmp
[2025-06-02T14:02:00.519+0000] {subprocess.py:75} INFO - Running command: ['/usr/bin/bash', '-c', 'python /opt/***/app/error_alert.py']
[2025-06-02T14:02:00.590+0000] {subprocess.py:86} INFO - Output:
[2025-06-02T14:02:01.256+0000] {subprocess.py:93} INFO - Traceback (most recent call last):
[2025-06-02T14:02:01.257+0000] {subprocess.py:93} INFO -   File "/opt/***/app/error_alert.py", line 14, in <module>
[2025-06-02T14:02:01.260+0000] {subprocess.py:93} INFO -     for filename in os.listdir(log_dir):
[2025-06-02T14:02:01.261+0000] {subprocess.py:93} INFO -                     ^^^^^^^^^^^^^^^^^^^
[2025-06-02T14:02:01.261+0000] {subprocess.py:93} INFO - FileNotFoundError: [Errno 2] No such file or directory: './output/error_logs'
[2025-06-02T14:02:01.266+0000] {subprocess.py:97} INFO - Command exited with return code 1
[2025-06-02T14:02:01.279+0000] {taskinstance.py:3310} ERROR - Task failed with exception
Traceback (most recent call last):
  File "/home/airflow/.local/lib/python3.12/site-packages/airflow/models/taskinstance.py", line 767, in _execute_task
    result = _execute_callable(context=context, **execute_callable_kwargs)
             ^^^^^^^^^^^^^^^^^^^^^^^^^^^^^^^^^^^^^^^^^^^^^^^^^^^^^^^^^^^^^
  File "/home/airflow/.local/lib/python3.12/site-packages/airflow/models/taskinstance.py", line 733, in _execute_callable
    return ExecutionCallableRunner(
           ^^^^^^^^^^^^^^^^^^^^^^^^
  File "/home/airflow/.local/lib/python3.12/site-packages/airflow/utils/operator_helpers.py", line 252, in run
    return self.func(*args, **kwargs)
           ^^^^^^^^^^^^^^^^^^^^^^^^^^
  File "/home/airflow/.local/lib/python3.12/site-packages/airflow/models/baseoperator.py", line 406, in wrapper
    return func(self, *args, **kwargs)
           ^^^^^^^^^^^^^^^^^^^^^^^^^^^
  File "/home/airflow/.local/lib/python3.12/site-packages/airflow/operators/bash.py", line 249, in execute
    raise AirflowException(
airflow.exceptions.AirflowException: Bash command failed. The command returned a non-zero exit code 1.
[2025-06-02T14:02:01.289+0000] {taskinstance.py:1225} INFO - Marking task as UP_FOR_RETRY. dag_id=log_monitoring_dag, task_id=run_alert_script, run_id=manual__2025-06-02T12:54:53.448668+00:00, execution_date=20250602T125453, start_date=20250602T140200, end_date=20250602T140201
[2025-06-02T14:02:01.312+0000] {taskinstance.py:340} INFO - ::group::Post task execution logs
[2025-06-02T14:02:01.313+0000] {standard_task_runner.py:124} ERROR - Failed to execute job 105 for task run_alert_script (Bash command failed. The command returned a non-zero exit code 1.; 969)
Traceback (most recent call last):
  File "/home/airflow/.local/lib/python3.12/site-packages/airflow/task/task_runner/standard_task_runner.py", line 117, in _start_by_fork
    ret = args.func(args, dag=self.dag)
          ^^^^^^^^^^^^^^^^^^^^^^^^^^^^^
  File "/home/airflow/.local/lib/python3.12/site-packages/airflow/cli/cli_config.py", line 49, in command
    return func(*args, **kwargs)
           ^^^^^^^^^^^^^^^^^^^^^
  File "/home/airflow/.local/lib/python3.12/site-packages/airflow/utils/cli.py", line 115, in wrapper
    return f(*args, **kwargs)
           ^^^^^^^^^^^^^^^^^^
  File "/home/airflow/.local/lib/python3.12/site-packages/airflow/cli/commands/task_command.py", line 483, in task_run
    task_return_code = _run_task_by_selected_method(args, _dag, ti)
                       ^^^^^^^^^^^^^^^^^^^^^^^^^^^^^^^^^^^^^^^^^^^^
  File "/home/airflow/.local/lib/python3.12/site-packages/airflow/cli/commands/task_command.py", line 256, in _run_task_by_selected_method
    return _run_raw_task(args, ti)
           ^^^^^^^^^^^^^^^^^^^^^^^
  File "/home/airflow/.local/lib/python3.12/site-packages/airflow/cli/commands/task_command.py", line 341, in _run_raw_task
    return ti._run_raw_task(
           ^^^^^^^^^^^^^^^^^
  File "/home/airflow/.local/lib/python3.12/site-packages/airflow/utils/session.py", line 97, in wrapper
    return func(*args, session=session, **kwargs)
           ^^^^^^^^^^^^^^^^^^^^^^^^^^^^^^^^^^^^^^
  File "/home/airflow/.local/lib/python3.12/site-packages/airflow/models/taskinstance.py", line 3004, in _run_raw_task
    return _run_raw_task(
           ^^^^^^^^^^^^^^
  File "/home/airflow/.local/lib/python3.12/site-packages/airflow/models/taskinstance.py", line 273, in _run_raw_task
    TaskInstance._execute_task_with_callbacks(
  File "/home/airflow/.local/lib/python3.12/site-packages/airflow/models/taskinstance.py", line 3158, in _execute_task_with_callbacks
    result = self._execute_task(context, task_orig)
             ^^^^^^^^^^^^^^^^^^^^^^^^^^^^^^^^^^^^^^
  File "/home/airflow/.local/lib/python3.12/site-packages/airflow/models/taskinstance.py", line 3182, in _execute_task
    return _execute_task(self, context, task_orig)
           ^^^^^^^^^^^^^^^^^^^^^^^^^^^^^^^^^^^^^^^
  File "/home/airflow/.local/lib/python3.12/site-packages/airflow/models/taskinstance.py", line 767, in _execute_task
    result = _execute_callable(context=context, **execute_callable_kwargs)
             ^^^^^^^^^^^^^^^^^^^^^^^^^^^^^^^^^^^^^^^^^^^^^^^^^^^^^^^^^^^^^
  File "/home/airflow/.local/lib/python3.12/site-packages/airflow/models/taskinstance.py", line 733, in _execute_callable
    return ExecutionCallableRunner(
           ^^^^^^^^^^^^^^^^^^^^^^^^
  File "/home/airflow/.local/lib/python3.12/site-packages/airflow/utils/operator_helpers.py", line 252, in run
    return self.func(*args, **kwargs)
           ^^^^^^^^^^^^^^^^^^^^^^^^^^
  File "/home/airflow/.local/lib/python3.12/site-packages/airflow/models/baseoperator.py", line 406, in wrapper
    return func(self, *args, **kwargs)
           ^^^^^^^^^^^^^^^^^^^^^^^^^^^
  File "/home/airflow/.local/lib/python3.12/site-packages/airflow/operators/bash.py", line 249, in execute
    raise AirflowException(
airflow.exceptions.AirflowException: Bash command failed. The command returned a non-zero exit code 1.
[2025-06-02T14:02:01.330+0000] {local_task_job_runner.py:266} INFO - Task exited with return code 1
[2025-06-02T14:02:01.355+0000] {taskinstance.py:3900} INFO - 0 downstream tasks scheduled from follow-on schedule check
[2025-06-02T14:02:01.361+0000] {local_task_job_runner.py:245} INFO - ::endgroup::
