[2025-06-02T11:01:33.042+0000] {local_task_job_runner.py:123} INFO - ::group::Pre task execution logs
[2025-06-02T11:01:33.059+0000] {taskinstance.py:2612} INFO - Dependencies all met for dep_context=non-requeueable deps ti=<TaskInstance: log_monitoring_dag.start_spark_consumer manual__2025-06-02T01:38:51.955055+00:00 [queued]>
[2025-06-02T11:01:33.067+0000] {taskinstance.py:2612} INFO - Dependencies all met for dep_context=requeueable deps ti=<TaskInstance: log_monitoring_dag.start_spark_consumer manual__2025-06-02T01:38:51.955055+00:00 [queued]>
[2025-06-02T11:01:33.068+0000] {taskinstance.py:2865} INFO - Starting attempt 15 of 15
[2025-06-02T11:01:33.083+0000] {taskinstance.py:2888} INFO - Executing <Task(BashOperator): start_spark_consumer> on 2025-06-02 01:38:51.955055+00:00
[2025-06-02T11:01:33.090+0000] {logging_mixin.py:190} WARNING - /home/***/.local/lib/python3.12/site-packages/***/task/task_runner/standard_task_runner.py:70 DeprecationWarning: This process (pid=488) is multi-threaded, use of fork() may lead to deadlocks in the child.
[2025-06-02T11:01:33.092+0000] {standard_task_runner.py:72} INFO - Started process 489 to run task
[2025-06-02T11:01:33.090+0000] {standard_task_runner.py:104} INFO - Running: ['***', 'tasks', 'run', 'log_monitoring_dag', 'start_spark_consumer', 'manual__2025-06-02T01:38:51.955055+00:00', '--job-id', '86', '--raw', '--subdir', 'DAGS_FOLDER/log_monitoring_dag.py', '--cfg-path', '/tmp/tmpic4q2fn9']
[2025-06-02T11:01:33.093+0000] {standard_task_runner.py:105} INFO - Job 86: Subtask start_spark_consumer
[2025-06-02T11:01:33.113+0000] {logging_mixin.py:190} WARNING - /home/***/.local/lib/python3.12/site-packages/***/settings.py:209 DeprecationWarning: The sql_alchemy_conn option in [core] has been moved to the sql_alchemy_conn option in [database] - the old setting has been used, but please update your config.
[2025-06-02T11:01:33.145+0000] {task_command.py:467} INFO - Running <TaskInstance: log_monitoring_dag.start_spark_consumer manual__2025-06-02T01:38:51.955055+00:00 [running]> on host 7fbbdd5b97b6
[2025-06-02T11:01:33.270+0000] {taskinstance.py:3131} INFO - Exporting env vars: AIRFLOW_CTX_DAG_OWNER='***' AIRFLOW_CTX_DAG_ID='log_monitoring_dag' AIRFLOW_CTX_TASK_ID='start_spark_consumer' AIRFLOW_CTX_EXECUTION_DATE='2025-06-02T01:38:51.955055+00:00' AIRFLOW_CTX_TRY_NUMBER='15' AIRFLOW_CTX_DAG_RUN_ID='manual__2025-06-02T01:38:51.955055+00:00'
[2025-06-02T11:01:33.271+0000] {taskinstance.py:731} INFO - ::endgroup::
[2025-06-02T11:01:33.287+0000] {subprocess.py:63} INFO - Tmp dir root location: /tmp
[2025-06-02T11:01:33.288+0000] {subprocess.py:75} INFO - Running command: ['/usr/bin/bash', '-c', 'docker exec -it realtime_log_monitoring-spark-1 spark-submit --packages org.apache.spark:spark-sql-kafka-0-10_2.12:3.3.0 /app/log_consumer.py']
[2025-06-02T11:01:33.300+0000] {subprocess.py:86} INFO - Output:
[2025-06-02T11:01:33.324+0000] {subprocess.py:93} INFO - the input device is not a TTY
[2025-06-02T11:01:33.326+0000] {subprocess.py:97} INFO - Command exited with return code 1
[2025-06-02T11:01:33.337+0000] {taskinstance.py:3310} ERROR - Task failed with exception
Traceback (most recent call last):
  File "/home/airflow/.local/lib/python3.12/site-packages/airflow/models/taskinstance.py", line 767, in _execute_task
    result = _execute_callable(context=context, **execute_callable_kwargs)
             ^^^^^^^^^^^^^^^^^^^^^^^^^^^^^^^^^^^^^^^^^^^^^^^^^^^^^^^^^^^^^
  File "/home/airflow/.local/lib/python3.12/site-packages/airflow/models/taskinstance.py", line 733, in _execute_callable
    return ExecutionCallableRunner(
           ^^^^^^^^^^^^^^^^^^^^^^^^
  File "/home/airflow/.local/lib/python3.12/site-packages/airflow/utils/operator_helpers.py", line 252, in run
    return self.func(*args, **kwargs)
           ^^^^^^^^^^^^^^^^^^^^^^^^^^
  File "/home/airflow/.local/lib/python3.12/site-packages/airflow/models/baseoperator.py", line 406, in wrapper
    return func(self, *args, **kwargs)
           ^^^^^^^^^^^^^^^^^^^^^^^^^^^
  File "/home/airflow/.local/lib/python3.12/site-packages/airflow/operators/bash.py", line 249, in execute
    raise AirflowException(
airflow.exceptions.AirflowException: Bash command failed. The command returned a non-zero exit code 1.
[2025-06-02T11:01:33.341+0000] {taskinstance.py:1225} INFO - Marking task as FAILED. dag_id=log_monitoring_dag, task_id=start_spark_consumer, run_id=manual__2025-06-02T01:38:51.955055+00:00, execution_date=20250602T013851, start_date=20250602T110133, end_date=20250602T110133
[2025-06-02T11:01:33.355+0000] {taskinstance.py:340} INFO - ::group::Post task execution logs
[2025-06-02T11:01:33.356+0000] {standard_task_runner.py:124} ERROR - Failed to execute job 86 for task start_spark_consumer (Bash command failed. The command returned a non-zero exit code 1.; 489)
Traceback (most recent call last):
  File "/home/airflow/.local/lib/python3.12/site-packages/airflow/task/task_runner/standard_task_runner.py", line 117, in _start_by_fork
    ret = args.func(args, dag=self.dag)
          ^^^^^^^^^^^^^^^^^^^^^^^^^^^^^
  File "/home/airflow/.local/lib/python3.12/site-packages/airflow/cli/cli_config.py", line 49, in command
    return func(*args, **kwargs)
           ^^^^^^^^^^^^^^^^^^^^^
  File "/home/airflow/.local/lib/python3.12/site-packages/airflow/utils/cli.py", line 115, in wrapper
    return f(*args, **kwargs)
           ^^^^^^^^^^^^^^^^^^
  File "/home/airflow/.local/lib/python3.12/site-packages/airflow/cli/commands/task_command.py", line 483, in task_run
    task_return_code = _run_task_by_selected_method(args, _dag, ti)
                       ^^^^^^^^^^^^^^^^^^^^^^^^^^^^^^^^^^^^^^^^^^^^
  File "/home/airflow/.local/lib/python3.12/site-packages/airflow/cli/commands/task_command.py", line 256, in _run_task_by_selected_method
    return _run_raw_task(args, ti)
           ^^^^^^^^^^^^^^^^^^^^^^^
  File "/home/airflow/.local/lib/python3.12/site-packages/airflow/cli/commands/task_command.py", line 341, in _run_raw_task
    return ti._run_raw_task(
           ^^^^^^^^^^^^^^^^^
  File "/home/airflow/.local/lib/python3.12/site-packages/airflow/utils/session.py", line 97, in wrapper
    return func(*args, session=session, **kwargs)
           ^^^^^^^^^^^^^^^^^^^^^^^^^^^^^^^^^^^^^^
  File "/home/airflow/.local/lib/python3.12/site-packages/airflow/models/taskinstance.py", line 3004, in _run_raw_task
    return _run_raw_task(
           ^^^^^^^^^^^^^^
  File "/home/airflow/.local/lib/python3.12/site-packages/airflow/models/taskinstance.py", line 273, in _run_raw_task
    TaskInstance._execute_task_with_callbacks(
  File "/home/airflow/.local/lib/python3.12/site-packages/airflow/models/taskinstance.py", line 3158, in _execute_task_with_callbacks
    result = self._execute_task(context, task_orig)
             ^^^^^^^^^^^^^^^^^^^^^^^^^^^^^^^^^^^^^^
  File "/home/airflow/.local/lib/python3.12/site-packages/airflow/models/taskinstance.py", line 3182, in _execute_task
    return _execute_task(self, context, task_orig)
           ^^^^^^^^^^^^^^^^^^^^^^^^^^^^^^^^^^^^^^^
  File "/home/airflow/.local/lib/python3.12/site-packages/airflow/models/taskinstance.py", line 767, in _execute_task
    result = _execute_callable(context=context, **execute_callable_kwargs)
             ^^^^^^^^^^^^^^^^^^^^^^^^^^^^^^^^^^^^^^^^^^^^^^^^^^^^^^^^^^^^^
  File "/home/airflow/.local/lib/python3.12/site-packages/airflow/models/taskinstance.py", line 733, in _execute_callable
    return ExecutionCallableRunner(
           ^^^^^^^^^^^^^^^^^^^^^^^^
  File "/home/airflow/.local/lib/python3.12/site-packages/airflow/utils/operator_helpers.py", line 252, in run
    return self.func(*args, **kwargs)
           ^^^^^^^^^^^^^^^^^^^^^^^^^^
  File "/home/airflow/.local/lib/python3.12/site-packages/airflow/models/baseoperator.py", line 406, in wrapper
    return func(self, *args, **kwargs)
           ^^^^^^^^^^^^^^^^^^^^^^^^^^^
  File "/home/airflow/.local/lib/python3.12/site-packages/airflow/operators/bash.py", line 249, in execute
    raise AirflowException(
airflow.exceptions.AirflowException: Bash command failed. The command returned a non-zero exit code 1.
[2025-06-02T11:01:33.388+0000] {local_task_job_runner.py:266} INFO - Task exited with return code 1
[2025-06-02T11:01:33.411+0000] {taskinstance.py:3900} INFO - 0 downstream tasks scheduled from follow-on schedule check
[2025-06-02T11:01:33.419+0000] {local_task_job_runner.py:245} INFO - ::endgroup::
