[2025-05-31T23:02:31.052+0000] {local_task_job_runner.py:123} INFO - ::group::Pre task execution logs
[2025-05-31T23:03:26.718+0000] {taskinstance.py:2612} INFO - Dependencies all met for dep_context=non-requeueable deps ti=<TaskInstance: log_monitoring_dag.start_log_producer scheduled__2025-05-31T20:45:00+00:00 [queued]>
[2025-05-31T23:03:29.870+0000] {taskinstance.py:2612} INFO - Dependencies all met for dep_context=requeueable deps ti=<TaskInstance: log_monitoring_dag.start_log_producer scheduled__2025-05-31T20:45:00+00:00 [queued]>
[2025-05-31T23:03:29.932+0000] {taskinstance.py:2865} INFO - Starting attempt 2 of 2
[2025-05-31T23:03:35.056+0000] {taskinstance.py:2888} INFO - Executing <Task(BashOperator): start_log_producer> on 2025-05-31 20:45:00+00:00
[2025-05-31T23:03:38.735+0000] {logging_mixin.py:190} WARNING - /home/***/.local/lib/python3.12/site-packages/***/task/task_runner/standard_task_runner.py:70 DeprecationWarning: This process (pid=1144) is multi-threaded, use of fork() may lead to deadlocks in the child.
[2025-05-31T23:03:41.593+0000] {standard_task_runner.py:72} INFO - Started process 1169 to run task
[2025-05-31T23:04:04.670+0000] {standard_task_runner.py:104} INFO - Running: ['***', 'tasks', 'run', 'log_monitoring_dag', 'start_log_producer', 'scheduled__2025-05-31T20:45:00+00:00', '--job-id', '47', '--raw', '--subdir', 'DAGS_FOLDER/log_monitoring_dag.py', '--cfg-path', '/tmp/tmpp_ak75uk']
[2025-05-31T23:04:14.731+0000] {standard_task_runner.py:105} INFO - Job 47: Subtask start_log_producer
[2025-05-31T23:05:37.106+0000] {logging_mixin.py:190} WARNING - /home/***/.local/lib/python3.12/site-packages/***/settings.py:209 DeprecationWarning: The sql_alchemy_conn option in [core] has been moved to the sql_alchemy_conn option in [database] - the old setting has been used, but please update your config.
[2025-05-31T23:05:40.953+0000] {job.py:229} INFO - Heartbeat recovered after 216.53 seconds
[2025-05-31T23:06:06.143+0000] {job.py:229} INFO - Heartbeat recovered after 28.39 seconds
[2025-05-31T23:06:18.755+0000] {task_command.py:467} INFO - Running <TaskInstance: log_monitoring_dag.start_log_producer scheduled__2025-05-31T20:45:00+00:00 [running]> on host fcc5407a0544
[2025-05-31T23:06:19.341+0000] {logging_mixin.py:190} WARNING - /home/***/.local/lib/python3.12/site-packages/***/settings.py:470 DeprecationWarning: The sql_alchemy_conn option in [core] has been moved to the sql_alchemy_conn option in [database] - the old setting has been used, but please update your config.
[2025-05-31T23:06:38.931+0000] {job.py:229} INFO - Heartbeat recovered after 37.95 seconds
[2025-05-31T23:07:08.417+0000] {job.py:229} INFO - Heartbeat recovered after 33.67 seconds
[2025-05-31T23:07:55.679+0000] {job.py:229} INFO - Heartbeat recovered after 56.45 seconds
[2025-05-31T23:08:05.964+0000] {taskinstance.py:3131} INFO - Exporting env vars: AIRFLOW_CTX_DAG_OWNER='***' AIRFLOW_CTX_DAG_ID='log_monitoring_dag' AIRFLOW_CTX_TASK_ID='start_log_producer' AIRFLOW_CTX_EXECUTION_DATE='2025-05-31T20:45:00+00:00' AIRFLOW_CTX_TRY_NUMBER='2' AIRFLOW_CTX_DAG_RUN_ID='scheduled__2025-05-31T20:45:00+00:00'
[2025-05-31T23:08:06.528+0000] {taskinstance.py:731} INFO - ::endgroup::
[2025-05-31T23:08:30.636+0000] {job.py:229} INFO - Heartbeat recovered after 35.25 seconds
[2025-05-31T23:08:39.003+0000] {subprocess.py:63} INFO - Tmp dir root location: /tmp
[2025-05-31T23:08:40.797+0000] {subprocess.py:75} INFO - Running command: ['/usr/bin/bash', '-c', 'cd /opt/***/app && python -u log_producer.py']
[2025-05-31T23:08:50.983+0000] {subprocess.py:86} INFO - Output:
[2025-05-31T23:09:14.020+0000] {job.py:229} INFO - Heartbeat recovered after 43.78 seconds
[2025-05-31T23:09:35.418+0000] {job.py:229} INFO - Heartbeat recovered after 22.13 seconds
[2025-05-31T23:09:48.379+0000] {job.py:229} INFO - Heartbeat recovered after 13.37 seconds
[2025-05-31T23:10:41.766+0000] {job.py:229} INFO - Heartbeat recovered after 40.08 seconds
[2025-05-31T23:11:03.097+0000] {job.py:229} INFO - Heartbeat recovered after 15.90 seconds
[2025-05-31T23:11:23.933+0000] {job.py:229} INFO - Heartbeat recovered after 21.30 seconds
[2025-05-31T23:11:43.074+0000] {job.py:229} INFO - Heartbeat recovered after 24.97 seconds
[2025-05-31T23:11:56.608+0000] {job.py:229} INFO - Heartbeat recovered after 14.85 seconds
[2025-05-31T23:12:17.270+0000] {job.py:229} INFO - Heartbeat recovered after 13.73 seconds
[2025-05-31T23:12:31.674+0000] {job.py:229} INFO - Heartbeat recovered after 16.30 seconds
[2025-05-31T23:12:40.302+0000] {subprocess.py:93} INFO - Traceback (most recent call last):
[2025-05-31T23:12:40.348+0000] {subprocess.py:93} INFO -   File "/opt/***/app/log_producer.py", line 7, in <module>
[2025-05-31T23:12:40.425+0000] {subprocess.py:93} INFO -     producer = KafkaProducer(
[2025-05-31T23:12:40.428+0000] {subprocess.py:93} INFO -                ^^^^^^^^^^^^^^
[2025-05-31T23:12:40.429+0000] {subprocess.py:93} INFO -   File "/home/***/.local/lib/python3.12/site-packages/kafka/producer/kafka.py", line 481, in __init__
[2025-05-31T23:12:40.630+0000] {subprocess.py:93} INFO -     client = self.config['kafka_client'](
[2025-05-31T23:12:40.866+0000] {subprocess.py:93} INFO -              ^^^^^^^^^^^^^^^^^^^^^^^^^^^^
[2025-05-31T23:12:41.347+0000] {subprocess.py:93} INFO -   File "/home/***/.local/lib/python3.12/site-packages/kafka/client_async.py", line 262, in __init__
[2025-05-31T23:12:41.365+0000] {subprocess.py:93} INFO -     self.config['api_version'] = self.check_version()
[2025-05-31T23:12:41.399+0000] {subprocess.py:93} INFO -                                  ^^^^^^^^^^^^^^^^^^^^
[2025-05-31T23:12:41.420+0000] {subprocess.py:93} INFO -   File "/home/***/.local/lib/python3.12/site-packages/kafka/client_async.py", line 1074, in check_version
[2025-05-31T23:12:41.457+0000] {subprocess.py:93} INFO -     raise Errors.NoBrokersAvailable()
[2025-05-31T23:12:41.509+0000] {subprocess.py:93} INFO - kafka.errors.NoBrokersAvailable: NoBrokersAvailable
[2025-05-31T23:12:41.516+0000] {subprocess.py:97} INFO - Command exited with return code 1
[2025-05-31T23:12:43.084+0000] {taskinstance.py:3310} ERROR - Task failed with exception
Traceback (most recent call last):
  File "/home/airflow/.local/lib/python3.12/site-packages/airflow/models/taskinstance.py", line 767, in _execute_task
    result = _execute_callable(context=context, **execute_callable_kwargs)
             ^^^^^^^^^^^^^^^^^^^^^^^^^^^^^^^^^^^^^^^^^^^^^^^^^^^^^^^^^^^^^
  File "/home/airflow/.local/lib/python3.12/site-packages/airflow/models/taskinstance.py", line 733, in _execute_callable
    return ExecutionCallableRunner(
           ^^^^^^^^^^^^^^^^^^^^^^^^
  File "/home/airflow/.local/lib/python3.12/site-packages/airflow/utils/operator_helpers.py", line 252, in run
    return self.func(*args, **kwargs)
           ^^^^^^^^^^^^^^^^^^^^^^^^^^
  File "/home/airflow/.local/lib/python3.12/site-packages/airflow/models/baseoperator.py", line 406, in wrapper
    return func(self, *args, **kwargs)
           ^^^^^^^^^^^^^^^^^^^^^^^^^^^
  File "/home/airflow/.local/lib/python3.12/site-packages/airflow/operators/bash.py", line 249, in execute
    raise AirflowException(
airflow.exceptions.AirflowException: Bash command failed. The command returned a non-zero exit code 1.
[2025-05-31T23:12:46.964+0000] {taskinstance.py:1225} INFO - Marking task as FAILED. dag_id=log_monitoring_dag, task_id=start_log_producer, run_id=scheduled__2025-05-31T20:45:00+00:00, execution_date=20250531T204500, start_date=20250531T230326, end_date=20250531T231246
[2025-05-31T23:12:56.784+0000] {taskinstance.py:340} INFO - ::group::Post task execution logs
[2025-05-31T23:12:57.296+0000] {standard_task_runner.py:124} ERROR - Failed to execute job 47 for task start_log_producer (Bash command failed. The command returned a non-zero exit code 1.; 1169)
Traceback (most recent call last):
  File "/home/airflow/.local/lib/python3.12/site-packages/airflow/task/task_runner/standard_task_runner.py", line 117, in _start_by_fork
    ret = args.func(args, dag=self.dag)
          ^^^^^^^^^^^^^^^^^^^^^^^^^^^^^
  File "/home/airflow/.local/lib/python3.12/site-packages/airflow/cli/cli_config.py", line 49, in command
    return func(*args, **kwargs)
           ^^^^^^^^^^^^^^^^^^^^^
  File "/home/airflow/.local/lib/python3.12/site-packages/airflow/utils/cli.py", line 115, in wrapper
    return f(*args, **kwargs)
           ^^^^^^^^^^^^^^^^^^
  File "/home/airflow/.local/lib/python3.12/site-packages/airflow/cli/commands/task_command.py", line 483, in task_run
    task_return_code = _run_task_by_selected_method(args, _dag, ti)
                       ^^^^^^^^^^^^^^^^^^^^^^^^^^^^^^^^^^^^^^^^^^^^
  File "/home/airflow/.local/lib/python3.12/site-packages/airflow/cli/commands/task_command.py", line 256, in _run_task_by_selected_method
    return _run_raw_task(args, ti)
           ^^^^^^^^^^^^^^^^^^^^^^^
  File "/home/airflow/.local/lib/python3.12/site-packages/airflow/cli/commands/task_command.py", line 341, in _run_raw_task
    return ti._run_raw_task(
           ^^^^^^^^^^^^^^^^^
  File "/home/airflow/.local/lib/python3.12/site-packages/airflow/utils/session.py", line 97, in wrapper
    return func(*args, session=session, **kwargs)
           ^^^^^^^^^^^^^^^^^^^^^^^^^^^^^^^^^^^^^^
  File "/home/airflow/.local/lib/python3.12/site-packages/airflow/models/taskinstance.py", line 3004, in _run_raw_task
    return _run_raw_task(
           ^^^^^^^^^^^^^^
  File "/home/airflow/.local/lib/python3.12/site-packages/airflow/models/taskinstance.py", line 273, in _run_raw_task
    TaskInstance._execute_task_with_callbacks(
  File "/home/airflow/.local/lib/python3.12/site-packages/airflow/models/taskinstance.py", line 3158, in _execute_task_with_callbacks
    result = self._execute_task(context, task_orig)
             ^^^^^^^^^^^^^^^^^^^^^^^^^^^^^^^^^^^^^^
  File "/home/airflow/.local/lib/python3.12/site-packages/airflow/models/taskinstance.py", line 3182, in _execute_task
    return _execute_task(self, context, task_orig)
           ^^^^^^^^^^^^^^^^^^^^^^^^^^^^^^^^^^^^^^^
  File "/home/airflow/.local/lib/python3.12/site-packages/airflow/models/taskinstance.py", line 767, in _execute_task
    result = _execute_callable(context=context, **execute_callable_kwargs)
             ^^^^^^^^^^^^^^^^^^^^^^^^^^^^^^^^^^^^^^^^^^^^^^^^^^^^^^^^^^^^^
  File "/home/airflow/.local/lib/python3.12/site-packages/airflow/models/taskinstance.py", line 733, in _execute_callable
    return ExecutionCallableRunner(
           ^^^^^^^^^^^^^^^^^^^^^^^^
  File "/home/airflow/.local/lib/python3.12/site-packages/airflow/utils/operator_helpers.py", line 252, in run
    return self.func(*args, **kwargs)
           ^^^^^^^^^^^^^^^^^^^^^^^^^^
  File "/home/airflow/.local/lib/python3.12/site-packages/airflow/models/baseoperator.py", line 406, in wrapper
    return func(self, *args, **kwargs)
           ^^^^^^^^^^^^^^^^^^^^^^^^^^^
  File "/home/airflow/.local/lib/python3.12/site-packages/airflow/operators/bash.py", line 249, in execute
    raise AirflowException(
airflow.exceptions.AirflowException: Bash command failed. The command returned a non-zero exit code 1.
[2025-05-31T23:12:58.887+0000] {local_task_job_runner.py:266} INFO - Task exited with return code 1
[2025-05-31T23:13:02.274+0000] {standard_task_runner.py:217} INFO - Process not found (most likely exited), stop collecting metrics
[2025-05-31T23:13:08.791+0000] {taskinstance.py:3900} INFO - 0 downstream tasks scheduled from follow-on schedule check
[2025-05-31T23:13:10.883+0000] {local_task_job_runner.py:245} INFO - ::endgroup::
