[2025-05-27T13:00:03.623+0000] {local_task_job_runner.py:123} INFO - ::group::Pre task execution logs
[2025-05-27T13:00:03.651+0000] {taskinstance.py:2612} INFO - Dependencies all met for dep_context=non-requeueable deps ti=<TaskInstance: log_monitoring_dag.start_log_producer manual__2025-05-27T12:58:55.251313+00:00 [queued]>
[2025-05-27T13:00:03.670+0000] {taskinstance.py:2612} INFO - Dependencies all met for dep_context=requeueable deps ti=<TaskInstance: log_monitoring_dag.start_log_producer manual__2025-05-27T12:58:55.251313+00:00 [queued]>
[2025-05-27T13:00:03.674+0000] {taskinstance.py:2865} INFO - Starting attempt 2 of 2
[2025-05-27T13:00:03.708+0000] {taskinstance.py:2888} INFO - Executing <Task(BashOperator): start_log_producer> on 2025-05-27 12:58:55.251313+00:00
[2025-05-27T13:00:03.719+0000] {logging_mixin.py:190} WARNING - /home/***/.local/lib/python3.12/site-packages/***/task/task_runner/standard_task_runner.py:70 DeprecationWarning: This process (pid=201) is multi-threaded, use of fork() may lead to deadlocks in the child.
[2025-05-27T13:00:03.721+0000] {standard_task_runner.py:72} INFO - Started process 202 to run task
[2025-05-27T13:00:03.720+0000] {standard_task_runner.py:104} INFO - Running: ['***', 'tasks', 'run', 'log_monitoring_dag', 'start_log_producer', 'manual__2025-05-27T12:58:55.251313+00:00', '--job-id', '43', '--raw', '--subdir', 'DAGS_FOLDER/log_monitoring_dag.py', '--cfg-path', '/tmp/tmpewwbbabu']
[2025-05-27T13:00:03.728+0000] {standard_task_runner.py:105} INFO - Job 43: Subtask start_log_producer
[2025-05-27T13:00:03.766+0000] {logging_mixin.py:190} WARNING - /home/***/.local/lib/python3.12/site-packages/***/settings.py:209 DeprecationWarning: The sql_alchemy_conn option in [core] has been moved to the sql_alchemy_conn option in [database] - the old setting has been used, but please update your config.
[2025-05-27T13:00:03.819+0000] {task_command.py:467} INFO - Running <TaskInstance: log_monitoring_dag.start_log_producer manual__2025-05-27T12:58:55.251313+00:00 [running]> on host f4ba84ec87a4
[2025-05-27T13:00:03.977+0000] {taskinstance.py:3131} INFO - Exporting env vars: AIRFLOW_CTX_DAG_OWNER='***' AIRFLOW_CTX_DAG_ID='log_monitoring_dag' AIRFLOW_CTX_TASK_ID='start_log_producer' AIRFLOW_CTX_EXECUTION_DATE='2025-05-27T12:58:55.251313+00:00' AIRFLOW_CTX_TRY_NUMBER='2' AIRFLOW_CTX_DAG_RUN_ID='manual__2025-05-27T12:58:55.251313+00:00'
[2025-05-27T13:00:03.978+0000] {taskinstance.py:731} INFO - ::endgroup::
[2025-05-27T13:00:04.128+0000] {subprocess.py:63} INFO - Tmp dir root location: /tmp
[2025-05-27T13:00:04.143+0000] {subprocess.py:75} INFO - Running command: ['/usr/bin/bash', '-c', 'python /app/log_producer.py']
[2025-05-27T13:00:04.168+0000] {subprocess.py:86} INFO - Output:
[2025-05-27T13:00:04.301+0000] {subprocess.py:93} INFO - Traceback (most recent call last):
[2025-05-27T13:00:04.302+0000] {subprocess.py:93} INFO -   File "/app/log_producer.py", line 1, in <module>
[2025-05-27T13:00:04.303+0000] {subprocess.py:93} INFO -     from kafka import KafkaProducer
[2025-05-27T13:00:04.304+0000] {subprocess.py:93} INFO - ModuleNotFoundError: No module named 'kafka'
[2025-05-27T13:00:04.308+0000] {subprocess.py:97} INFO - Command exited with return code 1
[2025-05-27T13:00:04.414+0000] {taskinstance.py:3310} ERROR - Task failed with exception
Traceback (most recent call last):
  File "/home/airflow/.local/lib/python3.12/site-packages/airflow/models/taskinstance.py", line 767, in _execute_task
    result = _execute_callable(context=context, **execute_callable_kwargs)
             ^^^^^^^^^^^^^^^^^^^^^^^^^^^^^^^^^^^^^^^^^^^^^^^^^^^^^^^^^^^^^
  File "/home/airflow/.local/lib/python3.12/site-packages/airflow/models/taskinstance.py", line 733, in _execute_callable
    return ExecutionCallableRunner(
           ^^^^^^^^^^^^^^^^^^^^^^^^
  File "/home/airflow/.local/lib/python3.12/site-packages/airflow/utils/operator_helpers.py", line 252, in run
    return self.func(*args, **kwargs)
           ^^^^^^^^^^^^^^^^^^^^^^^^^^
  File "/home/airflow/.local/lib/python3.12/site-packages/airflow/models/baseoperator.py", line 406, in wrapper
    return func(self, *args, **kwargs)
           ^^^^^^^^^^^^^^^^^^^^^^^^^^^
  File "/home/airflow/.local/lib/python3.12/site-packages/airflow/operators/bash.py", line 249, in execute
    raise AirflowException(
airflow.exceptions.AirflowException: Bash command failed. The command returned a non-zero exit code 1.
[2025-05-27T13:00:04.447+0000] {taskinstance.py:1225} INFO - Marking task as FAILED. dag_id=log_monitoring_dag, task_id=start_log_producer, run_id=manual__2025-05-27T12:58:55.251313+00:00, execution_date=20250527T125855, start_date=20250527T130003, end_date=20250527T130004
[2025-05-27T13:00:04.489+0000] {taskinstance.py:340} INFO - ::group::Post task execution logs
[2025-05-27T13:00:04.490+0000] {standard_task_runner.py:124} ERROR - Failed to execute job 43 for task start_log_producer (Bash command failed. The command returned a non-zero exit code 1.; 202)
Traceback (most recent call last):
  File "/home/airflow/.local/lib/python3.12/site-packages/airflow/task/task_runner/standard_task_runner.py", line 117, in _start_by_fork
    ret = args.func(args, dag=self.dag)
          ^^^^^^^^^^^^^^^^^^^^^^^^^^^^^
  File "/home/airflow/.local/lib/python3.12/site-packages/airflow/cli/cli_config.py", line 49, in command
    return func(*args, **kwargs)
           ^^^^^^^^^^^^^^^^^^^^^
  File "/home/airflow/.local/lib/python3.12/site-packages/airflow/utils/cli.py", line 115, in wrapper
    return f(*args, **kwargs)
           ^^^^^^^^^^^^^^^^^^
  File "/home/airflow/.local/lib/python3.12/site-packages/airflow/cli/commands/task_command.py", line 483, in task_run
    task_return_code = _run_task_by_selected_method(args, _dag, ti)
                       ^^^^^^^^^^^^^^^^^^^^^^^^^^^^^^^^^^^^^^^^^^^^
  File "/home/airflow/.local/lib/python3.12/site-packages/airflow/cli/commands/task_command.py", line 256, in _run_task_by_selected_method
    return _run_raw_task(args, ti)
           ^^^^^^^^^^^^^^^^^^^^^^^
  File "/home/airflow/.local/lib/python3.12/site-packages/airflow/cli/commands/task_command.py", line 341, in _run_raw_task
    return ti._run_raw_task(
           ^^^^^^^^^^^^^^^^^
  File "/home/airflow/.local/lib/python3.12/site-packages/airflow/utils/session.py", line 97, in wrapper
    return func(*args, session=session, **kwargs)
           ^^^^^^^^^^^^^^^^^^^^^^^^^^^^^^^^^^^^^^
  File "/home/airflow/.local/lib/python3.12/site-packages/airflow/models/taskinstance.py", line 3004, in _run_raw_task
    return _run_raw_task(
           ^^^^^^^^^^^^^^
  File "/home/airflow/.local/lib/python3.12/site-packages/airflow/models/taskinstance.py", line 273, in _run_raw_task
    TaskInstance._execute_task_with_callbacks(
  File "/home/airflow/.local/lib/python3.12/site-packages/airflow/models/taskinstance.py", line 3158, in _execute_task_with_callbacks
    result = self._execute_task(context, task_orig)
             ^^^^^^^^^^^^^^^^^^^^^^^^^^^^^^^^^^^^^^
  File "/home/airflow/.local/lib/python3.12/site-packages/airflow/models/taskinstance.py", line 3182, in _execute_task
    return _execute_task(self, context, task_orig)
           ^^^^^^^^^^^^^^^^^^^^^^^^^^^^^^^^^^^^^^^
  File "/home/airflow/.local/lib/python3.12/site-packages/airflow/models/taskinstance.py", line 767, in _execute_task
    result = _execute_callable(context=context, **execute_callable_kwargs)
             ^^^^^^^^^^^^^^^^^^^^^^^^^^^^^^^^^^^^^^^^^^^^^^^^^^^^^^^^^^^^^
  File "/home/airflow/.local/lib/python3.12/site-packages/airflow/models/taskinstance.py", line 733, in _execute_callable
    return ExecutionCallableRunner(
           ^^^^^^^^^^^^^^^^^^^^^^^^
  File "/home/airflow/.local/lib/python3.12/site-packages/airflow/utils/operator_helpers.py", line 252, in run
    return self.func(*args, **kwargs)
           ^^^^^^^^^^^^^^^^^^^^^^^^^^
  File "/home/airflow/.local/lib/python3.12/site-packages/airflow/models/baseoperator.py", line 406, in wrapper
    return func(self, *args, **kwargs)
           ^^^^^^^^^^^^^^^^^^^^^^^^^^^
  File "/home/airflow/.local/lib/python3.12/site-packages/airflow/operators/bash.py", line 249, in execute
    raise AirflowException(
airflow.exceptions.AirflowException: Bash command failed. The command returned a non-zero exit code 1.
[2025-05-27T13:00:04.543+0000] {local_task_job_runner.py:266} INFO - Task exited with return code 1
[2025-05-27T13:00:04.584+0000] {taskinstance.py:3900} INFO - 0 downstream tasks scheduled from follow-on schedule check
[2025-05-27T13:00:04.590+0000] {local_task_job_runner.py:245} INFO - ::endgroup::
