[2025-05-31T16:30:57.446+0000] {local_task_job_runner.py:123} INFO - ::group::Pre task execution logs
[2025-05-31T16:31:00.904+0000] {taskinstance.py:2612} INFO - Dependencies all met for dep_context=non-requeueable deps ti=<TaskInstance: log_monitoring_dag.start_log_producer scheduled__2025-05-28T05:50:00+00:00 [queued]>
[2025-05-31T16:31:02.934+0000] {taskinstance.py:2612} INFO - Dependencies all met for dep_context=requeueable deps ti=<TaskInstance: log_monitoring_dag.start_log_producer scheduled__2025-05-28T05:50:00+00:00 [queued]>
[2025-05-31T16:31:03.438+0000] {taskinstance.py:2865} INFO - Starting attempt 5 of 2
[2025-05-31T16:31:06.838+0000] {taskinstance.py:2888} INFO - Executing <Task(BashOperator): start_log_producer> on 2025-05-28 05:50:00+00:00
[2025-05-31T16:31:17.409+0000] {standard_task_runner.py:104} INFO - Running: ['***', 'tasks', 'run', 'log_monitoring_dag', 'start_log_producer', 'scheduled__2025-05-28T05:50:00+00:00', '--job-id', '210', '--raw', '--subdir', 'DAGS_FOLDER/log_monitoring_dag.py', '--cfg-path', '/tmp/tmp98oicewr']
[2025-05-31T16:31:19.598+0000] {standard_task_runner.py:105} INFO - Job 210: Subtask start_log_producer
[2025-05-31T16:31:23.825+0000] {logging_mixin.py:190} WARNING - /home/***/.local/lib/python3.12/site-packages/***/task/task_runner/standard_task_runner.py:70 DeprecationWarning: This process (pid=744) is multi-threaded, use of fork() may lead to deadlocks in the child.
[2025-05-31T16:31:23.827+0000] {standard_task_runner.py:72} INFO - Started process 776 to run task
[2025-05-31T16:31:38.672+0000] {logging_mixin.py:190} WARNING - /home/***/.local/lib/python3.12/site-packages/***/settings.py:209 DeprecationWarning: The sql_alchemy_conn option in [core] has been moved to the sql_alchemy_conn option in [database] - the old setting has been used, but please update your config.
[2025-05-31T16:31:45.091+0000] {job.py:229} INFO - Heartbeat recovered after 86.91 seconds
[2025-05-31T16:31:57.506+0000] {job.py:229} INFO - Heartbeat recovered after 13.55 seconds
[2025-05-31T16:32:02.250+0000] {task_command.py:467} INFO - Running <TaskInstance: log_monitoring_dag.start_log_producer scheduled__2025-05-28T05:50:00+00:00 [running]> on host 1d31c4e9dbe9
[2025-05-31T16:32:02.683+0000] {logging_mixin.py:190} WARNING - /home/***/.local/lib/python3.12/site-packages/***/settings.py:470 DeprecationWarning: The sql_alchemy_conn option in [core] has been moved to the sql_alchemy_conn option in [database] - the old setting has been used, but please update your config.
[2025-05-31T16:32:23.334+0000] {taskinstance.py:3131} INFO - Exporting env vars: AIRFLOW_CTX_DAG_OWNER='***' AIRFLOW_CTX_DAG_ID='log_monitoring_dag' AIRFLOW_CTX_TASK_ID='start_log_producer' AIRFLOW_CTX_EXECUTION_DATE='2025-05-28T05:50:00+00:00' AIRFLOW_CTX_TRY_NUMBER='5' AIRFLOW_CTX_DAG_RUN_ID='scheduled__2025-05-28T05:50:00+00:00'
[2025-05-31T16:32:23.338+0000] {taskinstance.py:731} INFO - ::endgroup::
[2025-05-31T16:32:24.937+0000] {job.py:229} INFO - Heartbeat recovered after 28.17 seconds
[2025-05-31T16:32:25.561+0000] {subprocess.py:63} INFO - Tmp dir root location: /tmp
[2025-05-31T16:32:27.001+0000] {subprocess.py:75} INFO - Running command: ['/usr/bin/bash', '-c', 'cd /opt/***/app && python -u log_producer.py']
[2025-05-31T16:32:29.295+0000] {subprocess.py:86} INFO - Output:
[2025-05-31T16:32:38.123+0000] {job.py:229} INFO - Heartbeat recovered after 14.26 seconds
[2025-05-31T16:32:52.059+0000] {job.py:229} INFO - Heartbeat recovered after 14.69 seconds
[2025-05-31T16:33:11.276+0000] {job.py:229} INFO - Heartbeat recovered after 12.73 seconds
[2025-05-31T16:33:23.391+0000] {job.py:229} INFO - Heartbeat recovered after 12.60 seconds
[2025-05-31T16:33:46.921+0000] {job.py:229} INFO - Heartbeat recovered after 11.81 seconds
[2025-05-31T16:34:01.289+0000] {job.py:229} INFO - Heartbeat recovered after 16.88 seconds
[2025-05-31T16:35:34.562+0000] {job.py:229} INFO - Heartbeat recovered after 94.81 seconds
[2025-05-31T16:35:40.369+0000] {subprocess.py:93} INFO - Traceback (most recent call last):
[2025-05-31T16:35:40.625+0000] {subprocess.py:93} INFO -   File "/opt/***/app/log_producer.py", line 7, in <module>
[2025-05-31T16:35:41.152+0000] {subprocess.py:93} INFO -     producer = KafkaProducer(
[2025-05-31T16:35:41.152+0000] {subprocess.py:93} INFO -                ^^^^^^^^^^^^^^
[2025-05-31T16:35:41.153+0000] {subprocess.py:93} INFO -   File "/home/***/.local/lib/python3.12/site-packages/kafka/producer/kafka.py", line 481, in __init__
[2025-05-31T16:35:41.179+0000] {subprocess.py:93} INFO -     client = self.config['kafka_client'](
[2025-05-31T16:35:41.209+0000] {subprocess.py:93} INFO -              ^^^^^^^^^^^^^^^^^^^^^^^^^^^^
[2025-05-31T16:35:41.210+0000] {subprocess.py:93} INFO -   File "/home/***/.local/lib/python3.12/site-packages/kafka/client_async.py", line 262, in __init__
[2025-05-31T16:35:45.713+0000] {subprocess.py:93} INFO -     self.config['api_version'] = self.check_version()
[2025-05-31T16:35:46.471+0000] {subprocess.py:93} INFO -                                  ^^^^^^^^^^^^^^^^^^^^
[2025-05-31T16:35:46.860+0000] {subprocess.py:93} INFO -   File "/home/***/.local/lib/python3.12/site-packages/kafka/client_async.py", line 1074, in check_version
[2025-05-31T16:35:46.879+0000] {subprocess.py:93} INFO -     raise Errors.NoBrokersAvailable()
[2025-05-31T16:35:47.329+0000] {subprocess.py:93} INFO - kafka.errors.NoBrokersAvailable: NoBrokersAvailable
[2025-05-31T16:35:48.732+0000] {job.py:229} INFO - Heartbeat recovered after 45.33 seconds
[2025-05-31T16:35:48.926+0000] {subprocess.py:97} INFO - Command exited with return code 1
[2025-05-31T16:35:49.835+0000] {taskinstance.py:3310} ERROR - Task failed with exception
Traceback (most recent call last):
  File "/home/airflow/.local/lib/python3.12/site-packages/airflow/models/taskinstance.py", line 767, in _execute_task
    result = _execute_callable(context=context, **execute_callable_kwargs)
             ^^^^^^^^^^^^^^^^^^^^^^^^^^^^^^^^^^^^^^^^^^^^^^^^^^^^^^^^^^^^^
  File "/home/airflow/.local/lib/python3.12/site-packages/airflow/models/taskinstance.py", line 733, in _execute_callable
    return ExecutionCallableRunner(
           ^^^^^^^^^^^^^^^^^^^^^^^^
  File "/home/airflow/.local/lib/python3.12/site-packages/airflow/utils/operator_helpers.py", line 252, in run
    return self.func(*args, **kwargs)
           ^^^^^^^^^^^^^^^^^^^^^^^^^^
  File "/home/airflow/.local/lib/python3.12/site-packages/airflow/models/baseoperator.py", line 406, in wrapper
    return func(self, *args, **kwargs)
           ^^^^^^^^^^^^^^^^^^^^^^^^^^^
  File "/home/airflow/.local/lib/python3.12/site-packages/airflow/operators/bash.py", line 249, in execute
    raise AirflowException(
airflow.exceptions.AirflowException: Bash command failed. The command returned a non-zero exit code 1.
[2025-05-31T16:35:50.215+0000] {taskinstance.py:1225} INFO - Marking task as FAILED. dag_id=log_monitoring_dag, task_id=start_log_producer, run_id=scheduled__2025-05-28T05:50:00+00:00, execution_date=20250528T055000, start_date=20250531T163101, end_date=20250531T163550
[2025-05-31T16:35:51.111+0000] {taskinstance.py:340} INFO - ::group::Post task execution logs
[2025-05-31T16:35:51.271+0000] {standard_task_runner.py:124} ERROR - Failed to execute job 210 for task start_log_producer (Bash command failed. The command returned a non-zero exit code 1.; 776)
Traceback (most recent call last):
  File "/home/airflow/.local/lib/python3.12/site-packages/airflow/task/task_runner/standard_task_runner.py", line 117, in _start_by_fork
    ret = args.func(args, dag=self.dag)
          ^^^^^^^^^^^^^^^^^^^^^^^^^^^^^
  File "/home/airflow/.local/lib/python3.12/site-packages/airflow/cli/cli_config.py", line 49, in command
    return func(*args, **kwargs)
           ^^^^^^^^^^^^^^^^^^^^^
  File "/home/airflow/.local/lib/python3.12/site-packages/airflow/utils/cli.py", line 115, in wrapper
    return f(*args, **kwargs)
           ^^^^^^^^^^^^^^^^^^
  File "/home/airflow/.local/lib/python3.12/site-packages/airflow/cli/commands/task_command.py", line 483, in task_run
    task_return_code = _run_task_by_selected_method(args, _dag, ti)
                       ^^^^^^^^^^^^^^^^^^^^^^^^^^^^^^^^^^^^^^^^^^^^
  File "/home/airflow/.local/lib/python3.12/site-packages/airflow/cli/commands/task_command.py", line 256, in _run_task_by_selected_method
    return _run_raw_task(args, ti)
           ^^^^^^^^^^^^^^^^^^^^^^^
  File "/home/airflow/.local/lib/python3.12/site-packages/airflow/cli/commands/task_command.py", line 341, in _run_raw_task
    return ti._run_raw_task(
           ^^^^^^^^^^^^^^^^^
  File "/home/airflow/.local/lib/python3.12/site-packages/airflow/utils/session.py", line 97, in wrapper
    return func(*args, session=session, **kwargs)
           ^^^^^^^^^^^^^^^^^^^^^^^^^^^^^^^^^^^^^^
  File "/home/airflow/.local/lib/python3.12/site-packages/airflow/models/taskinstance.py", line 3004, in _run_raw_task
    return _run_raw_task(
           ^^^^^^^^^^^^^^
  File "/home/airflow/.local/lib/python3.12/site-packages/airflow/models/taskinstance.py", line 273, in _run_raw_task
    TaskInstance._execute_task_with_callbacks(
  File "/home/airflow/.local/lib/python3.12/site-packages/airflow/models/taskinstance.py", line 3158, in _execute_task_with_callbacks
    result = self._execute_task(context, task_orig)
             ^^^^^^^^^^^^^^^^^^^^^^^^^^^^^^^^^^^^^^
  File "/home/airflow/.local/lib/python3.12/site-packages/airflow/models/taskinstance.py", line 3182, in _execute_task
    return _execute_task(self, context, task_orig)
           ^^^^^^^^^^^^^^^^^^^^^^^^^^^^^^^^^^^^^^^
  File "/home/airflow/.local/lib/python3.12/site-packages/airflow/models/taskinstance.py", line 767, in _execute_task
    result = _execute_callable(context=context, **execute_callable_kwargs)
             ^^^^^^^^^^^^^^^^^^^^^^^^^^^^^^^^^^^^^^^^^^^^^^^^^^^^^^^^^^^^^
  File "/home/airflow/.local/lib/python3.12/site-packages/airflow/models/taskinstance.py", line 733, in _execute_callable
    return ExecutionCallableRunner(
           ^^^^^^^^^^^^^^^^^^^^^^^^
  File "/home/airflow/.local/lib/python3.12/site-packages/airflow/utils/operator_helpers.py", line 252, in run
    return self.func(*args, **kwargs)
           ^^^^^^^^^^^^^^^^^^^^^^^^^^
  File "/home/airflow/.local/lib/python3.12/site-packages/airflow/models/baseoperator.py", line 406, in wrapper
    return func(self, *args, **kwargs)
           ^^^^^^^^^^^^^^^^^^^^^^^^^^^
  File "/home/airflow/.local/lib/python3.12/site-packages/airflow/operators/bash.py", line 249, in execute
    raise AirflowException(
airflow.exceptions.AirflowException: Bash command failed. The command returned a non-zero exit code 1.
[2025-05-31T16:35:51.957+0000] {local_task_job_runner.py:266} INFO - Task exited with return code 1
[2025-05-31T16:35:51.990+0000] {local_task_job_runner.py:245} INFO - ::endgroup::
