[2025-06-02T12:46:30.653+0000] {local_task_job_runner.py:123} INFO - ::group::Pre task execution logs
[2025-06-02T12:46:32.142+0000] {taskinstance.py:2612} INFO - Dependencies all met for dep_context=non-requeueable deps ti=<TaskInstance: log_monitoring_dag.start_log_producer manual__2025-06-02T12:43:37.462206+00:00 [queued]>
[2025-06-02T12:46:32.878+0000] {taskinstance.py:2612} INFO - Dependencies all met for dep_context=requeueable deps ti=<TaskInstance: log_monitoring_dag.start_log_producer manual__2025-06-02T12:43:37.462206+00:00 [queued]>
[2025-06-02T12:46:32.901+0000] {taskinstance.py:2865} INFO - Starting attempt 1 of 2
[2025-06-02T12:46:34.373+0000] {taskinstance.py:2888} INFO - Executing <Task(BashOperator): start_log_producer> on 2025-06-02 12:43:37.462206+00:00
[2025-06-02T12:46:34.476+0000] {standard_task_runner.py:104} INFO - Running: ['***', 'tasks', 'run', 'log_monitoring_dag', 'start_log_producer', 'manual__2025-06-02T12:43:37.462206+00:00', '--job-id', '92', '--raw', '--subdir', 'DAGS_FOLDER/log_monitoring_dag.py', '--cfg-path', '/tmp/tmpzub8g4h0']
[2025-06-02T12:46:34.480+0000] {standard_task_runner.py:105} INFO - Job 92: Subtask start_log_producer
[2025-06-02T12:46:34.497+0000] {logging_mixin.py:190} WARNING - /home/***/.local/lib/python3.12/site-packages/***/task/task_runner/standard_task_runner.py:70 DeprecationWarning: This process (pid=354) is multi-threaded, use of fork() may lead to deadlocks in the child.
[2025-06-02T12:46:34.500+0000] {standard_task_runner.py:72} INFO - Started process 368 to run task
[2025-06-02T12:46:35.143+0000] {logging_mixin.py:190} WARNING - /home/***/.local/lib/python3.12/site-packages/***/settings.py:209 DeprecationWarning: The sql_alchemy_conn option in [core] has been moved to the sql_alchemy_conn option in [database] - the old setting has been used, but please update your config.
[2025-06-02T12:46:36.184+0000] {task_command.py:467} INFO - Running <TaskInstance: log_monitoring_dag.start_log_producer manual__2025-06-02T12:43:37.462206+00:00 [running]> on host c47ce43ea693
[2025-06-02T12:46:41.993+0000] {job.py:229} INFO - Heartbeat recovered after 17.79 seconds
[2025-06-02T12:46:43.197+0000] {taskinstance.py:3131} INFO - Exporting env vars: AIRFLOW_CTX_DAG_OWNER='***' AIRFLOW_CTX_DAG_ID='log_monitoring_dag' AIRFLOW_CTX_TASK_ID='start_log_producer' AIRFLOW_CTX_EXECUTION_DATE='2025-06-02T12:43:37.462206+00:00' AIRFLOW_CTX_TRY_NUMBER='1' AIRFLOW_CTX_DAG_RUN_ID='manual__2025-06-02T12:43:37.462206+00:00'
[2025-06-02T12:46:43.292+0000] {taskinstance.py:731} INFO - ::endgroup::
[2025-06-02T12:46:51.620+0000] {subprocess.py:63} INFO - Tmp dir root location: /tmp
[2025-06-02T12:46:51.996+0000] {subprocess.py:75} INFO - Running command: ['/usr/bin/bash', '-c', 'cd /opt/***/app && python -u log_producer.py']
[2025-06-02T12:46:53.118+0000] {subprocess.py:86} INFO - Output:
[2025-06-02T12:47:53.124+0000] {subprocess.py:93} INFO - Traceback (most recent call last):
[2025-06-02T12:47:53.152+0000] {subprocess.py:93} INFO -   File "/opt/***/app/log_producer.py", line 8, in <module>
[2025-06-02T12:47:53.156+0000] {subprocess.py:93} INFO -     producer = KafkaProducer(
[2025-06-02T12:47:53.201+0000] {subprocess.py:93} INFO -                ^^^^^^^^^^^^^^
[2025-06-02T12:47:53.202+0000] {subprocess.py:93} INFO -   File "/home/***/.local/lib/python3.12/site-packages/kafka/producer/kafka.py", line 481, in __init__
[2025-06-02T12:47:53.203+0000] {subprocess.py:93} INFO -     client = self.config['kafka_client'](
[2025-06-02T12:47:53.204+0000] {subprocess.py:93} INFO -              ^^^^^^^^^^^^^^^^^^^^^^^^^^^^
[2025-06-02T12:47:53.204+0000] {subprocess.py:93} INFO -   File "/home/***/.local/lib/python3.12/site-packages/kafka/client_async.py", line 262, in __init__
[2025-06-02T12:47:53.205+0000] {subprocess.py:93} INFO -     self.config['api_version'] = self.check_version()
[2025-06-02T12:47:53.205+0000] {subprocess.py:93} INFO -                                  ^^^^^^^^^^^^^^^^^^^^
[2025-06-02T12:47:53.206+0000] {subprocess.py:93} INFO -   File "/home/***/.local/lib/python3.12/site-packages/kafka/client_async.py", line 1074, in check_version
[2025-06-02T12:47:53.207+0000] {subprocess.py:93} INFO -     raise Errors.NoBrokersAvailable()
[2025-06-02T12:47:53.207+0000] {subprocess.py:93} INFO - kafka.errors.NoBrokersAvailable: NoBrokersAvailable
[2025-06-02T12:47:54.299+0000] {subprocess.py:97} INFO - Command exited with return code 1
[2025-06-02T12:47:54.800+0000] {taskinstance.py:3310} ERROR - Task failed with exception
Traceback (most recent call last):
  File "/home/airflow/.local/lib/python3.12/site-packages/airflow/models/taskinstance.py", line 767, in _execute_task
    result = _execute_callable(context=context, **execute_callable_kwargs)
             ^^^^^^^^^^^^^^^^^^^^^^^^^^^^^^^^^^^^^^^^^^^^^^^^^^^^^^^^^^^^^
  File "/home/airflow/.local/lib/python3.12/site-packages/airflow/models/taskinstance.py", line 733, in _execute_callable
    return ExecutionCallableRunner(
           ^^^^^^^^^^^^^^^^^^^^^^^^
  File "/home/airflow/.local/lib/python3.12/site-packages/airflow/utils/operator_helpers.py", line 252, in run
    return self.func(*args, **kwargs)
           ^^^^^^^^^^^^^^^^^^^^^^^^^^
  File "/home/airflow/.local/lib/python3.12/site-packages/airflow/models/baseoperator.py", line 406, in wrapper
    return func(self, *args, **kwargs)
           ^^^^^^^^^^^^^^^^^^^^^^^^^^^
  File "/home/airflow/.local/lib/python3.12/site-packages/airflow/operators/bash.py", line 249, in execute
    raise AirflowException(
airflow.exceptions.AirflowException: Bash command failed. The command returned a non-zero exit code 1.
[2025-06-02T12:47:56.801+0000] {taskinstance.py:1225} INFO - Marking task as UP_FOR_RETRY. dag_id=log_monitoring_dag, task_id=start_log_producer, run_id=manual__2025-06-02T12:43:37.462206+00:00, execution_date=20250602T124337, start_date=20250602T124632, end_date=20250602T124756
[2025-06-02T12:47:59.057+0000] {taskinstance.py:340} INFO - ::group::Post task execution logs
[2025-06-02T12:47:59.097+0000] {standard_task_runner.py:124} ERROR - Failed to execute job 92 for task start_log_producer (Bash command failed. The command returned a non-zero exit code 1.; 368)
Traceback (most recent call last):
  File "/home/airflow/.local/lib/python3.12/site-packages/airflow/task/task_runner/standard_task_runner.py", line 117, in _start_by_fork
    ret = args.func(args, dag=self.dag)
          ^^^^^^^^^^^^^^^^^^^^^^^^^^^^^
  File "/home/airflow/.local/lib/python3.12/site-packages/airflow/cli/cli_config.py", line 49, in command
    return func(*args, **kwargs)
           ^^^^^^^^^^^^^^^^^^^^^
  File "/home/airflow/.local/lib/python3.12/site-packages/airflow/utils/cli.py", line 115, in wrapper
    return f(*args, **kwargs)
           ^^^^^^^^^^^^^^^^^^
  File "/home/airflow/.local/lib/python3.12/site-packages/airflow/cli/commands/task_command.py", line 483, in task_run
    task_return_code = _run_task_by_selected_method(args, _dag, ti)
                       ^^^^^^^^^^^^^^^^^^^^^^^^^^^^^^^^^^^^^^^^^^^^
  File "/home/airflow/.local/lib/python3.12/site-packages/airflow/cli/commands/task_command.py", line 256, in _run_task_by_selected_method
    return _run_raw_task(args, ti)
           ^^^^^^^^^^^^^^^^^^^^^^^
  File "/home/airflow/.local/lib/python3.12/site-packages/airflow/cli/commands/task_command.py", line 341, in _run_raw_task
    return ti._run_raw_task(
           ^^^^^^^^^^^^^^^^^
  File "/home/airflow/.local/lib/python3.12/site-packages/airflow/utils/session.py", line 97, in wrapper
    return func(*args, session=session, **kwargs)
           ^^^^^^^^^^^^^^^^^^^^^^^^^^^^^^^^^^^^^^
  File "/home/airflow/.local/lib/python3.12/site-packages/airflow/models/taskinstance.py", line 3004, in _run_raw_task
    return _run_raw_task(
           ^^^^^^^^^^^^^^
  File "/home/airflow/.local/lib/python3.12/site-packages/airflow/models/taskinstance.py", line 273, in _run_raw_task
    TaskInstance._execute_task_with_callbacks(
  File "/home/airflow/.local/lib/python3.12/site-packages/airflow/models/taskinstance.py", line 3158, in _execute_task_with_callbacks
    result = self._execute_task(context, task_orig)
             ^^^^^^^^^^^^^^^^^^^^^^^^^^^^^^^^^^^^^^
  File "/home/airflow/.local/lib/python3.12/site-packages/airflow/models/taskinstance.py", line 3182, in _execute_task
    return _execute_task(self, context, task_orig)
           ^^^^^^^^^^^^^^^^^^^^^^^^^^^^^^^^^^^^^^^
  File "/home/airflow/.local/lib/python3.12/site-packages/airflow/models/taskinstance.py", line 767, in _execute_task
    result = _execute_callable(context=context, **execute_callable_kwargs)
             ^^^^^^^^^^^^^^^^^^^^^^^^^^^^^^^^^^^^^^^^^^^^^^^^^^^^^^^^^^^^^
  File "/home/airflow/.local/lib/python3.12/site-packages/airflow/models/taskinstance.py", line 733, in _execute_callable
    return ExecutionCallableRunner(
           ^^^^^^^^^^^^^^^^^^^^^^^^
  File "/home/airflow/.local/lib/python3.12/site-packages/airflow/utils/operator_helpers.py", line 252, in run
    return self.func(*args, **kwargs)
           ^^^^^^^^^^^^^^^^^^^^^^^^^^
  File "/home/airflow/.local/lib/python3.12/site-packages/airflow/models/baseoperator.py", line 406, in wrapper
    return func(self, *args, **kwargs)
           ^^^^^^^^^^^^^^^^^^^^^^^^^^^
  File "/home/airflow/.local/lib/python3.12/site-packages/airflow/operators/bash.py", line 249, in execute
    raise AirflowException(
airflow.exceptions.AirflowException: Bash command failed. The command returned a non-zero exit code 1.
[2025-06-02T12:47:59.993+0000] {local_task_job_runner.py:266} INFO - Task exited with return code 1
[2025-06-02T12:48:00.732+0000] {taskinstance.py:3900} INFO - 0 downstream tasks scheduled from follow-on schedule check
[2025-06-02T12:48:00.737+0000] {local_task_job_runner.py:245} INFO - ::endgroup::
