[2025-05-31T16:30:30.932+0000] {local_task_job_runner.py:123} INFO - ::group::Pre task execution logs
[2025-05-31T16:30:32.101+0000] {taskinstance.py:2612} INFO - Dependencies all met for dep_context=non-requeueable deps ti=<TaskInstance: log_monitoring_dag.start_log_producer scheduled__2025-05-31T15:40:00+00:00 [queued]>
[2025-05-31T16:30:32.120+0000] {taskinstance.py:2612} INFO - Dependencies all met for dep_context=requeueable deps ti=<TaskInstance: log_monitoring_dag.start_log_producer scheduled__2025-05-31T15:40:00+00:00 [queued]>
[2025-05-31T16:30:32.121+0000] {taskinstance.py:2865} INFO - Starting attempt 2 of 2
[2025-05-31T16:30:33.098+0000] {taskinstance.py:2888} INFO - Executing <Task(BashOperator): start_log_producer> on 2025-05-31 15:40:00+00:00
[2025-05-31T16:30:33.529+0000] {standard_task_runner.py:104} INFO - Running: ['***', 'tasks', 'run', 'log_monitoring_dag', 'start_log_producer', 'scheduled__2025-05-31T15:40:00+00:00', '--job-id', '207', '--raw', '--subdir', 'DAGS_FOLDER/log_monitoring_dag.py', '--cfg-path', '/tmp/tmpz2xriz5c']
[2025-05-31T16:30:43.174+0000] {standard_task_runner.py:105} INFO - Job 207: Subtask start_log_producer
[2025-05-31T16:30:42.582+0000] {logging_mixin.py:190} WARNING - /home/***/.local/lib/python3.12/site-packages/***/task/task_runner/standard_task_runner.py:70 DeprecationWarning: This process (pid=739) is multi-threaded, use of fork() may lead to deadlocks in the child.
[2025-05-31T16:30:45.390+0000] {standard_task_runner.py:72} INFO - Started process 771 to run task
[2025-05-31T16:30:58.956+0000] {logging_mixin.py:190} WARNING - /home/***/.local/lib/python3.12/site-packages/***/settings.py:209 DeprecationWarning: The sql_alchemy_conn option in [core] has been moved to the sql_alchemy_conn option in [database] - the old setting has been used, but please update your config.
[2025-05-31T16:31:09.950+0000] {job.py:229} INFO - Heartbeat recovered after 64.79 seconds
[2025-05-31T16:31:26.375+0000] {job.py:229} INFO - Heartbeat recovered after 20.91 seconds
[2025-05-31T16:31:44.304+0000] {task_command.py:467} INFO - Running <TaskInstance: log_monitoring_dag.start_log_producer scheduled__2025-05-31T15:40:00+00:00 [running]> on host 1d31c4e9dbe9
[2025-05-31T16:31:46.044+0000] {job.py:229} INFO - Heartbeat recovered after 21.78 seconds
[2025-05-31T16:31:44.186+0000] {logging_mixin.py:190} WARNING - /home/***/.local/lib/python3.12/site-packages/***/settings.py:470 DeprecationWarning: The sql_alchemy_conn option in [core] has been moved to the sql_alchemy_conn option in [database] - the old setting has been used, but please update your config.
[2025-05-31T16:32:01.951+0000] {job.py:229} INFO - Heartbeat recovered after 20.21 seconds
[2025-05-31T16:32:23.347+0000] {job.py:229} INFO - Heartbeat recovered after 23.06 seconds
[2025-05-31T16:32:25.324+0000] {taskinstance.py:3131} INFO - Exporting env vars: AIRFLOW_CTX_DAG_OWNER='***' AIRFLOW_CTX_DAG_ID='log_monitoring_dag' AIRFLOW_CTX_TASK_ID='start_log_producer' AIRFLOW_CTX_EXECUTION_DATE='2025-05-31T15:40:00+00:00' AIRFLOW_CTX_TRY_NUMBER='2' AIRFLOW_CTX_DAG_RUN_ID='scheduled__2025-05-31T15:40:00+00:00'
[2025-05-31T16:32:27.842+0000] {taskinstance.py:731} INFO - ::endgroup::
[2025-05-31T16:32:30.208+0000] {subprocess.py:63} INFO - Tmp dir root location: /tmp
[2025-05-31T16:32:30.351+0000] {subprocess.py:75} INFO - Running command: ['/usr/bin/bash', '-c', 'cd /opt/***/app && python -u log_producer.py']
[2025-05-31T16:32:31.593+0000] {subprocess.py:86} INFO - Output:
[2025-05-31T16:32:53.270+0000] {job.py:229} INFO - Heartbeat recovered after 13.55 seconds
[2025-05-31T16:35:34.558+0000] {job.py:229} INFO - Heartbeat recovered after 99.56 seconds
[2025-05-31T16:35:40.362+0000] {subprocess.py:93} INFO - Traceback (most recent call last):
[2025-05-31T16:35:40.626+0000] {subprocess.py:93} INFO -   File "/opt/***/app/log_producer.py", line 7, in <module>
[2025-05-31T16:35:41.283+0000] {subprocess.py:93} INFO -     producer = KafkaProducer(
[2025-05-31T16:35:41.443+0000] {subprocess.py:93} INFO -                ^^^^^^^^^^^^^^
[2025-05-31T16:35:41.756+0000] {subprocess.py:93} INFO -   File "/home/***/.local/lib/python3.12/site-packages/kafka/producer/kafka.py", line 481, in __init__
[2025-05-31T16:35:42.132+0000] {subprocess.py:93} INFO -     client = self.config['kafka_client'](
[2025-05-31T16:35:42.269+0000] {subprocess.py:93} INFO -              ^^^^^^^^^^^^^^^^^^^^^^^^^^^^
[2025-05-31T16:35:42.459+0000] {subprocess.py:93} INFO -   File "/home/***/.local/lib/python3.12/site-packages/kafka/client_async.py", line 262, in __init__
[2025-05-31T16:35:45.716+0000] {subprocess.py:93} INFO -     self.config['api_version'] = self.check_version()
[2025-05-31T16:35:46.471+0000] {subprocess.py:93} INFO -                                  ^^^^^^^^^^^^^^^^^^^^
[2025-05-31T16:35:46.586+0000] {subprocess.py:93} INFO -   File "/home/***/.local/lib/python3.12/site-packages/kafka/client_async.py", line 1074, in check_version
[2025-05-31T16:35:46.880+0000] {subprocess.py:93} INFO -     raise Errors.NoBrokersAvailable()
[2025-05-31T16:35:47.328+0000] {subprocess.py:93} INFO - kafka.errors.NoBrokersAvailable: NoBrokersAvailable
[2025-05-31T16:35:48.930+0000] {subprocess.py:97} INFO - Command exited with return code 1
[2025-05-31T16:35:49.257+0000] {taskinstance.py:3310} ERROR - Task failed with exception
Traceback (most recent call last):
  File "/home/airflow/.local/lib/python3.12/site-packages/airflow/models/taskinstance.py", line 767, in _execute_task
    result = _execute_callable(context=context, **execute_callable_kwargs)
             ^^^^^^^^^^^^^^^^^^^^^^^^^^^^^^^^^^^^^^^^^^^^^^^^^^^^^^^^^^^^^
  File "/home/airflow/.local/lib/python3.12/site-packages/airflow/models/taskinstance.py", line 733, in _execute_callable
    return ExecutionCallableRunner(
           ^^^^^^^^^^^^^^^^^^^^^^^^
  File "/home/airflow/.local/lib/python3.12/site-packages/airflow/utils/operator_helpers.py", line 252, in run
    return self.func(*args, **kwargs)
           ^^^^^^^^^^^^^^^^^^^^^^^^^^
  File "/home/airflow/.local/lib/python3.12/site-packages/airflow/models/baseoperator.py", line 406, in wrapper
    return func(self, *args, **kwargs)
           ^^^^^^^^^^^^^^^^^^^^^^^^^^^
  File "/home/airflow/.local/lib/python3.12/site-packages/airflow/operators/bash.py", line 249, in execute
    raise AirflowException(
airflow.exceptions.AirflowException: Bash command failed. The command returned a non-zero exit code 1.
[2025-05-31T16:35:50.225+0000] {taskinstance.py:1225} INFO - Marking task as FAILED. dag_id=log_monitoring_dag, task_id=start_log_producer, run_id=scheduled__2025-05-31T15:40:00+00:00, execution_date=20250531T154000, start_date=20250531T163032, end_date=20250531T163549
[2025-05-31T16:35:50.402+0000] {job.py:229} INFO - Heartbeat recovered after 44.20 seconds
[2025-05-31T16:35:51.111+0000] {taskinstance.py:340} INFO - ::group::Post task execution logs
[2025-05-31T16:35:51.269+0000] {standard_task_runner.py:124} ERROR - Failed to execute job 207 for task start_log_producer (Bash command failed. The command returned a non-zero exit code 1.; 771)
Traceback (most recent call last):
  File "/home/airflow/.local/lib/python3.12/site-packages/airflow/task/task_runner/standard_task_runner.py", line 117, in _start_by_fork
    ret = args.func(args, dag=self.dag)
          ^^^^^^^^^^^^^^^^^^^^^^^^^^^^^
  File "/home/airflow/.local/lib/python3.12/site-packages/airflow/cli/cli_config.py", line 49, in command
    return func(*args, **kwargs)
           ^^^^^^^^^^^^^^^^^^^^^
  File "/home/airflow/.local/lib/python3.12/site-packages/airflow/utils/cli.py", line 115, in wrapper
    return f(*args, **kwargs)
           ^^^^^^^^^^^^^^^^^^
  File "/home/airflow/.local/lib/python3.12/site-packages/airflow/cli/commands/task_command.py", line 483, in task_run
    task_return_code = _run_task_by_selected_method(args, _dag, ti)
                       ^^^^^^^^^^^^^^^^^^^^^^^^^^^^^^^^^^^^^^^^^^^^
  File "/home/airflow/.local/lib/python3.12/site-packages/airflow/cli/commands/task_command.py", line 256, in _run_task_by_selected_method
    return _run_raw_task(args, ti)
           ^^^^^^^^^^^^^^^^^^^^^^^
  File "/home/airflow/.local/lib/python3.12/site-packages/airflow/cli/commands/task_command.py", line 341, in _run_raw_task
    return ti._run_raw_task(
           ^^^^^^^^^^^^^^^^^
  File "/home/airflow/.local/lib/python3.12/site-packages/airflow/utils/session.py", line 97, in wrapper
    return func(*args, session=session, **kwargs)
           ^^^^^^^^^^^^^^^^^^^^^^^^^^^^^^^^^^^^^^
  File "/home/airflow/.local/lib/python3.12/site-packages/airflow/models/taskinstance.py", line 3004, in _run_raw_task
    return _run_raw_task(
           ^^^^^^^^^^^^^^
  File "/home/airflow/.local/lib/python3.12/site-packages/airflow/models/taskinstance.py", line 273, in _run_raw_task
    TaskInstance._execute_task_with_callbacks(
  File "/home/airflow/.local/lib/python3.12/site-packages/airflow/models/taskinstance.py", line 3158, in _execute_task_with_callbacks
    result = self._execute_task(context, task_orig)
             ^^^^^^^^^^^^^^^^^^^^^^^^^^^^^^^^^^^^^^
  File "/home/airflow/.local/lib/python3.12/site-packages/airflow/models/taskinstance.py", line 3182, in _execute_task
    return _execute_task(self, context, task_orig)
           ^^^^^^^^^^^^^^^^^^^^^^^^^^^^^^^^^^^^^^^
  File "/home/airflow/.local/lib/python3.12/site-packages/airflow/models/taskinstance.py", line 767, in _execute_task
    result = _execute_callable(context=context, **execute_callable_kwargs)
             ^^^^^^^^^^^^^^^^^^^^^^^^^^^^^^^^^^^^^^^^^^^^^^^^^^^^^^^^^^^^^
  File "/home/airflow/.local/lib/python3.12/site-packages/airflow/models/taskinstance.py", line 733, in _execute_callable
    return ExecutionCallableRunner(
           ^^^^^^^^^^^^^^^^^^^^^^^^
  File "/home/airflow/.local/lib/python3.12/site-packages/airflow/utils/operator_helpers.py", line 252, in run
    return self.func(*args, **kwargs)
           ^^^^^^^^^^^^^^^^^^^^^^^^^^
  File "/home/airflow/.local/lib/python3.12/site-packages/airflow/models/baseoperator.py", line 406, in wrapper
    return func(self, *args, **kwargs)
           ^^^^^^^^^^^^^^^^^^^^^^^^^^^
  File "/home/airflow/.local/lib/python3.12/site-packages/airflow/operators/bash.py", line 249, in execute
    raise AirflowException(
airflow.exceptions.AirflowException: Bash command failed. The command returned a non-zero exit code 1.
[2025-05-31T16:35:52.027+0000] {local_task_job_runner.py:266} INFO - Task exited with return code 1
[2025-05-31T16:35:52.146+0000] {local_task_job_runner.py:245} INFO - ::endgroup::
