[2025-06-02T00:20:01.421+0000] {local_task_job_runner.py:123} INFO - ::group::Pre task execution logs
[2025-06-02T00:20:07.123+0000] {taskinstance.py:2612} INFO - Dependencies all met for dep_context=non-requeueable deps ti=<TaskInstance: log_monitoring_dag.start_log_producer manual__2025-06-02T00:17:16.073341+00:00 [queued]>
[2025-06-02T00:20:07.708+0000] {taskinstance.py:2612} INFO - Dependencies all met for dep_context=requeueable deps ti=<TaskInstance: log_monitoring_dag.start_log_producer manual__2025-06-02T00:17:16.073341+00:00 [queued]>
[2025-06-02T00:20:07.709+0000] {taskinstance.py:2865} INFO - Starting attempt 2 of 2
[2025-06-02T00:20:08.535+0000] {taskinstance.py:2888} INFO - Executing <Task(BashOperator): start_log_producer> on 2025-06-02 00:17:16.073341+00:00
[2025-06-02T00:20:08.846+0000] {standard_task_runner.py:104} INFO - Running: ['***', 'tasks', 'run', 'log_monitoring_dag', 'start_log_producer', 'manual__2025-06-02T00:17:16.073341+00:00', '--job-id', '41', '--raw', '--subdir', 'DAGS_FOLDER/log_monitoring_dag.py', '--cfg-path', '/tmp/tmp_6u379wf']
[2025-06-02T00:20:10.347+0000] {standard_task_runner.py:105} INFO - Job 41: Subtask start_log_producer
[2025-06-02T00:20:10.946+0000] {logging_mixin.py:190} WARNING - /home/***/.local/lib/python3.12/site-packages/***/task/task_runner/standard_task_runner.py:70 DeprecationWarning: This process (pid=298) is multi-threaded, use of fork() may lead to deadlocks in the child.
[2025-06-02T00:20:10.947+0000] {standard_task_runner.py:72} INFO - Started process 307 to run task
[2025-06-02T00:20:18.092+0000] {logging_mixin.py:190} WARNING - /home/***/.local/lib/python3.12/site-packages/***/settings.py:209 DeprecationWarning: The sql_alchemy_conn option in [core] has been moved to the sql_alchemy_conn option in [database] - the old setting has been used, but please update your config.
[2025-06-02T00:20:24.611+0000] {job.py:229} INFO - Heartbeat recovered after 34.86 seconds
[2025-06-02T00:20:25.970+0000] {task_command.py:467} INFO - Running <TaskInstance: log_monitoring_dag.start_log_producer manual__2025-06-02T00:17:16.073341+00:00 [running]> on host 81b8dfdf3580
[2025-06-02T00:20:34.727+0000] {job.py:229} INFO - Heartbeat recovered after 10.62 seconds
[2025-06-02T00:20:57.222+0000] {taskinstance.py:3131} INFO - Exporting env vars: AIRFLOW_CTX_DAG_OWNER='***' AIRFLOW_CTX_DAG_ID='log_monitoring_dag' AIRFLOW_CTX_TASK_ID='start_log_producer' AIRFLOW_CTX_EXECUTION_DATE='2025-06-02T00:17:16.073341+00:00' AIRFLOW_CTX_TRY_NUMBER='2' AIRFLOW_CTX_DAG_RUN_ID='manual__2025-06-02T00:17:16.073341+00:00'
[2025-06-02T00:20:57.506+0000] {taskinstance.py:731} INFO - ::endgroup::
[2025-06-02T00:21:05.641+0000] {job.py:229} INFO - Heartbeat recovered after 24.18 seconds
[2025-06-02T00:21:09.226+0000] {subprocess.py:63} INFO - Tmp dir root location: /tmp
[2025-06-02T00:21:09.252+0000] {subprocess.py:75} INFO - Running command: ['/usr/bin/bash', '-c', 'cd /opt/***/app && python -u log_producer.py']
[2025-06-02T00:21:09.453+0000] {subprocess.py:86} INFO - Output:
[2025-06-02T00:21:12.247+0000] {job.py:229} INFO - Heartbeat recovered after 15.58 seconds
[2025-06-02T00:22:11.366+0000] {job.py:229} INFO - Heartbeat recovered after 19.38 seconds
[2025-06-02T00:22:33.788+0000] {job.py:229} INFO - Heartbeat recovered after 14.66 seconds
[2025-06-02T00:22:43.003+0000] {job.py:229} INFO - Heartbeat recovered after 12.26 seconds
[2025-06-02T00:22:44.886+0000] {subprocess.py:93} INFO - Traceback (most recent call last):
[2025-06-02T00:22:45.546+0000] {subprocess.py:93} INFO -   File "/opt/***/app/log_producer.py", line 8, in <module>
[2025-06-02T00:22:45.548+0000] {subprocess.py:93} INFO -     producer = KafkaProducer(
[2025-06-02T00:22:45.548+0000] {subprocess.py:93} INFO -                ^^^^^^^^^^^^^^
[2025-06-02T00:22:45.548+0000] {subprocess.py:93} INFO -   File "/home/***/.local/lib/python3.12/site-packages/kafka/producer/kafka.py", line 481, in __init__
[2025-06-02T00:22:47.188+0000] {subprocess.py:93} INFO -     client = self.config['kafka_client'](
[2025-06-02T00:22:47.364+0000] {subprocess.py:93} INFO -              ^^^^^^^^^^^^^^^^^^^^^^^^^^^^
[2025-06-02T00:22:49.448+0000] {subprocess.py:93} INFO -   File "/home/***/.local/lib/python3.12/site-packages/kafka/client_async.py", line 262, in __init__
[2025-06-02T00:22:49.449+0000] {subprocess.py:93} INFO -     self.config['api_version'] = self.check_version()
[2025-06-02T00:22:49.590+0000] {subprocess.py:93} INFO -                                  ^^^^^^^^^^^^^^^^^^^^
[2025-06-02T00:22:49.874+0000] {subprocess.py:93} INFO -   File "/home/***/.local/lib/python3.12/site-packages/kafka/client_async.py", line 1074, in check_version
[2025-06-02T00:22:50.003+0000] {subprocess.py:93} INFO -     raise Errors.NoBrokersAvailable()
[2025-06-02T00:22:50.004+0000] {subprocess.py:93} INFO - kafka.errors.NoBrokersAvailable: NoBrokersAvailable
[2025-06-02T00:22:50.025+0000] {subprocess.py:97} INFO - Command exited with return code 1
[2025-06-02T00:22:50.764+0000] {taskinstance.py:3310} ERROR - Task failed with exception
Traceback (most recent call last):
  File "/home/airflow/.local/lib/python3.12/site-packages/airflow/models/taskinstance.py", line 767, in _execute_task
    result = _execute_callable(context=context, **execute_callable_kwargs)
             ^^^^^^^^^^^^^^^^^^^^^^^^^^^^^^^^^^^^^^^^^^^^^^^^^^^^^^^^^^^^^
  File "/home/airflow/.local/lib/python3.12/site-packages/airflow/models/taskinstance.py", line 733, in _execute_callable
    return ExecutionCallableRunner(
           ^^^^^^^^^^^^^^^^^^^^^^^^
  File "/home/airflow/.local/lib/python3.12/site-packages/airflow/utils/operator_helpers.py", line 252, in run
    return self.func(*args, **kwargs)
           ^^^^^^^^^^^^^^^^^^^^^^^^^^
  File "/home/airflow/.local/lib/python3.12/site-packages/airflow/models/baseoperator.py", line 406, in wrapper
    return func(self, *args, **kwargs)
           ^^^^^^^^^^^^^^^^^^^^^^^^^^^
  File "/home/airflow/.local/lib/python3.12/site-packages/airflow/operators/bash.py", line 249, in execute
    raise AirflowException(
airflow.exceptions.AirflowException: Bash command failed. The command returned a non-zero exit code 1.
[2025-06-02T00:22:51.268+0000] {taskinstance.py:1225} INFO - Marking task as FAILED. dag_id=log_monitoring_dag, task_id=start_log_producer, run_id=manual__2025-06-02T00:17:16.073341+00:00, execution_date=20250602T001716, start_date=20250602T002007, end_date=20250602T002251
[2025-06-02T00:22:52.499+0000] {taskinstance.py:340} INFO - ::group::Post task execution logs
[2025-06-02T00:22:53.328+0000] {job.py:229} INFO - Heartbeat recovered after 10.90 seconds
[2025-06-02T00:22:52.501+0000] {standard_task_runner.py:124} ERROR - Failed to execute job 41 for task start_log_producer (Bash command failed. The command returned a non-zero exit code 1.; 307)
Traceback (most recent call last):
  File "/home/airflow/.local/lib/python3.12/site-packages/airflow/task/task_runner/standard_task_runner.py", line 117, in _start_by_fork
    ret = args.func(args, dag=self.dag)
          ^^^^^^^^^^^^^^^^^^^^^^^^^^^^^
  File "/home/airflow/.local/lib/python3.12/site-packages/airflow/cli/cli_config.py", line 49, in command
    return func(*args, **kwargs)
           ^^^^^^^^^^^^^^^^^^^^^
  File "/home/airflow/.local/lib/python3.12/site-packages/airflow/utils/cli.py", line 115, in wrapper
    return f(*args, **kwargs)
           ^^^^^^^^^^^^^^^^^^
  File "/home/airflow/.local/lib/python3.12/site-packages/airflow/cli/commands/task_command.py", line 483, in task_run
    task_return_code = _run_task_by_selected_method(args, _dag, ti)
                       ^^^^^^^^^^^^^^^^^^^^^^^^^^^^^^^^^^^^^^^^^^^^
  File "/home/airflow/.local/lib/python3.12/site-packages/airflow/cli/commands/task_command.py", line 256, in _run_task_by_selected_method
    return _run_raw_task(args, ti)
           ^^^^^^^^^^^^^^^^^^^^^^^
  File "/home/airflow/.local/lib/python3.12/site-packages/airflow/cli/commands/task_command.py", line 341, in _run_raw_task
    return ti._run_raw_task(
           ^^^^^^^^^^^^^^^^^
  File "/home/airflow/.local/lib/python3.12/site-packages/airflow/utils/session.py", line 97, in wrapper
    return func(*args, session=session, **kwargs)
           ^^^^^^^^^^^^^^^^^^^^^^^^^^^^^^^^^^^^^^
  File "/home/airflow/.local/lib/python3.12/site-packages/airflow/models/taskinstance.py", line 3004, in _run_raw_task
    return _run_raw_task(
           ^^^^^^^^^^^^^^
  File "/home/airflow/.local/lib/python3.12/site-packages/airflow/models/taskinstance.py", line 273, in _run_raw_task
    TaskInstance._execute_task_with_callbacks(
  File "/home/airflow/.local/lib/python3.12/site-packages/airflow/models/taskinstance.py", line 3158, in _execute_task_with_callbacks
    result = self._execute_task(context, task_orig)
             ^^^^^^^^^^^^^^^^^^^^^^^^^^^^^^^^^^^^^^
  File "/home/airflow/.local/lib/python3.12/site-packages/airflow/models/taskinstance.py", line 3182, in _execute_task
    return _execute_task(self, context, task_orig)
           ^^^^^^^^^^^^^^^^^^^^^^^^^^^^^^^^^^^^^^^
  File "/home/airflow/.local/lib/python3.12/site-packages/airflow/models/taskinstance.py", line 767, in _execute_task
    result = _execute_callable(context=context, **execute_callable_kwargs)
             ^^^^^^^^^^^^^^^^^^^^^^^^^^^^^^^^^^^^^^^^^^^^^^^^^^^^^^^^^^^^^
  File "/home/airflow/.local/lib/python3.12/site-packages/airflow/models/taskinstance.py", line 733, in _execute_callable
    return ExecutionCallableRunner(
           ^^^^^^^^^^^^^^^^^^^^^^^^
  File "/home/airflow/.local/lib/python3.12/site-packages/airflow/utils/operator_helpers.py", line 252, in run
    return self.func(*args, **kwargs)
           ^^^^^^^^^^^^^^^^^^^^^^^^^^
  File "/home/airflow/.local/lib/python3.12/site-packages/airflow/models/baseoperator.py", line 406, in wrapper
    return func(self, *args, **kwargs)
           ^^^^^^^^^^^^^^^^^^^^^^^^^^^
  File "/home/airflow/.local/lib/python3.12/site-packages/airflow/operators/bash.py", line 249, in execute
    raise AirflowException(
airflow.exceptions.AirflowException: Bash command failed. The command returned a non-zero exit code 1.
[2025-06-02T00:22:55.249+0000] {local_task_job_runner.py:266} INFO - Task exited with return code 1
[2025-06-02T00:22:55.928+0000] {taskinstance.py:3900} INFO - 0 downstream tasks scheduled from follow-on schedule check
[2025-06-02T00:22:56.406+0000] {local_task_job_runner.py:245} INFO - ::endgroup::
