[2025-06-02T00:58:15.669+0000] {local_task_job_runner.py:123} INFO - ::group::Pre task execution logs
[2025-06-02T00:58:15.689+0000] {taskinstance.py:2612} INFO - Dependencies all met for dep_context=non-requeueable deps ti=<TaskInstance: log_monitoring_dag.start_spark_consumer scheduled__2025-06-02T00:45:00+00:00 [queued]>
[2025-06-02T00:58:15.697+0000] {taskinstance.py:2612} INFO - Dependencies all met for dep_context=requeueable deps ti=<TaskInstance: log_monitoring_dag.start_spark_consumer scheduled__2025-06-02T00:45:00+00:00 [queued]>
[2025-06-02T00:58:15.698+0000] {taskinstance.py:2865} INFO - Starting attempt 1 of 2
[2025-06-02T00:58:16.339+0000] {taskinstance.py:2888} INFO - Executing <Task(BashOperator): start_spark_consumer> on 2025-06-02 00:45:00+00:00
[2025-06-02T00:58:16.899+0000] {logging_mixin.py:190} WARNING - /home/***/.local/lib/python3.12/site-packages/***/task/task_runner/standard_task_runner.py:70 DeprecationWarning: This process (pid=385) is multi-threaded, use of fork() may lead to deadlocks in the child.
[2025-06-02T00:58:16.900+0000] {standard_task_runner.py:72} INFO - Started process 389 to run task
[2025-06-02T00:58:16.900+0000] {standard_task_runner.py:104} INFO - Running: ['***', 'tasks', 'run', 'log_monitoring_dag', 'start_spark_consumer', 'scheduled__2025-06-02T00:45:00+00:00', '--job-id', '62', '--raw', '--subdir', 'DAGS_FOLDER/log_monitoring_dag.py', '--cfg-path', '/tmp/tmpks9ecdyd']
[2025-06-02T00:58:16.903+0000] {standard_task_runner.py:105} INFO - Job 62: Subtask start_spark_consumer
[2025-06-02T01:00:24.655+0000] {job.py:229} INFO - Heartbeat recovered after 131.63 seconds
[2025-06-02T01:00:25.969+0000] {logging_mixin.py:190} WARNING - /home/***/.local/lib/python3.12/site-packages/***/settings.py:209 DeprecationWarning: The sql_alchemy_conn option in [core] has been moved to the sql_alchemy_conn option in [database] - the old setting has been used, but please update your config.
[2025-06-02T01:00:26.344+0000] {task_command.py:467} INFO - Running <TaskInstance: log_monitoring_dag.start_spark_consumer scheduled__2025-06-02T00:45:00+00:00 [running]> on host 95af1ae74a08
[2025-06-02T01:00:26.346+0000] {logging_mixin.py:190} WARNING - /home/***/.local/lib/python3.12/site-packages/***/settings.py:470 DeprecationWarning: The sql_alchemy_conn option in [core] has been moved to the sql_alchemy_conn option in [database] - the old setting has been used, but please update your config.
[2025-06-02T01:00:30.323+0000] {taskinstance.py:3131} INFO - Exporting env vars: AIRFLOW_CTX_DAG_OWNER='***' AIRFLOW_CTX_DAG_ID='log_monitoring_dag' AIRFLOW_CTX_TASK_ID='start_spark_consumer' AIRFLOW_CTX_EXECUTION_DATE='2025-06-02T00:45:00+00:00' AIRFLOW_CTX_TRY_NUMBER='1' AIRFLOW_CTX_DAG_RUN_ID='scheduled__2025-06-02T00:45:00+00:00'
[2025-06-02T01:00:30.337+0000] {taskinstance.py:731} INFO - ::endgroup::
[2025-06-02T01:00:30.402+0000] {subprocess.py:63} INFO - Tmp dir root location: /tmp
[2025-06-02T01:00:30.435+0000] {subprocess.py:75} INFO - Running command: ['/usr/bin/bash', '-c', '\n            docker run --rm             --network realtime_log_monitoring_default             -v /opt/***/app:/app             bitnami/spark:3.3.0             spark-submit --packages org.apache.spark:spark-sql-kafka-0-10_2.12:3.2.0 /app/log_consumer.py\n        ']
[2025-06-02T01:00:30.462+0000] {subprocess.py:86} INFO - Output:
[2025-06-02T01:00:30.788+0000] {job.py:229} INFO - Heartbeat recovered after 128.08 seconds
[2025-06-02T01:01:55.645+0000] {job.py:229} INFO - Heartbeat recovered after 39.29 seconds
[2025-06-02T01:03:10.933+0000] {job.py:229} INFO - Heartbeat recovered after 48.11 seconds
[2025-06-02T01:03:49.920+0000] {job.py:239} ERROR - Job heartbeat failed with error
Traceback (most recent call last):
  File "/home/airflow/.local/lib/python3.12/site-packages/sqlalchemy/engine/base.py", line 3371, in _wrap_pool_connect
    return fn()
           ^^^^
  File "/home/airflow/.local/lib/python3.12/site-packages/sqlalchemy/pool/base.py", line 327, in connect
    return _ConnectionFairy._checkout(self)
           ^^^^^^^^^^^^^^^^^^^^^^^^^^^^^^^^
  File "/home/airflow/.local/lib/python3.12/site-packages/sqlalchemy/pool/base.py", line 894, in _checkout
    fairy = _ConnectionRecord.checkout(pool)
            ^^^^^^^^^^^^^^^^^^^^^^^^^^^^^^^^
  File "/home/airflow/.local/lib/python3.12/site-packages/sqlalchemy/pool/base.py", line 493, in checkout
    rec = pool._do_get()
          ^^^^^^^^^^^^^^
  File "/home/airflow/.local/lib/python3.12/site-packages/sqlalchemy/pool/impl.py", line 256, in _do_get
    return self._create_connection()
           ^^^^^^^^^^^^^^^^^^^^^^^^^
  File "/home/airflow/.local/lib/python3.12/site-packages/sqlalchemy/pool/base.py", line 273, in _create_connection
    return _ConnectionRecord(self)
           ^^^^^^^^^^^^^^^^^^^^^^^
  File "/home/airflow/.local/lib/python3.12/site-packages/sqlalchemy/pool/base.py", line 388, in __init__
    self.__connect()
  File "/home/airflow/.local/lib/python3.12/site-packages/sqlalchemy/pool/base.py", line 690, in __connect
    with util.safe_reraise():
  File "/home/airflow/.local/lib/python3.12/site-packages/sqlalchemy/util/langhelpers.py", line 70, in __exit__
    compat.raise_(
  File "/home/airflow/.local/lib/python3.12/site-packages/sqlalchemy/util/compat.py", line 211, in raise_
    raise exception
  File "/home/airflow/.local/lib/python3.12/site-packages/sqlalchemy/pool/base.py", line 686, in __connect
    self.dbapi_connection = connection = pool._invoke_creator(self)
                                         ^^^^^^^^^^^^^^^^^^^^^^^^^^
  File "/home/airflow/.local/lib/python3.12/site-packages/sqlalchemy/engine/create.py", line 574, in connect
    return dialect.connect(*cargs, **cparams)
           ^^^^^^^^^^^^^^^^^^^^^^^^^^^^^^^^^^
  File "/home/airflow/.local/lib/python3.12/site-packages/sqlalchemy/engine/default.py", line 598, in connect
    return self.dbapi.connect(*cargs, **cparams)
           ^^^^^^^^^^^^^^^^^^^^^^^^^^^^^^^^^^^^^
  File "/home/airflow/.local/lib/python3.12/site-packages/psycopg2/__init__.py", line 122, in connect
    conn = _connect(dsn, connection_factory=connection_factory, **kwasync)
           ^^^^^^^^^^^^^^^^^^^^^^^^^^^^^^^^^^^^^^^^^^^^^^^^^^^^^^^^^^^^^^^
psycopg2.OperationalError: could not translate host name "postgres" to address: Temporary failure in name resolution


The above exception was the direct cause of the following exception:

Traceback (most recent call last):
  File "/home/airflow/.local/lib/python3.12/site-packages/airflow/jobs/job.py", line 207, in heartbeat
    self._merge_from(Job._fetch_from_db(self, session))
                     ^^^^^^^^^^^^^^^^^^^^^^^^^^^^^^^^^
  File "/home/airflow/.local/lib/python3.12/site-packages/airflow/api_internal/internal_api_call.py", line 139, in wrapper
    return func(*args, **kwargs)
           ^^^^^^^^^^^^^^^^^^^^^
  File "/home/airflow/.local/lib/python3.12/site-packages/airflow/utils/session.py", line 94, in wrapper
    return func(*args, **kwargs)
           ^^^^^^^^^^^^^^^^^^^^^
  File "/home/airflow/.local/lib/python3.12/site-packages/airflow/utils/retries.py", line 93, in wrapped_function
    for attempt in run_with_db_retries(max_retries=retries, logger=logger, **retry_kwargs):
                   ^^^^^^^^^^^^^^^^^^^^^^^^^^^^^^^^^^^^^^^^^^^^^^^^^^^^^^^^^^^^^^^^^^^^^^^
  File "/home/airflow/.local/lib/python3.12/site-packages/tenacity/__init__.py", line 443, in __iter__
    do = self.iter(retry_state=retry_state)
         ^^^^^^^^^^^^^^^^^^^^^^^^^^^^^^^^^^
  File "/home/airflow/.local/lib/python3.12/site-packages/tenacity/__init__.py", line 376, in iter
    result = action(retry_state)
             ^^^^^^^^^^^^^^^^^^^
  File "/home/airflow/.local/lib/python3.12/site-packages/tenacity/__init__.py", line 418, in exc_check
    raise retry_exc.reraise()
          ^^^^^^^^^^^^^^^^^^^
  File "/home/airflow/.local/lib/python3.12/site-packages/tenacity/__init__.py", line 185, in reraise
    raise self.last_attempt.result()
          ^^^^^^^^^^^^^^^^^^^^^^^^^^
  File "/usr/local/lib/python3.12/concurrent/futures/_base.py", line 449, in result
    return self.__get_result()
           ^^^^^^^^^^^^^^^^^^^
  File "/usr/local/lib/python3.12/concurrent/futures/_base.py", line 401, in __get_result
    raise self._exception
  File "/home/airflow/.local/lib/python3.12/site-packages/airflow/utils/retries.py", line 102, in wrapped_function
    return func(*args, **kwargs)
           ^^^^^^^^^^^^^^^^^^^^^
  File "/home/airflow/.local/lib/python3.12/site-packages/airflow/jobs/job.py", line 335, in _fetch_from_db
    session.merge(job)
  File "/home/airflow/.local/lib/python3.12/site-packages/sqlalchemy/orm/session.py", line 3056, in merge
    return self._merge(
           ^^^^^^^^^^^^
  File "/home/airflow/.local/lib/python3.12/site-packages/sqlalchemy/orm/session.py", line 3136, in _merge
    merged = self.get(
             ^^^^^^^^^
  File "/home/airflow/.local/lib/python3.12/site-packages/sqlalchemy/orm/session.py", line 2853, in get
    return self._get_impl(
           ^^^^^^^^^^^^^^^
  File "/home/airflow/.local/lib/python3.12/site-packages/sqlalchemy/orm/session.py", line 2975, in _get_impl
    return db_load_fn(
           ^^^^^^^^^^^
  File "/home/airflow/.local/lib/python3.12/site-packages/sqlalchemy/orm/loading.py", line 530, in load_on_pk_identity
    session.execute(
  File "/home/airflow/.local/lib/python3.12/site-packages/sqlalchemy/orm/session.py", line 1716, in execute
    conn = self._connection_for_bind(bind)
           ^^^^^^^^^^^^^^^^^^^^^^^^^^^^^^^
  File "/home/airflow/.local/lib/python3.12/site-packages/sqlalchemy/orm/session.py", line 1555, in _connection_for_bind
    return self._transaction._connection_for_bind(
           ^^^^^^^^^^^^^^^^^^^^^^^^^^^^^^^^^^^^^^^
  File "/home/airflow/.local/lib/python3.12/site-packages/sqlalchemy/orm/session.py", line 750, in _connection_for_bind
    conn = bind.connect()
           ^^^^^^^^^^^^^^
  File "/home/airflow/.local/lib/python3.12/site-packages/sqlalchemy/future/engine.py", line 412, in connect
    return super(Engine, self).connect()
           ^^^^^^^^^^^^^^^^^^^^^^^^^^^^^
  File "/home/airflow/.local/lib/python3.12/site-packages/sqlalchemy/engine/base.py", line 3325, in connect
    return self._connection_cls(self, close_with_result=close_with_result)
           ^^^^^^^^^^^^^^^^^^^^^^^^^^^^^^^^^^^^^^^^^^^^^^^^^^^^^^^^^^^^^^^
  File "/home/airflow/.local/lib/python3.12/site-packages/sqlalchemy/engine/base.py", line 96, in __init__
    else engine.raw_connection()
         ^^^^^^^^^^^^^^^^^^^^^^^
  File "/home/airflow/.local/lib/python3.12/site-packages/sqlalchemy/engine/base.py", line 3404, in raw_connection
    return self._wrap_pool_connect(self.pool.connect, _connection)
           ^^^^^^^^^^^^^^^^^^^^^^^^^^^^^^^^^^^^^^^^^^^^^^^^^^^^^^^
  File "/home/airflow/.local/lib/python3.12/site-packages/sqlalchemy/engine/base.py", line 3374, in _wrap_pool_connect
    Connection._handle_dbapi_exception_noconnection(
  File "/home/airflow/.local/lib/python3.12/site-packages/sqlalchemy/engine/base.py", line 2208, in _handle_dbapi_exception_noconnection
    util.raise_(
  File "/home/airflow/.local/lib/python3.12/site-packages/sqlalchemy/util/compat.py", line 211, in raise_
    raise exception
  File "/home/airflow/.local/lib/python3.12/site-packages/sqlalchemy/engine/base.py", line 3371, in _wrap_pool_connect
    return fn()
           ^^^^
  File "/home/airflow/.local/lib/python3.12/site-packages/sqlalchemy/pool/base.py", line 327, in connect
    return _ConnectionFairy._checkout(self)
           ^^^^^^^^^^^^^^^^^^^^^^^^^^^^^^^^
  File "/home/airflow/.local/lib/python3.12/site-packages/sqlalchemy/pool/base.py", line 894, in _checkout
    fairy = _ConnectionRecord.checkout(pool)
            ^^^^^^^^^^^^^^^^^^^^^^^^^^^^^^^^
  File "/home/airflow/.local/lib/python3.12/site-packages/sqlalchemy/pool/base.py", line 493, in checkout
    rec = pool._do_get()
          ^^^^^^^^^^^^^^
  File "/home/airflow/.local/lib/python3.12/site-packages/sqlalchemy/pool/impl.py", line 256, in _do_get
    return self._create_connection()
           ^^^^^^^^^^^^^^^^^^^^^^^^^
  File "/home/airflow/.local/lib/python3.12/site-packages/sqlalchemy/pool/base.py", line 273, in _create_connection
    return _ConnectionRecord(self)
           ^^^^^^^^^^^^^^^^^^^^^^^
  File "/home/airflow/.local/lib/python3.12/site-packages/sqlalchemy/pool/base.py", line 388, in __init__
    self.__connect()
  File "/home/airflow/.local/lib/python3.12/site-packages/sqlalchemy/pool/base.py", line 690, in __connect
    with util.safe_reraise():
  File "/home/airflow/.local/lib/python3.12/site-packages/sqlalchemy/util/langhelpers.py", line 70, in __exit__
    compat.raise_(
  File "/home/airflow/.local/lib/python3.12/site-packages/sqlalchemy/util/compat.py", line 211, in raise_
    raise exception
  File "/home/airflow/.local/lib/python3.12/site-packages/sqlalchemy/pool/base.py", line 686, in __connect
    self.dbapi_connection = connection = pool._invoke_creator(self)
                                         ^^^^^^^^^^^^^^^^^^^^^^^^^^
  File "/home/airflow/.local/lib/python3.12/site-packages/sqlalchemy/engine/create.py", line 574, in connect
    return dialect.connect(*cargs, **cparams)
           ^^^^^^^^^^^^^^^^^^^^^^^^^^^^^^^^^^
  File "/home/airflow/.local/lib/python3.12/site-packages/sqlalchemy/engine/default.py", line 598, in connect
    return self.dbapi.connect(*cargs, **cparams)
           ^^^^^^^^^^^^^^^^^^^^^^^^^^^^^^^^^^^^^
  File "/home/airflow/.local/lib/python3.12/site-packages/psycopg2/__init__.py", line 122, in connect
    conn = _connect(dsn, connection_factory=connection_factory, **kwasync)
           ^^^^^^^^^^^^^^^^^^^^^^^^^^^^^^^^^^^^^^^^^^^^^^^^^^^^^^^^^^^^^^^
sqlalchemy.exc.OperationalError: (psycopg2.OperationalError) could not translate host name "postgres" to address: Temporary failure in name resolution

(Background on this error at: https://sqlalche.me/e/14/e3q8)
[2025-06-02T01:03:53.339+0000] {job.py:254} ERROR - Job heartbeat failed with error. Scheduler is in unhealthy state
[2025-06-02T01:04:29.463+0000] {job.py:254} ERROR - Job heartbeat failed with error. Scheduler is in unhealthy state
[2025-06-02T01:04:41.406+0000] {job.py:229} INFO - Heartbeat recovered after 130.61 seconds
[2025-06-02T01:05:01.452+0000] {job.py:229} INFO - Heartbeat recovered after 20.73 seconds
[2025-06-02T01:05:10.130+0000] {job.py:229} INFO - Heartbeat recovered after 16.90 seconds
[2025-06-02T01:05:48.042+0000] {job.py:229} INFO - Heartbeat recovered after 10.87 seconds
[2025-06-02T01:06:06.087+0000] {job.py:229} INFO - Heartbeat recovered after 11.46 seconds
[2025-06-02T01:07:35.680+0000] {job.py:229} INFO - Heartbeat recovered after 60.69 seconds
[2025-06-02T01:07:43.788+0000] {job.py:229} INFO - Heartbeat recovered after 59.26 seconds
[2025-06-02T01:08:11.059+0000] {job.py:229} INFO - Heartbeat recovered after 13.95 seconds
[2025-06-02T01:08:19.370+0000] {job.py:229} INFO - Heartbeat recovered after 10.77 seconds
[2025-06-02T01:09:08.261+0000] {job.py:229} INFO - Heartbeat recovered after 50.07 seconds
[2025-06-02T01:09:25.725+0000] {job.py:229} INFO - Heartbeat recovered after 21.43 seconds
[2025-06-02T01:09:45.072+0000] {job.py:229} INFO - Heartbeat recovered after 21.08 seconds
[2025-06-02T01:10:20.449+0000] {job.py:229} INFO - Heartbeat recovered after 37.40 seconds
[2025-06-02T01:10:53.136+0000] {job.py:229} INFO - Heartbeat recovered after 32.73 seconds
[2025-06-02T01:11:06.509+0000] {job.py:229} INFO - Heartbeat recovered after 15.63 seconds
[2025-06-02T01:11:18.029+0000] {job.py:229} INFO - Heartbeat recovered after 11.85 seconds
[2025-06-02T01:11:51.661+0000] {job.py:229} INFO - Heartbeat recovered after 36.41 seconds
[2025-06-02T01:12:18.589+0000] {job.py:229} INFO - Heartbeat recovered after 29.40 seconds
[2025-06-02T01:12:29.922+0000] {job.py:229} INFO - Heartbeat recovered after 11.37 seconds
[2025-06-02T01:12:40.362+0000] {job.py:229} INFO - Heartbeat recovered after 11.20 seconds
[2025-06-02T01:12:53.030+0000] {job.py:229} INFO - Heartbeat recovered after 13.57 seconds
[2025-06-02T01:13:05.917+0000] {job.py:229} INFO - Heartbeat recovered after 13.24 seconds
[2025-06-02T01:13:23.132+0000] {job.py:229} INFO - Heartbeat recovered after 17.69 seconds
[2025-06-02T01:14:08.830+0000] {job.py:229} INFO - Heartbeat recovered after 32.66 seconds
[2025-06-02T01:13:46.246+0000] {subprocess.py:93} INFO - [38;5;6m [38;5;5m01:13:33.94 [0m
[2025-06-02T01:14:10.926+0000] {subprocess.py:93} INFO - [38;5;6m [38;5;5m01:13:34.01 [0m[1mWelcome to the Bitnami spark container[0m
[2025-06-02T01:14:12.077+0000] {subprocess.py:93} INFO - [38;5;6m [38;5;5m01:13:34.03 [0mSubscribe to project updates by watching [1mhttps://github.com/bitnami/containers[0m
[2025-06-02T01:14:14.155+0000] {subprocess.py:93} INFO - [38;5;6m [38;5;5m01:13:34.03 [0mSubmit issues and feature requests at [1mhttps://github.com/bitnami/containers/issues[0m
[2025-06-02T01:14:14.501+0000] {subprocess.py:93} INFO - [38;5;6m [38;5;5m01:13:34.03 [0m
[2025-06-02T01:14:14.575+0000] {subprocess.py:93} INFO - 
[2025-06-02T01:14:28.609+0000] {job.py:229} INFO - Heartbeat recovered after 20.08 seconds
[2025-06-02T01:14:51.815+0000] {job.py:229} INFO - Heartbeat recovered after 23.83 seconds
[2025-06-02T01:15:25.384+0000] {job.py:229} INFO - Heartbeat recovered after 21.95 seconds
[2025-06-02T01:15:39.443+0000] {job.py:229} INFO - Heartbeat recovered after 17.53 seconds
[2025-06-02T01:16:04.082+0000] {job.py:229} INFO - Heartbeat recovered after 25.08 seconds
[2025-06-02T01:16:19.838+0000] {job.py:229} INFO - Heartbeat recovered after 16.47 seconds
[2025-06-02T01:17:04.181+0000] {job.py:229} INFO - Heartbeat recovered after 11.38 seconds
[2025-06-02T01:17:25.946+0000] {job.py:229} INFO - Heartbeat recovered after 22.06 seconds
[2025-06-02T01:17:50.404+0000] {subprocess.py:93} INFO - :: loading settings :: url = jar:file:/opt/bitnami/spark/jars/ivy-2.5.0.jar!/org/apache/ivy/core/settings/ivysettings.xml
[2025-06-02T01:17:53.188+0000] {job.py:229} INFO - Heartbeat recovered after 27.98 seconds
[2025-06-02T01:17:57.616+0000] {subprocess.py:93} INFO - Ivy Default Cache set to: /opt/bitnami/spark/.ivy2/cache
[2025-06-02T01:17:57.762+0000] {subprocess.py:93} INFO - The jars for the packages stored in: /opt/bitnami/spark/.ivy2/jars
[2025-06-02T01:17:57.764+0000] {subprocess.py:93} INFO - org.apache.spark#spark-sql-kafka-0-10_2.12 added as a dependency
[2025-06-02T01:17:57.892+0000] {subprocess.py:93} INFO - :: resolving dependencies :: org.apache.spark#spark-submit-parent-55e10b55-90e6-43fb-82c4-0690d51badb5;1.0
[2025-06-02T01:17:59.966+0000] {subprocess.py:93} INFO - 	confs: [default]
[2025-06-02T01:18:06.652+0000] {job.py:229} INFO - Heartbeat recovered after 14.81 seconds
[2025-06-02T01:18:15.686+0000] {subprocess.py:93} INFO - You probably access the destination server through a proxy server that is not well configured.
[2025-06-02T01:18:17.079+0000] {subprocess.py:93} INFO - You probably access the destination server through a proxy server that is not well configured.
[2025-06-02T01:18:18.402+0000] {job.py:229} INFO - Heartbeat recovered after 11.82 seconds
[2025-06-02T01:18:41.044+0000] {job.py:229} INFO - Heartbeat recovered after 22.65 seconds
[2025-06-02T01:18:41.482+0000] {subprocess.py:93} INFO - :: resolution report :: resolve 43950ms :: artifacts dl 1ms
[2025-06-02T01:18:44.811+0000] {subprocess.py:93} INFO - 	:: modules in use:
[2025-06-02T01:18:45.149+0000] {subprocess.py:93} INFO - 	---------------------------------------------------------------------
[2025-06-02T01:18:45.471+0000] {subprocess.py:93} INFO - 	|                  |            modules            ||   artifacts   |
[2025-06-02T01:18:50.335+0000] {subprocess.py:93} INFO - 	|       conf       | number| search|dwnlded|evicted|| number|dwnlded|
[2025-06-02T01:18:50.337+0000] {subprocess.py:93} INFO - 	---------------------------------------------------------------------
[2025-06-02T01:18:50.828+0000] {subprocess.py:93} INFO - 	|      default     |   1   |   0   |   0   |   0   ||   0   |   0   |
[2025-06-02T01:18:51.101+0000] {subprocess.py:93} INFO - 	---------------------------------------------------------------------
[2025-06-02T01:18:51.576+0000] {subprocess.py:93} INFO - 
[2025-06-02T01:18:52.072+0000] {subprocess.py:93} INFO - :: problems summary ::
[2025-06-02T01:18:52.594+0000] {subprocess.py:93} INFO - :::: WARNINGS
[2025-06-02T01:18:54.912+0000] {job.py:229} INFO - Heartbeat recovered after 17.61 seconds
[2025-06-02T01:18:55.683+0000] {subprocess.py:93} INFO - 	Host repo1.maven.org not found. url=https://repo1.maven.org/maven2/org/apache/spark/spark-sql-kafka-0-10_2.12/3.2.0/spark-sql-kafka-0-10_2.12-3.2.0.pom
[2025-06-02T01:18:55.761+0000] {subprocess.py:93} INFO - 
[2025-06-02T01:18:56.095+0000] {subprocess.py:93} INFO - 	Host repo1.maven.org not found. url=https://repo1.maven.org/maven2/org/apache/spark/spark-sql-kafka-0-10_2.12/3.2.0/spark-sql-kafka-0-10_2.12-3.2.0.jar
[2025-06-02T01:18:56.096+0000] {subprocess.py:93} INFO - 
[2025-06-02T01:18:56.261+0000] {subprocess.py:93} INFO - 		module not found: org.apache.spark#spark-sql-kafka-0-10_2.12;3.2.0
[2025-06-02T01:18:57.194+0000] {subprocess.py:93} INFO - 
[2025-06-02T01:18:57.309+0000] {subprocess.py:93} INFO - 	==== local-m2-cache: tried
[2025-06-02T01:18:57.310+0000] {subprocess.py:93} INFO - 
[2025-06-02T01:18:57.505+0000] {subprocess.py:93} INFO - 	  file:/opt/bitnami/spark/.m2/repository/org/apache/spark/spark-sql-kafka-0-10_2.12/3.2.0/spark-sql-kafka-0-10_2.12-3.2.0.pom
[2025-06-02T01:18:57.506+0000] {subprocess.py:93} INFO - 
[2025-06-02T01:18:57.527+0000] {subprocess.py:93} INFO - 	  -- artifact org.apache.spark#spark-sql-kafka-0-10_2.12;3.2.0!spark-sql-kafka-0-10_2.12.jar:
[2025-06-02T01:18:58.943+0000] {subprocess.py:93} INFO - 
[2025-06-02T01:18:58.950+0000] {subprocess.py:93} INFO - 	  file:/opt/bitnami/spark/.m2/repository/org/apache/spark/spark-sql-kafka-0-10_2.12/3.2.0/spark-sql-kafka-0-10_2.12-3.2.0.jar
[2025-06-02T01:18:58.951+0000] {subprocess.py:93} INFO - 
[2025-06-02T01:18:59.045+0000] {subprocess.py:93} INFO - 	==== local-ivy-cache: tried
[2025-06-02T01:18:59.045+0000] {subprocess.py:93} INFO - 
[2025-06-02T01:18:59.052+0000] {subprocess.py:93} INFO - 	  /opt/bitnami/spark/.ivy2/local/org.apache.spark/spark-sql-kafka-0-10_2.12/3.2.0/ivys/ivy.xml
[2025-06-02T01:18:59.053+0000] {subprocess.py:93} INFO - 
[2025-06-02T01:18:59.053+0000] {subprocess.py:93} INFO - 	  -- artifact org.apache.spark#spark-sql-kafka-0-10_2.12;3.2.0!spark-sql-kafka-0-10_2.12.jar:
[2025-06-02T01:18:59.054+0000] {subprocess.py:93} INFO - 
[2025-06-02T01:18:59.055+0000] {subprocess.py:93} INFO - 	  /opt/bitnami/spark/.ivy2/local/org.apache.spark/spark-sql-kafka-0-10_2.12/3.2.0/jars/spark-sql-kafka-0-10_2.12.jar
[2025-06-02T01:18:59.055+0000] {subprocess.py:93} INFO - 
[2025-06-02T01:18:59.056+0000] {subprocess.py:93} INFO - 	==== central: tried
[2025-06-02T01:18:59.085+0000] {subprocess.py:93} INFO - 
[2025-06-02T01:18:59.108+0000] {subprocess.py:93} INFO - 	  https://repo1.maven.org/maven2/org/apache/spark/spark-sql-kafka-0-10_2.12/3.2.0/spark-sql-kafka-0-10_2.12-3.2.0.pom
[2025-06-02T01:18:59.108+0000] {subprocess.py:93} INFO - 
[2025-06-02T01:18:59.109+0000] {subprocess.py:93} INFO - 	  -- artifact org.apache.spark#spark-sql-kafka-0-10_2.12;3.2.0!spark-sql-kafka-0-10_2.12.jar:
[2025-06-02T01:18:59.137+0000] {subprocess.py:93} INFO - 
[2025-06-02T01:18:59.137+0000] {subprocess.py:93} INFO - 	  https://repo1.maven.org/maven2/org/apache/spark/spark-sql-kafka-0-10_2.12/3.2.0/spark-sql-kafka-0-10_2.12-3.2.0.jar
[2025-06-02T01:18:59.138+0000] {subprocess.py:93} INFO - 
[2025-06-02T01:18:59.138+0000] {subprocess.py:93} INFO - 	==== spark-packages: tried
[2025-06-02T01:18:59.139+0000] {subprocess.py:93} INFO - 
[2025-06-02T01:18:59.285+0000] {subprocess.py:93} INFO - 	  https://repos.spark-packages.org/org/apache/spark/spark-sql-kafka-0-10_2.12/3.2.0/spark-sql-kafka-0-10_2.12-3.2.0.pom
[2025-06-02T01:18:59.285+0000] {subprocess.py:93} INFO - 
[2025-06-02T01:18:59.298+0000] {subprocess.py:93} INFO - 	  -- artifact org.apache.spark#spark-sql-kafka-0-10_2.12;3.2.0!spark-sql-kafka-0-10_2.12.jar:
[2025-06-02T01:18:59.299+0000] {subprocess.py:93} INFO - 
[2025-06-02T01:18:59.410+0000] {subprocess.py:93} INFO - 	  https://repos.spark-packages.org/org/apache/spark/spark-sql-kafka-0-10_2.12/3.2.0/spark-sql-kafka-0-10_2.12-3.2.0.jar
[2025-06-02T01:18:59.426+0000] {subprocess.py:93} INFO - 
[2025-06-02T01:18:59.426+0000] {subprocess.py:93} INFO - 		::::::::::::::::::::::::::::::::::::::::::::::
[2025-06-02T01:18:59.427+0000] {subprocess.py:93} INFO - 
[2025-06-02T01:18:59.427+0000] {subprocess.py:93} INFO - 		::          UNRESOLVED DEPENDENCIES         ::
[2025-06-02T01:18:59.428+0000] {subprocess.py:93} INFO - 
[2025-06-02T01:18:59.428+0000] {subprocess.py:93} INFO - 		::::::::::::::::::::::::::::::::::::::::::::::
[2025-06-02T01:18:59.429+0000] {subprocess.py:93} INFO - 
[2025-06-02T01:18:59.429+0000] {subprocess.py:93} INFO - 		:: org.apache.spark#spark-sql-kafka-0-10_2.12;3.2.0: not found
[2025-06-02T01:18:59.430+0000] {subprocess.py:93} INFO - 
[2025-06-02T01:18:59.430+0000] {subprocess.py:93} INFO - 		::::::::::::::::::::::::::::::::::::::::::::::
[2025-06-02T01:18:59.431+0000] {subprocess.py:93} INFO - 
[2025-06-02T01:18:59.431+0000] {subprocess.py:93} INFO - 
[2025-06-02T01:18:59.432+0000] {subprocess.py:93} INFO - 
[2025-06-02T01:18:59.432+0000] {subprocess.py:93} INFO - :: USE VERBOSE OR DEBUG MESSAGE LEVEL FOR MORE DETAILS
[2025-06-02T01:18:59.432+0000] {subprocess.py:93} INFO - Exception in thread "main" java.lang.RuntimeException: [unresolved dependency: org.apache.spark#spark-sql-kafka-0-10_2.12;3.2.0: not found]
[2025-06-02T01:18:59.433+0000] {subprocess.py:93} INFO - 	at org.apache.spark.deploy.SparkSubmitUtils$.resolveMavenCoordinates(SparkSubmit.scala:1456)
[2025-06-02T01:18:59.433+0000] {subprocess.py:93} INFO - 	at org.apache.spark.util.DependencyUtils$.resolveMavenDependencies(DependencyUtils.scala:185)
[2025-06-02T01:18:59.434+0000] {subprocess.py:93} INFO - 	at org.apache.spark.deploy.SparkSubmit.prepareSubmitEnvironment(SparkSubmit.scala:308)
[2025-06-02T01:18:59.434+0000] {subprocess.py:93} INFO - 	at org.apache.spark.deploy.SparkSubmit.org$apache$spark$deploy$SparkSubmit$$runMain(SparkSubmit.scala:901)
[2025-06-02T01:18:59.435+0000] {subprocess.py:93} INFO - 	at org.apache.spark.deploy.SparkSubmit.doRunMain$1(SparkSubmit.scala:180)
[2025-06-02T01:18:59.435+0000] {subprocess.py:93} INFO - 	at org.apache.spark.deploy.SparkSubmit.submit(SparkSubmit.scala:203)
[2025-06-02T01:18:59.435+0000] {subprocess.py:93} INFO - 	at org.apache.spark.deploy.SparkSubmit.doSubmit(SparkSubmit.scala:90)
[2025-06-02T01:18:59.435+0000] {subprocess.py:93} INFO - 	at org.apache.spark.deploy.SparkSubmit$$anon$2.doSubmit(SparkSubmit.scala:1046)
[2025-06-02T01:18:59.436+0000] {subprocess.py:93} INFO - 	at org.apache.spark.deploy.SparkSubmit$.main(SparkSubmit.scala:1055)
[2025-06-02T01:18:59.436+0000] {subprocess.py:93} INFO - 	at org.apache.spark.deploy.SparkSubmit.main(SparkSubmit.scala)
[2025-06-02T01:19:05.551+0000] {job.py:229} INFO - Heartbeat recovered after 10.65 seconds
[2025-06-02T01:19:19.579+0000] {subprocess.py:97} INFO - Command exited with return code 1
[2025-06-02T01:21:05.190+0000] {taskinstance.py:3310} ERROR - Task failed with exception
Traceback (most recent call last):
  File "/home/airflow/.local/lib/python3.12/site-packages/airflow/models/taskinstance.py", line 767, in _execute_task
    result = _execute_callable(context=context, **execute_callable_kwargs)
             ^^^^^^^^^^^^^^^^^^^^^^^^^^^^^^^^^^^^^^^^^^^^^^^^^^^^^^^^^^^^^
  File "/home/airflow/.local/lib/python3.12/site-packages/airflow/models/taskinstance.py", line 733, in _execute_callable
    return ExecutionCallableRunner(
           ^^^^^^^^^^^^^^^^^^^^^^^^
  File "/home/airflow/.local/lib/python3.12/site-packages/airflow/utils/operator_helpers.py", line 252, in run
    return self.func(*args, **kwargs)
           ^^^^^^^^^^^^^^^^^^^^^^^^^^
  File "/home/airflow/.local/lib/python3.12/site-packages/airflow/models/baseoperator.py", line 406, in wrapper
    return func(self, *args, **kwargs)
           ^^^^^^^^^^^^^^^^^^^^^^^^^^^
  File "/home/airflow/.local/lib/python3.12/site-packages/airflow/operators/bash.py", line 249, in execute
    raise AirflowException(
airflow.exceptions.AirflowException: Bash command failed. The command returned a non-zero exit code 1.
[2025-06-02T01:21:18.563+0000] {taskinstance.py:1225} INFO - Marking task as UP_FOR_RETRY. dag_id=log_monitoring_dag, task_id=start_spark_consumer, run_id=scheduled__2025-06-02T00:45:00+00:00, execution_date=20250602T004500, start_date=20250602T005815, end_date=20250602T012117
[2025-06-02T01:21:32.907+0000] {taskinstance.py:340} INFO - ::group::Post task execution logs
[2025-06-02T01:21:34.817+0000] {standard_task_runner.py:124} ERROR - Failed to execute job 62 for task start_spark_consumer (Bash command failed. The command returned a non-zero exit code 1.; 389)
Traceback (most recent call last):
  File "/home/airflow/.local/lib/python3.12/site-packages/airflow/task/task_runner/standard_task_runner.py", line 117, in _start_by_fork
    ret = args.func(args, dag=self.dag)
          ^^^^^^^^^^^^^^^^^^^^^^^^^^^^^
  File "/home/airflow/.local/lib/python3.12/site-packages/airflow/cli/cli_config.py", line 49, in command
    return func(*args, **kwargs)
           ^^^^^^^^^^^^^^^^^^^^^
  File "/home/airflow/.local/lib/python3.12/site-packages/airflow/utils/cli.py", line 115, in wrapper
    return f(*args, **kwargs)
           ^^^^^^^^^^^^^^^^^^
  File "/home/airflow/.local/lib/python3.12/site-packages/airflow/cli/commands/task_command.py", line 483, in task_run
    task_return_code = _run_task_by_selected_method(args, _dag, ti)
                       ^^^^^^^^^^^^^^^^^^^^^^^^^^^^^^^^^^^^^^^^^^^^
  File "/home/airflow/.local/lib/python3.12/site-packages/airflow/cli/commands/task_command.py", line 256, in _run_task_by_selected_method
    return _run_raw_task(args, ti)
           ^^^^^^^^^^^^^^^^^^^^^^^
  File "/home/airflow/.local/lib/python3.12/site-packages/airflow/cli/commands/task_command.py", line 341, in _run_raw_task
    return ti._run_raw_task(
           ^^^^^^^^^^^^^^^^^
  File "/home/airflow/.local/lib/python3.12/site-packages/airflow/utils/session.py", line 97, in wrapper
    return func(*args, session=session, **kwargs)
           ^^^^^^^^^^^^^^^^^^^^^^^^^^^^^^^^^^^^^^
  File "/home/airflow/.local/lib/python3.12/site-packages/airflow/models/taskinstance.py", line 3004, in _run_raw_task
    return _run_raw_task(
           ^^^^^^^^^^^^^^
  File "/home/airflow/.local/lib/python3.12/site-packages/airflow/models/taskinstance.py", line 273, in _run_raw_task
    TaskInstance._execute_task_with_callbacks(
  File "/home/airflow/.local/lib/python3.12/site-packages/airflow/models/taskinstance.py", line 3158, in _execute_task_with_callbacks
    result = self._execute_task(context, task_orig)
             ^^^^^^^^^^^^^^^^^^^^^^^^^^^^^^^^^^^^^^
  File "/home/airflow/.local/lib/python3.12/site-packages/airflow/models/taskinstance.py", line 3182, in _execute_task
    return _execute_task(self, context, task_orig)
           ^^^^^^^^^^^^^^^^^^^^^^^^^^^^^^^^^^^^^^^
  File "/home/airflow/.local/lib/python3.12/site-packages/airflow/models/taskinstance.py", line 767, in _execute_task
    result = _execute_callable(context=context, **execute_callable_kwargs)
             ^^^^^^^^^^^^^^^^^^^^^^^^^^^^^^^^^^^^^^^^^^^^^^^^^^^^^^^^^^^^^
  File "/home/airflow/.local/lib/python3.12/site-packages/airflow/models/taskinstance.py", line 733, in _execute_callable
    return ExecutionCallableRunner(
           ^^^^^^^^^^^^^^^^^^^^^^^^
  File "/home/airflow/.local/lib/python3.12/site-packages/airflow/utils/operator_helpers.py", line 252, in run
    return self.func(*args, **kwargs)
           ^^^^^^^^^^^^^^^^^^^^^^^^^^
  File "/home/airflow/.local/lib/python3.12/site-packages/airflow/models/baseoperator.py", line 406, in wrapper
    return func(self, *args, **kwargs)
           ^^^^^^^^^^^^^^^^^^^^^^^^^^^
  File "/home/airflow/.local/lib/python3.12/site-packages/airflow/operators/bash.py", line 249, in execute
    raise AirflowException(
airflow.exceptions.AirflowException: Bash command failed. The command returned a non-zero exit code 1.
[2025-06-02T01:21:39.346+0000] {local_task_job_runner.py:266} INFO - Task exited with return code 1
[2025-06-02T01:21:41.583+0000] {standard_task_runner.py:217} INFO - Process not found (most likely exited), stop collecting metrics
[2025-06-02T01:22:14.115+0000] {taskinstance.py:3900} INFO - 0 downstream tasks scheduled from follow-on schedule check
[2025-06-02T01:22:14.267+0000] {local_task_job_runner.py:245} INFO - ::endgroup::
