[2025-05-27T13:50:04.866+0000] {local_task_job_runner.py:123} INFO - ::group::Pre task execution logs
[2025-05-27T13:50:04.898+0000] {taskinstance.py:2612} INFO - Dependencies all met for dep_context=non-requeueable deps ti=<TaskInstance: log_monitoring_dag.start_log_producer scheduled__2025-05-27T13:45:00+00:00 [queued]>
[2025-05-27T13:50:04.916+0000] {taskinstance.py:2612} INFO - Dependencies all met for dep_context=requeueable deps ti=<TaskInstance: log_monitoring_dag.start_log_producer scheduled__2025-05-27T13:45:00+00:00 [queued]>
[2025-05-27T13:50:04.917+0000] {taskinstance.py:2865} INFO - Starting attempt 1 of 2
[2025-05-27T13:50:04.945+0000] {taskinstance.py:2888} INFO - Executing <Task(BashOperator): start_log_producer> on 2025-05-27 13:45:00+00:00
[2025-05-27T13:50:04.959+0000] {standard_task_runner.py:104} INFO - Running: ['***', 'tasks', 'run', 'log_monitoring_dag', 'start_log_producer', 'scheduled__2025-05-27T13:45:00+00:00', '--job-id', '80', '--raw', '--subdir', 'DAGS_FOLDER/log_monitoring_dag.py', '--cfg-path', '/tmp/tmpt3wjmzyw']
[2025-05-27T13:50:04.963+0000] {standard_task_runner.py:105} INFO - Job 80: Subtask start_log_producer
[2025-05-27T13:50:04.964+0000] {logging_mixin.py:190} WARNING - /home/***/.local/lib/python3.12/site-packages/***/task/task_runner/standard_task_runner.py:70 DeprecationWarning: This process (pid=178) is multi-threaded, use of fork() may lead to deadlocks in the child.
[2025-05-27T13:50:04.965+0000] {standard_task_runner.py:72} INFO - Started process 179 to run task
[2025-05-27T13:50:05.003+0000] {logging_mixin.py:190} WARNING - /home/***/.local/lib/python3.12/site-packages/***/settings.py:209 DeprecationWarning: The sql_alchemy_conn option in [core] has been moved to the sql_alchemy_conn option in [database] - the old setting has been used, but please update your config.
[2025-05-27T13:50:05.059+0000] {task_command.py:467} INFO - Running <TaskInstance: log_monitoring_dag.start_log_producer scheduled__2025-05-27T13:45:00+00:00 [running]> on host 1d31c4e9dbe9
[2025-05-27T13:50:05.061+0000] {logging_mixin.py:190} WARNING - /home/***/.local/lib/python3.12/site-packages/***/settings.py:470 DeprecationWarning: The sql_alchemy_conn option in [core] has been moved to the sql_alchemy_conn option in [database] - the old setting has been used, but please update your config.
[2025-05-27T13:50:05.266+0000] {taskinstance.py:3131} INFO - Exporting env vars: AIRFLOW_CTX_DAG_OWNER='***' AIRFLOW_CTX_DAG_ID='log_monitoring_dag' AIRFLOW_CTX_TASK_ID='start_log_producer' AIRFLOW_CTX_EXECUTION_DATE='2025-05-27T13:45:00+00:00' AIRFLOW_CTX_TRY_NUMBER='1' AIRFLOW_CTX_DAG_RUN_ID='scheduled__2025-05-27T13:45:00+00:00'
[2025-05-27T13:50:05.268+0000] {taskinstance.py:731} INFO - ::endgroup::
[2025-05-27T13:50:05.419+0000] {subprocess.py:63} INFO - Tmp dir root location: /tmp
[2025-05-27T13:50:05.427+0000] {subprocess.py:75} INFO - Running command: ['/usr/bin/bash', '-c', 'cd /opt/***/app && python log_producer.py']
[2025-05-27T13:50:05.457+0000] {subprocess.py:86} INFO - Output:
[2025-05-27T13:50:12.593+0000] {subprocess.py:93} INFO - Traceback (most recent call last):
[2025-05-27T13:50:12.596+0000] {subprocess.py:93} INFO -   File "/opt/***/app/log_producer.py", line 7, in <module>
[2025-05-27T13:50:13.031+0000] {subprocess.py:93} INFO -     producer = KafkaProducer(
[2025-05-27T13:50:13.113+0000] {subprocess.py:93} INFO -                ^^^^^^^^^^^^^^
[2025-05-27T13:50:13.113+0000] {subprocess.py:93} INFO -   File "/home/***/.local/lib/python3.12/site-packages/kafka/producer/kafka.py", line 481, in __init__
[2025-05-27T13:50:13.334+0000] {subprocess.py:93} INFO -     client = self.config['kafka_client'](
[2025-05-27T13:50:13.339+0000] {subprocess.py:93} INFO -              ^^^^^^^^^^^^^^^^^^^^^^^^^^^^
[2025-05-27T13:50:13.340+0000] {subprocess.py:93} INFO -   File "/home/***/.local/lib/python3.12/site-packages/kafka/client_async.py", line 262, in __init__
[2025-05-27T13:50:13.348+0000] {subprocess.py:93} INFO -     self.config['api_version'] = self.check_version()
[2025-05-27T13:50:13.349+0000] {subprocess.py:93} INFO -                                  ^^^^^^^^^^^^^^^^^^^^
[2025-05-27T13:50:13.350+0000] {subprocess.py:93} INFO -   File "/home/***/.local/lib/python3.12/site-packages/kafka/client_async.py", line 1074, in check_version
[2025-05-27T13:50:13.353+0000] {subprocess.py:93} INFO -     raise Errors.NoBrokersAvailable()
[2025-05-27T13:50:13.354+0000] {subprocess.py:93} INFO - kafka.errors.NoBrokersAvailable: NoBrokersAvailable
[2025-05-27T13:50:13.700+0000] {subprocess.py:97} INFO - Command exited with return code 1
[2025-05-27T13:50:13.883+0000] {taskinstance.py:3310} ERROR - Task failed with exception
Traceback (most recent call last):
  File "/home/airflow/.local/lib/python3.12/site-packages/airflow/models/taskinstance.py", line 767, in _execute_task
    result = _execute_callable(context=context, **execute_callable_kwargs)
             ^^^^^^^^^^^^^^^^^^^^^^^^^^^^^^^^^^^^^^^^^^^^^^^^^^^^^^^^^^^^^
  File "/home/airflow/.local/lib/python3.12/site-packages/airflow/models/taskinstance.py", line 733, in _execute_callable
    return ExecutionCallableRunner(
           ^^^^^^^^^^^^^^^^^^^^^^^^
  File "/home/airflow/.local/lib/python3.12/site-packages/airflow/utils/operator_helpers.py", line 252, in run
    return self.func(*args, **kwargs)
           ^^^^^^^^^^^^^^^^^^^^^^^^^^
  File "/home/airflow/.local/lib/python3.12/site-packages/airflow/models/baseoperator.py", line 406, in wrapper
    return func(self, *args, **kwargs)
           ^^^^^^^^^^^^^^^^^^^^^^^^^^^
  File "/home/airflow/.local/lib/python3.12/site-packages/airflow/operators/bash.py", line 249, in execute
    raise AirflowException(
airflow.exceptions.AirflowException: Bash command failed. The command returned a non-zero exit code 1.
[2025-05-27T13:50:14.565+0000] {taskinstance.py:1225} INFO - Marking task as UP_FOR_RETRY. dag_id=log_monitoring_dag, task_id=start_log_producer, run_id=scheduled__2025-05-27T13:45:00+00:00, execution_date=20250527T134500, start_date=20250527T135004, end_date=20250527T135014
[2025-05-27T13:50:17.814+0000] {taskinstance.py:340} INFO - ::group::Post task execution logs
[2025-05-27T13:50:17.816+0000] {standard_task_runner.py:124} ERROR - Failed to execute job 80 for task start_log_producer (Bash command failed. The command returned a non-zero exit code 1.; 179)
Traceback (most recent call last):
  File "/home/airflow/.local/lib/python3.12/site-packages/airflow/task/task_runner/standard_task_runner.py", line 117, in _start_by_fork
    ret = args.func(args, dag=self.dag)
          ^^^^^^^^^^^^^^^^^^^^^^^^^^^^^
  File "/home/airflow/.local/lib/python3.12/site-packages/airflow/cli/cli_config.py", line 49, in command
    return func(*args, **kwargs)
           ^^^^^^^^^^^^^^^^^^^^^
  File "/home/airflow/.local/lib/python3.12/site-packages/airflow/utils/cli.py", line 115, in wrapper
    return f(*args, **kwargs)
           ^^^^^^^^^^^^^^^^^^
  File "/home/airflow/.local/lib/python3.12/site-packages/airflow/cli/commands/task_command.py", line 483, in task_run
    task_return_code = _run_task_by_selected_method(args, _dag, ti)
                       ^^^^^^^^^^^^^^^^^^^^^^^^^^^^^^^^^^^^^^^^^^^^
  File "/home/airflow/.local/lib/python3.12/site-packages/airflow/cli/commands/task_command.py", line 256, in _run_task_by_selected_method
    return _run_raw_task(args, ti)
           ^^^^^^^^^^^^^^^^^^^^^^^
  File "/home/airflow/.local/lib/python3.12/site-packages/airflow/cli/commands/task_command.py", line 341, in _run_raw_task
    return ti._run_raw_task(
           ^^^^^^^^^^^^^^^^^
  File "/home/airflow/.local/lib/python3.12/site-packages/airflow/utils/session.py", line 97, in wrapper
    return func(*args, session=session, **kwargs)
           ^^^^^^^^^^^^^^^^^^^^^^^^^^^^^^^^^^^^^^
  File "/home/airflow/.local/lib/python3.12/site-packages/airflow/models/taskinstance.py", line 3004, in _run_raw_task
    return _run_raw_task(
           ^^^^^^^^^^^^^^
  File "/home/airflow/.local/lib/python3.12/site-packages/airflow/models/taskinstance.py", line 273, in _run_raw_task
    TaskInstance._execute_task_with_callbacks(
  File "/home/airflow/.local/lib/python3.12/site-packages/airflow/models/taskinstance.py", line 3158, in _execute_task_with_callbacks
    result = self._execute_task(context, task_orig)
             ^^^^^^^^^^^^^^^^^^^^^^^^^^^^^^^^^^^^^^
  File "/home/airflow/.local/lib/python3.12/site-packages/airflow/models/taskinstance.py", line 3182, in _execute_task
    return _execute_task(self, context, task_orig)
           ^^^^^^^^^^^^^^^^^^^^^^^^^^^^^^^^^^^^^^^
  File "/home/airflow/.local/lib/python3.12/site-packages/airflow/models/taskinstance.py", line 767, in _execute_task
    result = _execute_callable(context=context, **execute_callable_kwargs)
             ^^^^^^^^^^^^^^^^^^^^^^^^^^^^^^^^^^^^^^^^^^^^^^^^^^^^^^^^^^^^^
  File "/home/airflow/.local/lib/python3.12/site-packages/airflow/models/taskinstance.py", line 733, in _execute_callable
    return ExecutionCallableRunner(
           ^^^^^^^^^^^^^^^^^^^^^^^^
  File "/home/airflow/.local/lib/python3.12/site-packages/airflow/utils/operator_helpers.py", line 252, in run
    return self.func(*args, **kwargs)
           ^^^^^^^^^^^^^^^^^^^^^^^^^^
  File "/home/airflow/.local/lib/python3.12/site-packages/airflow/models/baseoperator.py", line 406, in wrapper
    return func(self, *args, **kwargs)
           ^^^^^^^^^^^^^^^^^^^^^^^^^^^
  File "/home/airflow/.local/lib/python3.12/site-packages/airflow/operators/bash.py", line 249, in execute
    raise AirflowException(
airflow.exceptions.AirflowException: Bash command failed. The command returned a non-zero exit code 1.
[2025-05-27T13:50:17.861+0000] {local_task_job_runner.py:266} INFO - Task exited with return code 1
[2025-05-27T13:50:17.897+0000] {taskinstance.py:3900} INFO - 0 downstream tasks scheduled from follow-on schedule check
[2025-05-27T13:50:17.902+0000] {local_task_job_runner.py:245} INFO - ::endgroup::
