[2025-06-01T12:54:39.203+0000] {local_task_job_runner.py:123} INFO - ::group::Pre task execution logs
[2025-06-01T12:54:44.587+0000] {taskinstance.py:2612} INFO - Dependencies all met for dep_context=non-requeueable deps ti=<TaskInstance: log_monitoring_dag.start_spark_consumer scheduled__2025-05-31T23:05:00+00:00 [queued]>
[2025-06-01T12:54:45.175+0000] {taskinstance.py:2612} INFO - Dependencies all met for dep_context=requeueable deps ti=<TaskInstance: log_monitoring_dag.start_spark_consumer scheduled__2025-05-31T23:05:00+00:00 [queued]>
[2025-06-01T12:54:45.654+0000] {taskinstance.py:2865} INFO - Starting attempt 4 of 4
[2025-06-01T12:54:49.272+0000] {taskinstance.py:2888} INFO - Executing <Task(BashOperator): start_spark_consumer> on 2025-05-31 23:05:00+00:00
[2025-06-01T12:55:08.484+0000] {standard_task_runner.py:104} INFO - Running: ['***', 'tasks', 'run', 'log_monitoring_dag', 'start_spark_consumer', 'scheduled__2025-05-31T23:05:00+00:00', '--job-id', '123', '--raw', '--subdir', 'DAGS_FOLDER/log_monitoring_dag.py', '--cfg-path', '/tmp/tmp1lyarog1']
[2025-06-01T12:55:11.572+0000] {standard_task_runner.py:105} INFO - Job 123: Subtask start_spark_consumer
[2025-06-01T12:55:09.098+0000] {logging_mixin.py:190} WARNING - /home/***/.local/lib/python3.12/site-packages/***/task/task_runner/standard_task_runner.py:70 DeprecationWarning: This process (pid=187) is multi-threaded, use of fork() may lead to deadlocks in the child.
[2025-06-01T12:55:14.972+0000] {standard_task_runner.py:72} INFO - Started process 203 to run task
[2025-06-01T12:55:19.912+0000] {logging_mixin.py:190} WARNING - /home/***/.local/lib/python3.12/site-packages/***/settings.py:209 DeprecationWarning: The sql_alchemy_conn option in [core] has been moved to the sql_alchemy_conn option in [database] - the old setting has been used, but please update your config.
[2025-06-01T12:56:24.796+0000] {job.py:229} INFO - Heartbeat recovered after 113.16 seconds
[2025-06-01T12:56:51.399+0000] {task_command.py:467} INFO - Running <TaskInstance: log_monitoring_dag.start_spark_consumer scheduled__2025-05-31T23:05:00+00:00 [running]> on host 398f8ed29d5e
[2025-06-01T12:56:51.405+0000] {logging_mixin.py:190} WARNING - /home/***/.local/lib/python3.12/site-packages/***/settings.py:470 DeprecationWarning: The sql_alchemy_conn option in [core] has been moved to the sql_alchemy_conn option in [database] - the old setting has been used, but please update your config.
[2025-06-01T12:57:33.052+0000] {job.py:229} INFO - Heartbeat recovered after 74.54 seconds
[2025-06-01T12:57:52.664+0000] {job.py:229} INFO - Heartbeat recovered after 21.37 seconds
[2025-06-01T12:58:08.634+0000] {job.py:229} INFO - Heartbeat recovered after 17.38 seconds
[2025-06-01T12:58:24.270+0000] {taskinstance.py:3131} INFO - Exporting env vars: AIRFLOW_CTX_DAG_OWNER='***' AIRFLOW_CTX_DAG_ID='log_monitoring_dag' AIRFLOW_CTX_TASK_ID='start_spark_consumer' AIRFLOW_CTX_EXECUTION_DATE='2025-05-31T23:05:00+00:00' AIRFLOW_CTX_TRY_NUMBER='4' AIRFLOW_CTX_DAG_RUN_ID='scheduled__2025-05-31T23:05:00+00:00'
[2025-06-01T12:58:25.964+0000] {taskinstance.py:731} INFO - ::endgroup::
[2025-06-01T12:58:29.970+0000] {job.py:229} INFO - Heartbeat recovered after 24.57 seconds
[2025-06-01T12:58:31.750+0000] {subprocess.py:63} INFO - Tmp dir root location: /tmp
[2025-06-01T12:58:32.376+0000] {subprocess.py:75} INFO - Running command: ['/usr/bin/bash', '-c', 'docker exec spark spark-submit --packages org.apache.spark:spark-sql-kafka-0-10_2.12:3.2.0 /app/log_consumer.py']
[2025-06-01T12:58:33.423+0000] {subprocess.py:86} INFO - Output:
[2025-06-01T12:58:44.722+0000] {job.py:229} INFO - Heartbeat recovered after 19.14 seconds
[2025-06-01T12:58:56.194+0000] {job.py:229} INFO - Heartbeat recovered after 14.67 seconds
[2025-06-01T12:59:08.537+0000] {job.py:229} INFO - Heartbeat recovered after 12.55 seconds
[2025-06-01T12:59:17.358+0000] {job.py:229} INFO - Heartbeat recovered after 11.46 seconds
[2025-06-01T12:59:29.980+0000] {job.py:229} INFO - Heartbeat recovered after 14.14 seconds
[2025-06-01T13:00:01.150+0000] {subprocess.py:93} INFO - Cannot connect to the Docker daemon at unix:///var/run/docker.sock. Is the docker daemon running?
[2025-06-01T13:00:01.807+0000] {subprocess.py:97} INFO - Command exited with return code 1
[2025-06-01T13:00:02.104+0000] {job.py:229} INFO - Heartbeat recovered after 12.54 seconds
[2025-06-01T13:00:02.420+0000] {taskinstance.py:3310} ERROR - Task failed with exception
Traceback (most recent call last):
  File "/home/airflow/.local/lib/python3.12/site-packages/airflow/models/taskinstance.py", line 767, in _execute_task
    result = _execute_callable(context=context, **execute_callable_kwargs)
             ^^^^^^^^^^^^^^^^^^^^^^^^^^^^^^^^^^^^^^^^^^^^^^^^^^^^^^^^^^^^^
  File "/home/airflow/.local/lib/python3.12/site-packages/airflow/models/taskinstance.py", line 733, in _execute_callable
    return ExecutionCallableRunner(
           ^^^^^^^^^^^^^^^^^^^^^^^^
  File "/home/airflow/.local/lib/python3.12/site-packages/airflow/utils/operator_helpers.py", line 252, in run
    return self.func(*args, **kwargs)
           ^^^^^^^^^^^^^^^^^^^^^^^^^^
  File "/home/airflow/.local/lib/python3.12/site-packages/airflow/models/baseoperator.py", line 406, in wrapper
    return func(self, *args, **kwargs)
           ^^^^^^^^^^^^^^^^^^^^^^^^^^^
  File "/home/airflow/.local/lib/python3.12/site-packages/airflow/operators/bash.py", line 249, in execute
    raise AirflowException(
airflow.exceptions.AirflowException: Bash command failed. The command returned a non-zero exit code 1.
[2025-06-01T13:00:04.721+0000] {taskinstance.py:1225} INFO - Marking task as FAILED. dag_id=log_monitoring_dag, task_id=start_spark_consumer, run_id=scheduled__2025-05-31T23:05:00+00:00, execution_date=20250531T230500, start_date=20250601T125445, end_date=20250601T130004
[2025-06-01T13:00:05.199+0000] {taskinstance.py:340} INFO - ::group::Post task execution logs
[2025-06-01T13:00:05.341+0000] {standard_task_runner.py:124} ERROR - Failed to execute job 123 for task start_spark_consumer (Bash command failed. The command returned a non-zero exit code 1.; 203)
Traceback (most recent call last):
  File "/home/airflow/.local/lib/python3.12/site-packages/airflow/task/task_runner/standard_task_runner.py", line 117, in _start_by_fork
    ret = args.func(args, dag=self.dag)
          ^^^^^^^^^^^^^^^^^^^^^^^^^^^^^
  File "/home/airflow/.local/lib/python3.12/site-packages/airflow/cli/cli_config.py", line 49, in command
    return func(*args, **kwargs)
           ^^^^^^^^^^^^^^^^^^^^^
  File "/home/airflow/.local/lib/python3.12/site-packages/airflow/utils/cli.py", line 115, in wrapper
    return f(*args, **kwargs)
           ^^^^^^^^^^^^^^^^^^
  File "/home/airflow/.local/lib/python3.12/site-packages/airflow/cli/commands/task_command.py", line 483, in task_run
    task_return_code = _run_task_by_selected_method(args, _dag, ti)
                       ^^^^^^^^^^^^^^^^^^^^^^^^^^^^^^^^^^^^^^^^^^^^
  File "/home/airflow/.local/lib/python3.12/site-packages/airflow/cli/commands/task_command.py", line 256, in _run_task_by_selected_method
    return _run_raw_task(args, ti)
           ^^^^^^^^^^^^^^^^^^^^^^^
  File "/home/airflow/.local/lib/python3.12/site-packages/airflow/cli/commands/task_command.py", line 341, in _run_raw_task
    return ti._run_raw_task(
           ^^^^^^^^^^^^^^^^^
  File "/home/airflow/.local/lib/python3.12/site-packages/airflow/utils/session.py", line 97, in wrapper
    return func(*args, session=session, **kwargs)
           ^^^^^^^^^^^^^^^^^^^^^^^^^^^^^^^^^^^^^^
  File "/home/airflow/.local/lib/python3.12/site-packages/airflow/models/taskinstance.py", line 3004, in _run_raw_task
    return _run_raw_task(
           ^^^^^^^^^^^^^^
  File "/home/airflow/.local/lib/python3.12/site-packages/airflow/models/taskinstance.py", line 273, in _run_raw_task
    TaskInstance._execute_task_with_callbacks(
  File "/home/airflow/.local/lib/python3.12/site-packages/airflow/models/taskinstance.py", line 3158, in _execute_task_with_callbacks
    result = self._execute_task(context, task_orig)
             ^^^^^^^^^^^^^^^^^^^^^^^^^^^^^^^^^^^^^^
  File "/home/airflow/.local/lib/python3.12/site-packages/airflow/models/taskinstance.py", line 3182, in _execute_task
    return _execute_task(self, context, task_orig)
           ^^^^^^^^^^^^^^^^^^^^^^^^^^^^^^^^^^^^^^^
  File "/home/airflow/.local/lib/python3.12/site-packages/airflow/models/taskinstance.py", line 767, in _execute_task
    result = _execute_callable(context=context, **execute_callable_kwargs)
             ^^^^^^^^^^^^^^^^^^^^^^^^^^^^^^^^^^^^^^^^^^^^^^^^^^^^^^^^^^^^^
  File "/home/airflow/.local/lib/python3.12/site-packages/airflow/models/taskinstance.py", line 733, in _execute_callable
    return ExecutionCallableRunner(
           ^^^^^^^^^^^^^^^^^^^^^^^^
  File "/home/airflow/.local/lib/python3.12/site-packages/airflow/utils/operator_helpers.py", line 252, in run
    return self.func(*args, **kwargs)
           ^^^^^^^^^^^^^^^^^^^^^^^^^^
  File "/home/airflow/.local/lib/python3.12/site-packages/airflow/models/baseoperator.py", line 406, in wrapper
    return func(self, *args, **kwargs)
           ^^^^^^^^^^^^^^^^^^^^^^^^^^^
  File "/home/airflow/.local/lib/python3.12/site-packages/airflow/operators/bash.py", line 249, in execute
    raise AirflowException(
airflow.exceptions.AirflowException: Bash command failed. The command returned a non-zero exit code 1.
[2025-06-01T13:00:05.856+0000] {local_task_job_runner.py:266} INFO - Task exited with return code 1
[2025-06-01T13:00:06.176+0000] {taskinstance.py:3900} INFO - 0 downstream tasks scheduled from follow-on schedule check
[2025-06-01T13:00:06.250+0000] {local_task_job_runner.py:245} INFO - ::endgroup::
