[2025-06-01T23:47:30.287+0000] {local_task_job_runner.py:123} INFO - ::group::Pre task execution logs
[2025-06-01T23:47:50.708+0000] {taskinstance.py:2612} INFO - Dependencies all met for dep_context=non-requeueable deps ti=<TaskInstance: log_monitoring_dag.start_spark_consumer scheduled__2025-06-01T23:35:00+00:00 [queued]>
[2025-06-01T23:47:50.717+0000] {taskinstance.py:2612} INFO - Dependencies all met for dep_context=requeueable deps ti=<TaskInstance: log_monitoring_dag.start_spark_consumer scheduled__2025-06-01T23:35:00+00:00 [queued]>
[2025-06-01T23:47:50.729+0000] {taskinstance.py:2865} INFO - Starting attempt 1 of 2
[2025-06-01T23:47:50.854+0000] {taskinstance.py:2888} INFO - Executing <Task(BashOperator): start_spark_consumer> on 2025-06-01 23:35:00+00:00
[2025-06-01T23:47:50.862+0000] {standard_task_runner.py:104} INFO - Running: ['***', 'tasks', 'run', 'log_monitoring_dag', 'start_spark_consumer', 'scheduled__2025-06-01T23:35:00+00:00', '--job-id', '20', '--raw', '--subdir', 'DAGS_FOLDER/log_monitoring_dag.py', '--cfg-path', '/tmp/tmp6vho1ujl']
[2025-06-01T23:47:50.864+0000] {standard_task_runner.py:105} INFO - Job 20: Subtask start_spark_consumer
[2025-06-01T23:47:50.875+0000] {logging_mixin.py:190} WARNING - /home/***/.local/lib/python3.12/site-packages/***/task/task_runner/standard_task_runner.py:70 DeprecationWarning: This process (pid=533) is multi-threaded, use of fork() may lead to deadlocks in the child.
[2025-06-01T23:47:50.877+0000] {standard_task_runner.py:72} INFO - Started process 538 to run task
[2025-06-01T23:47:51.869+0000] {logging_mixin.py:190} WARNING - /home/***/.local/lib/python3.12/site-packages/***/settings.py:209 DeprecationWarning: The sql_alchemy_conn option in [core] has been moved to the sql_alchemy_conn option in [database] - the old setting has been used, but please update your config.
[2025-06-01T23:47:52.299+0000] {task_command.py:467} INFO - Running <TaskInstance: log_monitoring_dag.start_spark_consumer scheduled__2025-06-01T23:35:00+00:00 [running]> on host 2317d0480f96
[2025-06-01T23:47:52.301+0000] {logging_mixin.py:190} WARNING - /home/***/.local/lib/python3.12/site-packages/***/settings.py:470 DeprecationWarning: The sql_alchemy_conn option in [core] has been moved to the sql_alchemy_conn option in [database] - the old setting has been used, but please update your config.
[2025-06-01T23:47:53.764+0000] {taskinstance.py:3131} INFO - Exporting env vars: AIRFLOW_CTX_DAG_OWNER='***' AIRFLOW_CTX_DAG_ID='log_monitoring_dag' AIRFLOW_CTX_TASK_ID='start_spark_consumer' AIRFLOW_CTX_EXECUTION_DATE='2025-06-01T23:35:00+00:00' AIRFLOW_CTX_TRY_NUMBER='1' AIRFLOW_CTX_DAG_RUN_ID='scheduled__2025-06-01T23:35:00+00:00'
[2025-06-01T23:47:53.767+0000] {taskinstance.py:731} INFO - ::endgroup::
[2025-06-01T23:47:55.004+0000] {subprocess.py:63} INFO - Tmp dir root location: /tmp
[2025-06-01T23:47:55.062+0000] {subprocess.py:75} INFO - Running command: ['/usr/bin/bash', '-c', '\n            docker run --rm             --network realtime_log_monitoring_default             -v /opt/***/app:/app             bitnami/spark:3.3.0             spark-submit --packages org.apache.spark:spark-sql-kafka-0-10_2.12:3.2.0 /app/log_consumer.py\n        ']
[2025-06-01T23:47:56.030+0000] {subprocess.py:86} INFO - Output:
[2025-06-01T23:47:56.978+0000] {job.py:229} INFO - Heartbeat recovered after 84.22 seconds
[2025-06-01T23:48:07.928+0000] {job.py:229} INFO - Heartbeat recovered after 11.12 seconds
[2025-06-01T23:49:39.528+0000] {job.py:239} ERROR - Job heartbeat failed with error
Traceback (most recent call last):
  File "/home/airflow/.local/lib/python3.12/site-packages/sqlalchemy/engine/base.py", line 3371, in _wrap_pool_connect
    return fn()
           ^^^^
  File "/home/airflow/.local/lib/python3.12/site-packages/sqlalchemy/pool/base.py", line 327, in connect
    return _ConnectionFairy._checkout(self)
           ^^^^^^^^^^^^^^^^^^^^^^^^^^^^^^^^
  File "/home/airflow/.local/lib/python3.12/site-packages/sqlalchemy/pool/base.py", line 894, in _checkout
    fairy = _ConnectionRecord.checkout(pool)
            ^^^^^^^^^^^^^^^^^^^^^^^^^^^^^^^^
  File "/home/airflow/.local/lib/python3.12/site-packages/sqlalchemy/pool/base.py", line 493, in checkout
    rec = pool._do_get()
          ^^^^^^^^^^^^^^
  File "/home/airflow/.local/lib/python3.12/site-packages/sqlalchemy/pool/impl.py", line 256, in _do_get
    return self._create_connection()
           ^^^^^^^^^^^^^^^^^^^^^^^^^
  File "/home/airflow/.local/lib/python3.12/site-packages/sqlalchemy/pool/base.py", line 273, in _create_connection
    return _ConnectionRecord(self)
           ^^^^^^^^^^^^^^^^^^^^^^^
  File "/home/airflow/.local/lib/python3.12/site-packages/sqlalchemy/pool/base.py", line 388, in __init__
    self.__connect()
  File "/home/airflow/.local/lib/python3.12/site-packages/sqlalchemy/pool/base.py", line 690, in __connect
    with util.safe_reraise():
  File "/home/airflow/.local/lib/python3.12/site-packages/sqlalchemy/util/langhelpers.py", line 70, in __exit__
    compat.raise_(
  File "/home/airflow/.local/lib/python3.12/site-packages/sqlalchemy/util/compat.py", line 211, in raise_
    raise exception
  File "/home/airflow/.local/lib/python3.12/site-packages/sqlalchemy/pool/base.py", line 686, in __connect
    self.dbapi_connection = connection = pool._invoke_creator(self)
                                         ^^^^^^^^^^^^^^^^^^^^^^^^^^
  File "/home/airflow/.local/lib/python3.12/site-packages/sqlalchemy/engine/create.py", line 574, in connect
    return dialect.connect(*cargs, **cparams)
           ^^^^^^^^^^^^^^^^^^^^^^^^^^^^^^^^^^
  File "/home/airflow/.local/lib/python3.12/site-packages/sqlalchemy/engine/default.py", line 598, in connect
    return self.dbapi.connect(*cargs, **cparams)
           ^^^^^^^^^^^^^^^^^^^^^^^^^^^^^^^^^^^^^
  File "/home/airflow/.local/lib/python3.12/site-packages/psycopg2/__init__.py", line 122, in connect
    conn = _connect(dsn, connection_factory=connection_factory, **kwasync)
           ^^^^^^^^^^^^^^^^^^^^^^^^^^^^^^^^^^^^^^^^^^^^^^^^^^^^^^^^^^^^^^^
psycopg2.OperationalError: could not translate host name "postgres" to address: Temporary failure in name resolution


The above exception was the direct cause of the following exception:

Traceback (most recent call last):
  File "/home/airflow/.local/lib/python3.12/site-packages/airflow/jobs/job.py", line 207, in heartbeat
    self._merge_from(Job._fetch_from_db(self, session))
                     ^^^^^^^^^^^^^^^^^^^^^^^^^^^^^^^^^
  File "/home/airflow/.local/lib/python3.12/site-packages/airflow/api_internal/internal_api_call.py", line 139, in wrapper
    return func(*args, **kwargs)
           ^^^^^^^^^^^^^^^^^^^^^
  File "/home/airflow/.local/lib/python3.12/site-packages/airflow/utils/session.py", line 94, in wrapper
    return func(*args, **kwargs)
           ^^^^^^^^^^^^^^^^^^^^^
  File "/home/airflow/.local/lib/python3.12/site-packages/airflow/utils/retries.py", line 93, in wrapped_function
    for attempt in run_with_db_retries(max_retries=retries, logger=logger, **retry_kwargs):
                   ^^^^^^^^^^^^^^^^^^^^^^^^^^^^^^^^^^^^^^^^^^^^^^^^^^^^^^^^^^^^^^^^^^^^^^^
  File "/home/airflow/.local/lib/python3.12/site-packages/tenacity/__init__.py", line 443, in __iter__
    do = self.iter(retry_state=retry_state)
         ^^^^^^^^^^^^^^^^^^^^^^^^^^^^^^^^^^
  File "/home/airflow/.local/lib/python3.12/site-packages/tenacity/__init__.py", line 376, in iter
    result = action(retry_state)
             ^^^^^^^^^^^^^^^^^^^
  File "/home/airflow/.local/lib/python3.12/site-packages/tenacity/__init__.py", line 418, in exc_check
    raise retry_exc.reraise()
          ^^^^^^^^^^^^^^^^^^^
  File "/home/airflow/.local/lib/python3.12/site-packages/tenacity/__init__.py", line 185, in reraise
    raise self.last_attempt.result()
          ^^^^^^^^^^^^^^^^^^^^^^^^^^
  File "/usr/local/lib/python3.12/concurrent/futures/_base.py", line 449, in result
    return self.__get_result()
           ^^^^^^^^^^^^^^^^^^^
  File "/usr/local/lib/python3.12/concurrent/futures/_base.py", line 401, in __get_result
    raise self._exception
  File "/home/airflow/.local/lib/python3.12/site-packages/airflow/utils/retries.py", line 102, in wrapped_function
    return func(*args, **kwargs)
           ^^^^^^^^^^^^^^^^^^^^^
  File "/home/airflow/.local/lib/python3.12/site-packages/airflow/jobs/job.py", line 335, in _fetch_from_db
    session.merge(job)
  File "/home/airflow/.local/lib/python3.12/site-packages/sqlalchemy/orm/session.py", line 3056, in merge
    return self._merge(
           ^^^^^^^^^^^^
  File "/home/airflow/.local/lib/python3.12/site-packages/sqlalchemy/orm/session.py", line 3136, in _merge
    merged = self.get(
             ^^^^^^^^^
  File "/home/airflow/.local/lib/python3.12/site-packages/sqlalchemy/orm/session.py", line 2853, in get
    return self._get_impl(
           ^^^^^^^^^^^^^^^
  File "/home/airflow/.local/lib/python3.12/site-packages/sqlalchemy/orm/session.py", line 2975, in _get_impl
    return db_load_fn(
           ^^^^^^^^^^^
  File "/home/airflow/.local/lib/python3.12/site-packages/sqlalchemy/orm/loading.py", line 530, in load_on_pk_identity
    session.execute(
  File "/home/airflow/.local/lib/python3.12/site-packages/sqlalchemy/orm/session.py", line 1716, in execute
    conn = self._connection_for_bind(bind)
           ^^^^^^^^^^^^^^^^^^^^^^^^^^^^^^^
  File "/home/airflow/.local/lib/python3.12/site-packages/sqlalchemy/orm/session.py", line 1555, in _connection_for_bind
    return self._transaction._connection_for_bind(
           ^^^^^^^^^^^^^^^^^^^^^^^^^^^^^^^^^^^^^^^
  File "/home/airflow/.local/lib/python3.12/site-packages/sqlalchemy/orm/session.py", line 750, in _connection_for_bind
    conn = bind.connect()
           ^^^^^^^^^^^^^^
  File "/home/airflow/.local/lib/python3.12/site-packages/sqlalchemy/future/engine.py", line 412, in connect
    return super(Engine, self).connect()
           ^^^^^^^^^^^^^^^^^^^^^^^^^^^^^
  File "/home/airflow/.local/lib/python3.12/site-packages/sqlalchemy/engine/base.py", line 3325, in connect
    return self._connection_cls(self, close_with_result=close_with_result)
           ^^^^^^^^^^^^^^^^^^^^^^^^^^^^^^^^^^^^^^^^^^^^^^^^^^^^^^^^^^^^^^^
  File "/home/airflow/.local/lib/python3.12/site-packages/sqlalchemy/engine/base.py", line 96, in __init__
    else engine.raw_connection()
         ^^^^^^^^^^^^^^^^^^^^^^^
  File "/home/airflow/.local/lib/python3.12/site-packages/sqlalchemy/engine/base.py", line 3404, in raw_connection
    return self._wrap_pool_connect(self.pool.connect, _connection)
           ^^^^^^^^^^^^^^^^^^^^^^^^^^^^^^^^^^^^^^^^^^^^^^^^^^^^^^^
  File "/home/airflow/.local/lib/python3.12/site-packages/sqlalchemy/engine/base.py", line 3374, in _wrap_pool_connect
    Connection._handle_dbapi_exception_noconnection(
  File "/home/airflow/.local/lib/python3.12/site-packages/sqlalchemy/engine/base.py", line 2208, in _handle_dbapi_exception_noconnection
    util.raise_(
  File "/home/airflow/.local/lib/python3.12/site-packages/sqlalchemy/util/compat.py", line 211, in raise_
    raise exception
  File "/home/airflow/.local/lib/python3.12/site-packages/sqlalchemy/engine/base.py", line 3371, in _wrap_pool_connect
    return fn()
           ^^^^
  File "/home/airflow/.local/lib/python3.12/site-packages/sqlalchemy/pool/base.py", line 327, in connect
    return _ConnectionFairy._checkout(self)
           ^^^^^^^^^^^^^^^^^^^^^^^^^^^^^^^^
  File "/home/airflow/.local/lib/python3.12/site-packages/sqlalchemy/pool/base.py", line 894, in _checkout
    fairy = _ConnectionRecord.checkout(pool)
            ^^^^^^^^^^^^^^^^^^^^^^^^^^^^^^^^
  File "/home/airflow/.local/lib/python3.12/site-packages/sqlalchemy/pool/base.py", line 493, in checkout
    rec = pool._do_get()
          ^^^^^^^^^^^^^^
  File "/home/airflow/.local/lib/python3.12/site-packages/sqlalchemy/pool/impl.py", line 256, in _do_get
    return self._create_connection()
           ^^^^^^^^^^^^^^^^^^^^^^^^^
  File "/home/airflow/.local/lib/python3.12/site-packages/sqlalchemy/pool/base.py", line 273, in _create_connection
    return _ConnectionRecord(self)
           ^^^^^^^^^^^^^^^^^^^^^^^
  File "/home/airflow/.local/lib/python3.12/site-packages/sqlalchemy/pool/base.py", line 388, in __init__
    self.__connect()
  File "/home/airflow/.local/lib/python3.12/site-packages/sqlalchemy/pool/base.py", line 690, in __connect
    with util.safe_reraise():
  File "/home/airflow/.local/lib/python3.12/site-packages/sqlalchemy/util/langhelpers.py", line 70, in __exit__
    compat.raise_(
  File "/home/airflow/.local/lib/python3.12/site-packages/sqlalchemy/util/compat.py", line 211, in raise_
    raise exception
  File "/home/airflow/.local/lib/python3.12/site-packages/sqlalchemy/pool/base.py", line 686, in __connect
    self.dbapi_connection = connection = pool._invoke_creator(self)
                                         ^^^^^^^^^^^^^^^^^^^^^^^^^^
  File "/home/airflow/.local/lib/python3.12/site-packages/sqlalchemy/engine/create.py", line 574, in connect
    return dialect.connect(*cargs, **cparams)
           ^^^^^^^^^^^^^^^^^^^^^^^^^^^^^^^^^^
  File "/home/airflow/.local/lib/python3.12/site-packages/sqlalchemy/engine/default.py", line 598, in connect
    return self.dbapi.connect(*cargs, **cparams)
           ^^^^^^^^^^^^^^^^^^^^^^^^^^^^^^^^^^^^^
  File "/home/airflow/.local/lib/python3.12/site-packages/psycopg2/__init__.py", line 122, in connect
    conn = _connect(dsn, connection_factory=connection_factory, **kwasync)
           ^^^^^^^^^^^^^^^^^^^^^^^^^^^^^^^^^^^^^^^^^^^^^^^^^^^^^^^^^^^^^^^
sqlalchemy.exc.OperationalError: (psycopg2.OperationalError) could not translate host name "postgres" to address: Temporary failure in name resolution

(Background on this error at: https://sqlalche.me/e/14/e3q8)
[2025-06-01T23:51:21.503+0000] {job.py:254} ERROR - Job heartbeat failed with error. Scheduler is in unhealthy state
[2025-06-01T23:51:31.680+0000] {job.py:229} INFO - Heartbeat recovered after 208.18 seconds
[2025-06-01T23:54:11.290+0000] {job.py:229} INFO - Heartbeat recovered after 147.36 seconds
[2025-06-01T23:54:22.485+0000] {job.py:229} INFO - Heartbeat recovered after 13.61 seconds
[2025-06-01T23:54:34.711+0000] {job.py:229} INFO - Heartbeat recovered after 12.63 seconds
[2025-06-01T23:55:08.711+0000] {job.py:229} INFO - Heartbeat recovered after 22.27 seconds
[2025-06-01T23:55:46.847+0000] {job.py:229} INFO - Heartbeat recovered after 39.00 seconds
[2025-06-01T23:56:17.125+0000] {job.py:229} INFO - Heartbeat recovered after 47.97 seconds
[2025-06-01T23:56:22.554+0000] {job.py:229} INFO - Heartbeat recovered after 28.58 seconds
[2025-06-01T23:56:46.083+0000] {job.py:229} INFO - Heartbeat recovered after 15.54 seconds
[2025-06-01T23:56:56.805+0000] {job.py:229} INFO - Heartbeat recovered after 11.11 seconds
[2025-06-01T23:57:36.094+0000] {job.py:229} INFO - Heartbeat recovered after 10.93 seconds
[2025-06-01T23:58:23.008+0000] {subprocess.py:93} INFO - [38;5;6m [38;5;5m23:58:20.64 [0m
[2025-06-01T23:58:27.484+0000] {subprocess.py:93} INFO - [38;5;6m [38;5;5m23:58:21.98 [0m[1mWelcome to the Bitnami spark container[0m
[2025-06-01T23:58:27.719+0000] {subprocess.py:93} INFO - [38;5;6m [38;5;5m23:58:22.31 [0mSubscribe to project updates by watching [1mhttps://github.com/bitnami/containers[0m
[2025-06-01T23:58:28.993+0000] {subprocess.py:93} INFO - [38;5;6m [38;5;5m23:58:22.31 [0mSubmit issues and feature requests at [1mhttps://github.com/bitnami/containers/issues[0m
[2025-06-01T23:58:29.341+0000] {subprocess.py:93} INFO - [38;5;6m [38;5;5m23:58:22.31 [0m
[2025-06-01T23:58:29.642+0000] {subprocess.py:93} INFO - 
[2025-06-01T23:59:48.834+0000] {job.py:229} INFO - Heartbeat recovered after 15.93 seconds
[2025-06-02T00:01:28.180+0000] {job.py:229} INFO - Heartbeat recovered after 11.65 seconds
[2025-06-02T00:01:53.638+0000] {job.py:229} INFO - Heartbeat recovered after 10.81 seconds
[2025-06-02T00:02:04.608+0000] {job.py:229} INFO - Heartbeat recovered after 11.39 seconds
[2025-06-02T00:02:16.148+0000] {job.py:229} INFO - Heartbeat recovered after 12.79 seconds
[2025-06-02T00:02:47.246+0000] {job.py:229} INFO - Heartbeat recovered after 12.20 seconds
[2025-06-02T00:03:03.285+0000] {job.py:229} INFO - Heartbeat recovered after 16.54 seconds
[2025-06-02T00:03:40.402+0000] {subprocess.py:93} INFO - :: loading settings :: url = jar:file:/opt/bitnami/spark/jars/ivy-2.5.0.jar!/org/apache/ivy/core/settings/ivysettings.xml
[2025-06-02T00:03:40.650+0000] {subprocess.py:93} INFO - Ivy Default Cache set to: /opt/bitnami/spark/.ivy2/cache
[2025-06-02T00:03:40.651+0000] {subprocess.py:93} INFO - The jars for the packages stored in: /opt/bitnami/spark/.ivy2/jars
[2025-06-02T00:03:40.972+0000] {subprocess.py:93} INFO - org.apache.spark#spark-sql-kafka-0-10_2.12 added as a dependency
[2025-06-02T00:03:41.012+0000] {subprocess.py:93} INFO - :: resolving dependencies :: org.apache.spark#spark-submit-parent-83c83866-0426-493a-9b47-8bf14a4da3dd;1.0
[2025-06-02T00:03:41.012+0000] {subprocess.py:93} INFO - 	confs: [default]
[2025-06-02T00:03:56.398+0000] {job.py:229} INFO - Heartbeat recovered after 11.39 seconds
[2025-06-02T00:04:07.735+0000] {local_task_job_runner.py:127} ERROR - Received SIGTERM. Terminating subprocesses
[2025-06-02T00:04:08.143+0000] {subprocess.py:93} INFO - 	found org.apache.spark#spark-sql-kafka-0-10_2.12;3.2.0 in central
